Workbook
Name Agua: '[1]Listas Desplegables'!#REF!
Name Agua: 'Listas Desplegables'!#REF!
Name Biomasa: 'Listas Desplegables'!$H$9:$H$10
Name Carbón: '[1]Listas Desplegables'!#REF!
Name Carbón: 'Listas Desplegables'!#REF!
Name Crudo_Pesado: '[1]Listas Desplegables'!#REF!
Name Crudo_Pesado: 'Listas Desplegables'!#REF!
Name Cultivo_Energético: '[1]Listas Desplegables'!#REF!
Name Cultivo_Energético: 'Listas Desplegables'!#REF!
Name Eólica: 'Listas Desplegables'!$F$9:$F$9
Name Fuil_Oil: '[1]Listas Desplegables'!#REF!
Name Fuil_Oil: 'Listas Desplegables'!#REF!
Name Gas: '[1]Listas Desplegables'!#REF!
Name Gas: 'Listas Desplegables'!#REF!
Name Geotérmica: 'Listas Desplegables'!$I$9:$I$9
Name Hidráulico: 'Listas Desplegables'!$G$9:$G$9
Name Otro: '[1]Listas Desplegables'!#REF!
Name Otro: 'Listas Desplegables'!#REF!
Name Recurso: '[1]Listas Desplegables'!$B$11:$B$12
Name Recurso: 'Listas Desplegables'!$B$11:$B$12
Name Residuos_Agrícolas_Cultivo: '[1]Listas Desplegables'!#REF!
Name Residuos_Agrícolas_Cultivo: 'Listas Desplegables'!#REF!
Name Residuos_Agrícolas_Industriales: '[1]Listas Desplegables'!#REF!
Name Residuos_Agrícolas_Industriales: 'Listas Desplegables'!#REF!
Name Residuos_Pecuarios: '[1]Listas Desplegables'!#REF!
Name Residuos_Pecuarios: 'Listas Desplegables'!#REF!
Name Residuos_Solidos_Urbanos: '[1]Listas Desplegables'!#REF!
Name Residuos_Solidos_Urbanos: 'Listas Desplegables'!#REF!
Name Sol: '[1]Listas Desplegables'!#REF!
Name Sol: 'Listas Desplegables'!#REF!
Name Solar: 'Listas Desplegables'!$E$9:$E$9
Name Tecnologia: '[1]Listas Desplegables'!#REF!
Name Tecnologia: 'Listas Desplegables'!#REF!
Name Térmica: 'Listas Desplegables'!$J$9:$J$9
Name TGenerador: 'Listas Desplegables'!$B$4:$B$6
Name TGenerador: '[2]Listas Desplegables'!$B$3:$B$7
Name TProyecto: '[1]Listas Desplegables'!$B$8:$B$9
Name TProyecto: 'Listas Desplegables'!$B$8:$B$9
Name Vapor: '[1]Listas Desplegables'!#REF!
Name Vapor: 'Listas Desplegables'!#REF!
Name Viento: '[1]Listas Desplegables'!#REF!
Name Viento: 'Listas Desplegables'!#REF!
Name zona: '[1]Listas Desplegables'!#REF!
Name zona: 'Listas Desplegables'!#REF!

Sheet Manual de Uso
B2: MANUAL DE USO PARA EL REPORTE DE INFORMACIÓN REQUERIDA DE LOS TRANSPORTADORES
B7: INTRODUCCIÓN
B8: El presente formato se establece en cumplimiento de lo establecido en el articulo 7 de la Resolución CREG 075 de 2021, para facilitar el reporte uniforme de la información que los transportadores deben entregar para la realización de los estudios de conexión y disponibilidad de espacio físico. El uso del presente formato es transitorio, y se requerirá hasta que entre en funcionamiento el sistema de información de la ventanilla única de la UPME, a través del cual se reportará y actualizará la información requerida para estudios de conexión.
B14: CONTENIDO
B15: El Formato se encuentra dividido en 9 secciones según el tipo de activo a reportar: 1. Información de líneas de transmisión y distribución 2. Información de transformadores tridevanados 3. Información de transformadores bidevanados 4. Información de subestaciones 5. Información de demandas 6. Información de compensaciones 7. Información de compensaciones dinámicas 8. Información de dispositivos DFACTS 9. Información de disponibilidad de espacio físico
B26: MANUAL DE USO
B27: Dentro de cada sección se solicita que el Transportador compile información característica de cada uno de los tipos de activo. A continuación, se presenta la información y una descripción de lo requerido:
B29: Líneas de transmisión y distribución | C29: Nombre | D29: Nombre de línea de transmisión o distribución.
C30: Subestación 1 | D30: Subestación o punto de la red a la cual se conecta uno de los extremos de la línea
C31: Subestación 2 | D31: Subestación o punto de la red a la cual se conecta el otro extremo de la línea
C32: Nivel de tensión [kV] | D32: Nivel de tensión nominal en kilovoltios al cual opera la línea
C33: Longitud [km] | D33: Longitud en kilometros de la línea
C34: Capacidad transporte nominal [A] | D34: Capacidad de transporte de corriente nominal de la línea de transmisión en estado estable en amperios
C35: Capacidad transporte térmico [A] | D35: Capacidad nominal de transporte de corriente del conductor de menor capacidad utilizado en la línea de transmisión en amperios
C36: Capacidad transporte emergencia [A] | D36: Capacidad de corriente máxima que puede soportar la línea ante condiciones de emergencia en amperios
C37: Causa límite de capacidad | D37: Indicar la razón por la cual se limita la capacidad de transporte de la línea. Ej: Topología, capacidad conductor, configuración CTs,etc.
C38: R1 [Ohm/km] | D38: Resistencia de secuencia positiva por unidad de longitud en ohmios por kilometro
C39: X1 [Ohm/km] | D39: Reactancia de secuencia positiva por unidad de longitud en ohmios por kilometro
C40: B1 [uS/km] | D40: Susceptancia de secuancia positiva por unidad de longitud en microsiemens por kilometro
C41: R0 [Ohm/km] | D41: Resistencia de secuencia cero por unidad de longitud en ohmios por kilometro
... C52: Observaciones transportador | D52: Sección de libre diligenciamiento, donde el transportador debe indicar explicítamente cualquier condición operativa o de planeación que no este incluida en las demás variables. Ejemplo: La línea opera normalmente abierta al lado de la subestación A o se tiene planeado una repotenciación de la línea hasta una capacidad de X Amperios, la cual entrará en operación desde dd/mm/aaaa.
B53: Transformadores tridevanados | C53: Nombre | D53: Nombre del transformador tridevanado. Se sugiere sea nombre de la subestación seguido de los niveles de tensión del transformador
C54: Subestación | D54: Subestación en la cual se encuentra ubicado el transformador
C55: Nivel de tensión HV [kV] | D55: Nivel de tensión nominal de diseño de los bornes de alta tensión del transformador en kilovoltios
C56: Nivel de tensión MV [kV] | D56: Nivel de tensión nominal de diseño de los bornes de media tensión del transformador en kilovoltios
C57: Nivel de tensión LV [kV] | D57: Nivel de tensión nominal de diseño de los bornes de baja tensión del transformador en kilovoltios
C58: Capacidad HV [MVA] | D58: Capacidad nominal en el devanado de alta tensión del transformador en MVA
C59: Capacidad MV [MVA] | D59: Capacidad nominal en el devanado de media tensión del transformador en MVA
C60: Capacidad LV [MVA] | D60: Capacidad nominal en el devanado de baja tensión del transformador en MVA
C61: Grupo de conexión | D61: Convención utilizada para describir las configuraciones de los distintos devanados del transformador y el desfase en los angulos de fase según norma IEC 60076-1 2011. Ejemplo: YNyn0d5
C62: Impedancia HV-MV Secuencia +[%] | D62: Impedancia de corto circuito entre los devanados de alta y media tensión en secuencia positiva como porcentaje de la impedancia de referencia
C63: Impedancia HV-LV Secuencia +[%] | D63: Impedancia de corto circuito entre los devanados de alta y baja tensión en secuencia positiva como porcentaje de la impedancia de referencia
C64: Impedancia MV-LV Secuencia +[%] | D64: Impedancia de corto circuito entre los devanados de media y baja tensión en secuencia positiva como porcentaje de la impedancia de referencia
C65: Impedancia HV-MV Secuencia 0[%] | D65: Impedancia de corto circuito entre los devanados de alta y media tensión en secuencia cero como porcentaje de la impedancia de referencia
... C82: Observaciones transportador | D82: Sección de libre diligenciamiento, donde el transportador debe indicar explicítamente cualquier condición operativa o de planeación que no este incluida en las demás variables.
B83: Tranformadores bidevanados | C83: Nombre | D83: Nombre del transformador tridevanado. Se sugiere sea nombre de la subestación seguido de los niveles de tensión del transformador
C84: Subestación | D84: Subestación en la cual se encuentra ubicado el transformador
C85: Nivel de tensión HV [kV] | D85: Nivel de tensión nominal de diseño de los bornes de alta tensión del transformador en kilovoltios
C86: Nivel de tensión LV [kV] | D86: Nivel de tensión nominal de diseño de los bornes de baja tensión del transformador en kilovoltios
C87: Capacidad [MVA] | D87: Capacidad nominal del transformador en MVA
...

Sheet 1. Líneas
C3: Información General de Líneas
C4: No. | D4: ='Manual de Uso'!C29 -> Nombre | E4: ='Manual de Uso'!C30 -> Subestación 1 | F4: ='Manual de Uso'!C31 -> Subestación 2 | G4: ='Manual de Uso'!C32 -> Nivel de tensión [kV] | H4: ='Manual de Uso'!C33 -> Longitud [km] | I4: ='Manual de Uso'!C34 -> Capacidad transporte nominal [A] | J4: ='Manual de Uso'!C35 -> Capacidad transporte térmico [A] | K4: ='Manual de Uso'!C36 -> Capacidad transporte emergencia [A] | L4: ='Manual de Uso'!C37 -> Causa límite de capacidad | M4: ='Manual de Uso'!C38 -> R1 [Ohm/km] | N4: ='Manual de Uso'!C39 -> X1 [Ohm/km] | O4: ='Manual de Uso'!C40 -> B1 [uS/km] | P4: ='Manual de Uso'!C41 -> R0 [Ohm/km] | Q4: ='Manual de Uso'!C42 -> X0 [Ohm/km] | R4: ='Manual de Uso'!C43 -> B0 [uS/km] | S4: ='Manual de Uso'!C44 -> Sistema | T4: ='Manual de Uso'!C45 -> Tipo | U4: ='Manual de Uso'!C46 -> En Operación | V4: ='Manual de Uso'!C47 -> FPO | W4: ='Manual de Uso'!C48 -> Conductor | X4: ='Manual de Uso'!C49 -> Tiempo medio de reparación por evento [h] | Y4: ='Manual de Uso'!C50 -> Horas anuales de indisponibilidad [h] | Z4: ='Manual de Uso'!C51 -> Eventos anuales de indisponibilidad | AA4: ='Manual de Uso'!C52 -> Observaciones transportador
A6: =VLOOKUP(E6,'[2]Listas Desplegables'!$H$3:$J$7,2,FALSE) -> #N/A | B6: =VLOOKUP(E6,'[2]Listas Desplegables'!$H$3:$J$7,3,FALSE) -> #N/A | C6: 1 | D6: BUIA45 | E6: AGUACHICA | F6: BUTURAMA | G6: 115 | H6: 1.5 | I6: 260 | J6: 670 | K6: 260 | L6: Ajuste por carga | M6: 0.1341201 | N6: 0.4843308 | O6: 3.4194 | P6: 0.4254369 | Q6: 1.5449 | R6: 1.8857 | S6: STR | T6: Áerea | U6: Sí | W6: 477 - Aluminio | X6: 10.540444 | Y6: 31.621333 | Z6: 3 | AA6: AGUACHICA - BUTURAMA 1 115 Kv
A7: =VLOOKUP(E7,'[2]Listas Desplegables'!$H$3:$J$7,2,FALSE) -> #N/A | B7: =VLOOKUP(E7,'[2]Listas Desplegables'!$H$3:$J$7,3,FALSE) -> #N/A | C7: 2 | D7: BUIA25 | E7: AYACUCHO | F7: BUTURAMA | G7: 115 | H7: 43.7 | I7: 661 | J7: 661 | K7: 690 | L7: Ajuste por carga | M7: 0.1205253 | N7: 0.4928924 | O7: 3.3342 | P7: 0.2885014 | Q7: 1.6211 | R7: 1.69 | S7: STR | T7: Áerea | U7: Sí | W7: 477 - Aluminio | X7: 3.5440833 | Y7: 14.176333 | Z7: 4 | AA7: AYACUCHO - BUTURAMA 1 115 kV
A8: =VLOOKUP(E8,'[2]Listas Desplegables'!$H$3:$J$7,2,FALSE) -> #N/A | B8: =VLOOKUP(E8,'[2]Listas Desplegables'!$H$3:$J$7,3,FALSE) -> #N/A | C8: 3 | D8: CONS75 | E8: AYACUCHO | F8: CONVENCION | G8: 115 | H8: 37.89 | I8: 530 | J8: 530 | K8: 610 | L8: Ajuste por carga | M8: 0.1851 | N8: 0.4869 | O8: 3.3676 | P8: 0.4764 | Q8: 1.5475 | R8: 1.8698 | S8: STR | T8: Áerea | U8: Sí | W8: 336.4 - Aluminio | X8: 8.3269444 | Y8: 83.269444 | Z8: 10 | AA8: AYACUCHO - CONVENCION 1 115 kV
A9: =VLOOKUP(E9,'[2]Listas Desplegables'!$H$3:$J$7,2,FALSE) -> #N/A | B9: =VLOOKUP(E9,'[2]Listas Desplegables'!$H$3:$J$7,3,FALSE) -> #N/A | C9: 4 | D9: SEVS10 | E9: SEVILLA | F9: BELEN | G9: 115 | H9: 4.155 | I9: 300 | J9: 490 | K9: 300 | L9: Transformador de corriente | M9: 0.1859 | N9: 0.4852 | O9: 3.4061 | P9: 0.4626 | Q9: 1.3712 | R9: 2.0368 | S9: STR | T9: Áerea | U9: Sí | W9: 300 - Aluminio | X9: 14.491019 | Y9: 43.473056 | Z9: 3
A10: =VLOOKUP(E10,'[2]Listas Desplegables'!$H$3:$J$7,2,FALSE) -> #N/A | B10: =VLOOKUP(E10,'[2]Listas Desplegables'!$H$3:$J$7,3,FALSE) -> #N/A | C10: 5 | D10: SEVS20 | E10: SEVILLA | F10: BELEN | G10: 115 | H10: 4.155 | I10: 200 | J10: 530 | K10: 200 | L10: Transformador de corriente | M10: 0.1648 | N10: 0.4773 | O10: 3.4545 | P10: 0.4416 | Q10: 1.3633 | R10: 2.0524 | S10: STR | T10: Áerea | U10: Sí | W10: 300 - Aluminio | X10: 15.956736 | Y10: 63.826944 | Z10: 4
A11: =VLOOKUP(E11,'[2]Listas Desplegables'!$H$3:$J$7,2,FALSE) -> #N/A | B11: =VLOOKUP(E11,'[2]Listas Desplegables'!$H$3:$J$7,3,FALSE) -> #N/A | C11: 6 | D11: OCAIA15 | E11: OCANA | F11: BUTURAMA | G11: 115 | H11: 41.5 | I11: 670 | J11: 670 | K11: 690 | L11: Ajuste por carga | M11: 0.1341 | N11: 0.4843308 | O11: 3.4194 | P11: 0.4254369 | Q11: 1.5449 | R11: 1.8857 | S11: STR | T11: Áerea | U11: Sí | W11: 477 - Aluminio | X11: 2.2682778 | Y11: 11.341389 | Z11: 5
A12: =VLOOKUP(E12,'[2]Listas Desplegables'!$H$3:$J$7,2,FALSE) -> #N/A | B12: =VLOOKUP(E12,'[2]Listas Desplegables'!$H$3:$J$7,3,FALSE) -> #N/A | C12: 7 | D12: BELEN 230 - SAN MATEO 230 | E12: BELÉN | F12: SAN MATEO | G12: 230 | H12: 1 | I12: 800 | J12: 860 | K12: 860 | L12: Transformador de corriente | M12: 0.0667 | N12: 0.5181 | O12: 3.337 | P12: 0.289 | Q12: 0.924 | R12: 2.696 | S12: STN | T12: Áerea | U12: Sí | W12: 795 - Aluminio | X12: 0 | Y12: 0 | Z12: 0
C13: 8 | D13: BELEN 230 - TERMOTASAJERO 230 | E13: BELÉN | F13: TERMOTASAJERO | G13: 230 | H13: 1 | I13: 814 | M13: 0.0729 | N13: 0.5368 | O13: 3.2052 | P13: 0.4278 | Q13: 1.358 | R13: 2.1902 | S13: STN | T13: Áerea | U13: Sí | AA13: LINEA OPERADA POR ISA
A14: =VLOOKUP(E14,'[2]Listas Desplegables'!$H$3:$J$7,2,FALSE) -> #N/A | B14: =VLOOKUP(E14,'[2]Listas Desplegables'!$H$3:$J$7,3,FALSE) -> #N/A | C14: 9 | D14: OCAIC25 | E14: OCANA | F14: CONVENCION | G14: 115 | H14: 33.67 | I14: 660 | J14: 661 | K14: 660 | L14: Transformador de corriente | M14: 0.1209 | N14: 0.4927 | O14: 3.3617 | P14: 0.4094 | Q14: 1.3655 | R14: 1.9414 | S14: STR | T14: Áerea | U14: Sí | W14: 477 - Aluminio | X14: 4.56625 | Y14: 45.6625 | Z14: 10
A15: =VLOOKUP(E15,'[2]Listas Desplegables'!$H$3:$J$7,2,FALSE) -> #N/A | B15: =VLOOKUP(E15,'[2]Listas Desplegables'!$H$3:$J$7,3,FALSE) -> #N/A | C15: 10 | D15: CONS95 | E15: CONVENCION | F15: PLANTA TIBU | G15: 115 | H15: 79.22 | I15: 300 | J15: 300 | K15: 300 | L15: Linea | M15: 0.4291201 | N15: 0.5960744 | O15: 3.176718 | P15: 0.7204369 | Q15: 1.65666 | R15: 1.80959 | S15: STR | T15: Áerea | U15: Sí | W15: 300 - Aluminio | X15: 9.6074635 | Y15: 951.13889 | Z15: 99
A16: =VLOOKUP(E16,'[2]Listas Desplegables'!$H$3:$J$7,2,FALSE) -> #N/A | B16: =VLOOKUP(E16,'[2]Listas Desplegables'!$H$3:$J$7,3,FALSE) -> #N/A | C16: 11 | D16: INSIL60 | E16: INSULA | F16: BELEN | G16: 115 | H16: 21.38 | I16: 661 | J16: 859 | K16: 793.6 | L16: Transformador de corriente | M16: 0.121 | N16: 0.3784 | O16: 0.4874 | P16: 1.2775 | Q16: 3.4074 | R16: 1.9498 | S16: STR | T16: Áerea | U16: Sí | W16: 477 - Aluminio | X16: 24.722454 | Y16: 148.33472 | Z16: 6 | AA16: Esta línea sera seccionada con la entrada en operación de la subestación Tonchala en el km 18.38 sentido Insula - Belén
A17: =VLOOKUP(E17,'[2]Listas Desplegables'!$H$3:$J$7,2,FALSE) -> #N/A | B17: =VLOOKUP(E17,'[2]Listas Desplegables'!$H$3:$J$7,3,FALSE) -> #N/A | C17: 12 | D17: PLZS10 | E17: PLANTA ZULIA | F17: INSULA | G17: 115 | H17: 31.24 | I17: 350 | J17: 490 | K17: 350 | L17: Transformador de corriente | M17: 0.2091604 | N17: 0.495041 | O17: 3.321633 | P17: 0.5004 | Q17: 1.5556 | R17: 1.85562 | S17: STR | T17: Áerea | U17: Sí | W17: 300 - Aluminio | X17: 4.4133025 | Y17: 39.719722 | Z17: 9
A18: =VLOOKUP(E18,'[2]Listas Desplegables'!$H$3:$J$7,2,FALSE) -> #N/A | B18: =VLOOKUP(E18,'[2]Listas Desplegables'!$H$3:$J$7,3,FALSE) -> #N/A | C18: 13 | D18: SANIL15 | E18: INSULA | F18: SAN MATEO | G18: 115 | H18: 13.601 | I18: 910 | J18: 910 | K18: 970 | L18: Transformador de corriente | M18: 0.0801201 | N18: 0.4582712 | O18: 3.601048 | P18: 0.3714369 | Q18: 1.51886 | R18: 1.9395 | S18: STR | T18: Áerea | U18: Sí | W18: 795 - Aluminio | X18: 1.1416667 | Y18: 2.2833333 | Z18: 2 | AA18: LA INSULA (CUCUTA) - SAN MATEO (CUCUTA) 1 115 Kv
C19: 14 | D19: SAN MATEO 230 - OCAÑA 230 | E19: San Mateo | F19: Ocaña | G19: 230 | H19: 1 | I19: 875 | M19: 0.0647 | N19: 0.5131 | O19: 3.3254 | P19: 0.292 | Q19: 1.0764 | R19: 2.1992 | S19: STN | T19: Áerea | U19: Sí | AA19: LINEA OPERADA POR ISA
A20: =VLOOKUP(E20,'[2]Listas Desplegables'!$H$3:$J$7,2,FALSE) -> #N/A | B20: =VLOOKUP(E20,'[2]Listas Desplegables'!$H$3:$J$7,3,FALSE) -> #N/A | C20: 15 | D20: PLZS20 | E20: PLANTA ZULIA | F20: PLANTA TIBU | G20: 115 | H20: 68.34 | I20: 300 | J20: 490 | K20: 300 | L20: Transformador de corriente | M20: 0.2091 | N20: 0.4951 | O20: 3.3216 | P20: 0.5004 | Q20: 1.5556 | R20: 1.8556 | S20: STR | T20: Áerea | U20: Sí | W20: 300 - Aluminio | X20: 14.219943 | Y20: 483.47806 | Z20: 34
C21: 16 | D21: TERMOTASAJERO 230 - SAN MATEO 230 | E21: Termotasajero | F21: San Mateo | G21: 230 | H21: 1 | I21: 860 | M21: 0.0666 | N21: 0.4946 | O21: 3.342 | P21: 0.289 | Q21: 0.924 | R21: 2.696 | S21: STN | T21: Áerea | U21: Sí | AA21: LINEA OPERADA POR ISA
C22: 17 | D22: TOLEDO 230 - SAMORE 230 | E22: Toledo | F22: Samore | G22: 220 | H22: 1 | I22: 868 | M22: 0.0682 | N22: 0.5266 | O22: 3.2315 | P22: 0.3002 | Q22: 1.0499 | R22: 2.1945 | S22: STN | T22: Áerea | U22: Sí | AA22: LINEA OPERADA POR ISA
A23: =VLOOKUP(E23,'[2]Listas Desplegables'!$H$3:$J$7,2,FALSE) -> #N/A | B23: =VLOOKUP(E23,'[2]Listas Desplegables'!$H$3:$J$7,3,FALSE) -> #N/A | C23: 18 | D23: SANOL45 | E23: SAN MATEO | F23: EL SAMAN | G23: 34.5 | H23: 4.6271 | I23: 454 | M23: 0.2123465 | N23: 0.3569778 | O23: 4.752502 | P23: 0.3855992 | Q23: 1.97044 | R23: 1.443583 | S23: SDL | T23: Áerea | U23: Sí | W23: 266.8 - Aluminio | X23: 3.3468519 | Y23: 10.040556 | Z23: 3
A24: =VLOOKUP(E24,'[2]Listas Desplegables'!$H$3:$J$7,2,FALSE) -> #N/A | B24: =VLOOKUP(E24,'[2]Listas Desplegables'!$H$3:$J$7,3,FALSE) -> #N/A | C24: 19 | D24: SANOL35 | E24: SAN MATEO | F24: ESCOBAL | G24: 34.5 | H24: 10.1513 | I24: 357 | M24: 0.2647822 | N24: 0.3778648 | O24: 4.638185 | P24: 0.4380348 | Q24: 1.991327 | R24: 1.432903 | S24: SDL | T24: Áerea | U24: Sí | W24: 4/0 - Aluminio | X24: 9.6713194 | Y24: 77.370556 | Z24: 8
A25: =VLOOKUP(E25,'[2]Listas Desplegables'!$H$3:$J$7,2,FALSE) -> #N/A | B25: =VLOOKUP(E25,'[2]Listas Desplegables'!$H$3:$J$7,3,FALSE) -> #N/A | C25: 20 | D25: INSC77 | E25: ÍNSULA | F25: ATALAYA | G25: 34.5 | H25: 7.56 | I25: 357 | M25: 0.2647822 | N25: 0.3778648 | O25: 4.638185 | P25: 0.4380348 | Q25: 1.991327 | R25: 1.432903 | S25: SDL | T25: Áerea | U25: Sí | W25: 4/0 - Aluminio | X25: 4.0009127 | Y25: 28.006389 | Z25: 7
A26: =VLOOKUP(E26,'[2]Listas Desplegables'!$H$3:$J$7,2,FALSE) -> #N/A | B26: =VLOOKUP(E26,'[2]Listas Desplegables'!$H$3:$J$7,3,FALSE) -> #N/A | C26: 21 | D26: BEL35_1_PATIOS | E26: BELÉN | F26: LOS PATIOS | G26: 34.5 | H26: 7.9783 | I26: 357 | M26: 0.2647822 | N26: 0.3778648 | O26: 4.638185 | P26: 0.4380348 | Q26: 1.991327 | R26: 1.432903 | S26: SDL | T26: Áerea | U26: Sí | W26: 4/0 - Aluminio | X26: 2.8313105 | Y26: 110.42111 | Z26: 39 | AA26: Linea con salida desde la subestación Belén hasta la subestación Patios 34.5 kV
A27: =VLOOKUP(E27,'[2]Listas Desplegables'!$H$3:$J$7,2,FALSE) -> #N/A | B27: =VLOOKUP(E27,'[2]Listas Desplegables'!$H$3:$J$7,3,FALSE) -> #N/A | C27: 22 | D27: BEL35_2_PALERMO | E27: BELÉN | F27: PALERMO | G27: 34.5 | H27: 31.1713 | I27: 357 | M27: 0.2647822 | N27: 0.3778648 | O27: 4.638185 | P27: 0.4380348 | Q27: 1.991327 | R27: 1.432903 | S27: SDL | T27: Áerea | U27: Sí | W27: 4/0 - Aluminio | X27: 7.1732738 | Y27: 200.85167 | Z27: 28 | AA27: Linea con salida desde la subestación Patios 34.5 kV hasta la Subestación Palermo
A28: =VLOOKUP(E28,'[2]Listas Desplegables'!$H$3:$J$7,2,FALSE) -> #N/A | B28: =VLOOKUP(E28,'[2]Listas Desplegables'!$H$3:$J$7,3,FALSE) -> #N/A | C28: 23 | D28: TOLPALERMO_1_PAMPLONA | E28: TOLEDO | F28: PAMPLONA | G28: 34.5 | H28: 31.5998 | I28: 357 | M28: 0.2647822 | N28: 0.3778648 | O28: 4.638185 | P28: 0.4380348 | Q28: 1.991327 | R28: 1.432903 | S28: SDL | T28: Áerea | U28: Sí | W28: 4/0 - Aluminio | X28: 0.38722222 | Y28: 0.77444444 | Z28: 2
A29: =VLOOKUP(E29,'[2]Listas Desplegables'!$H$3:$J$7,2,FALSE) -> #N/A | B29: =VLOOKUP(E29,'[2]Listas Desplegables'!$H$3:$J$7,3,FALSE) -> #N/A | C29: 24 | D29: TOLPALERMO_2_PALERMO | E29: TOLEDO | F29: PALERMO | G29: 34.5 | H29: 28.3024 | I29: 357 | M29: 0.2647822 | N29: 0.3778648 | O29: 4.638185 | P29: 0.4380348 | Q29: 1.991327 | R29: 1.432903 | S29: SDL | T29: Áerea | U29: Sí | W29: 4/0 - Aluminio | X29: 1.621963 | Y29: 97.317778 | Z29: 60
A30: =VLOOKUP(E30,'[2]Listas Desplegables'!$H$3:$J$7,2,FALSE) -> #N/A | B30: =VLOOKUP(E30,'[2]Listas Desplegables'!$H$3:$J$7,3,FALSE) -> #N/A | C30: 25 | D30: BUTC2 | E30: BUTURAMA | F30: MONTESITOS | G30: 34.5 | H30: 30.2476 | I30: 276 | M30: 0.4199826 | N30: 0.3954189 | O30: 4.412274 | P30: 0.5932353 | Q30: 2.008881 | R30: 1.410682 | S30: SDL | T30: Áerea | U30: Sí | W30: 2/0 - Aluminio | X30: 1.3298977 | Y30: 50.536111 | Z30: 38
A31: =VLOOKUP(E31,'[2]Listas Desplegables'!$H$3:$J$7,2,FALSE) -> #N/A | B31: =VLOOKUP(E31,'[2]Listas Desplegables'!$H$3:$J$7,3,FALSE) -> #N/A | C31: 26 | D31: BUTC1 | E31: BUTURAMA | F31: GAMARRA | G31: 34.5 | H31: 15.0876 | I31: 528 | M31: 0.1681272 | N31: 0.3430972 | O31: 4.899959 | P31: 0.3413799 | Q31: 1.956559 | R31: 1.456839 | S31: SDL | T31: Áerea | U31: Sí | W31: 336.4 - Aluminio | X31: 1.6370494 | Y31: 73.667222 | Z31: 45
A32: =VLOOKUP(E32,'[2]Listas Desplegables'!$H$3:$J$7,2,FALSE) -> #N/A | B32: =VLOOKUP(E32,'[2]Listas Desplegables'!$H$3:$J$7,3,FALSE) -> #N/A | C32: 27 | D32: AYAA31_1_LA_MATA | E32: AYACUCHO | F32: LA MATA | G32: 34.5 | H32: 4.5961 | I32: 454 | M32: 0.2123465 | N32: 0.3569778 | O32: 4.752502 | P32: 0.3855992 | Q32: 1.97044 | R32: 1.443583 | S32: SDL | T32: Áerea | U32: Sí | W32: 266.8 - Aluminio | X32: 0.80483333 | Y32: 12.0725 | Z32: 15
A33: =VLOOKUP(E33,'[2]Listas Desplegables'!$H$3:$J$7,2,FALSE) -> #N/A | B33: =VLOOKUP(E33,'[2]Listas Desplegables'!$H$3:$J$7,3,FALSE) -> #N/A | C33: 28 | D33: AYAA31_2_PELAYA | E33: AYACUCHO | F33: PELAYA | G33: 34.5 | H33: 9.6779 | I33: 454 | M33: 0.2123465 | N33: 0.3569778 | O33: 4.752502 | P33: 0.3855992 | Q33: 1.97044 | R33: 1.443583 | S33: SDL | T33: Áerea | U33: Sí | W33: 266.8 - Aluminio | X33: 1.8237719 | Y33: 34.651667 | Z33: 19
A34: =VLOOKUP(E34,'[2]Listas Desplegables'!$H$3:$J$7,2,FALSE) -> #N/A | B34: =VLOOKUP(E34,'[2]Listas Desplegables'!$H$3:$J$7,3,FALSE) -> #N/A | C34: 29 | D34: CONS65_1_SAN PABLO | E34: CONVENCIÓN | F34: SAN PABLO | G34: 34.5 | H34: 12.9854 | I34: 357 | M34: 0.2647822 | N34: 0.3778648 | O34: 4.638185 | P34: 0.4380348 | Q34: 1.991327 | R34: 1.432903 | S34: SDL | T34: Áerea | U34: Sí | W34: 4/0 - Aluminio | X34: 3.6026736 | Y34: 57.642778 | Z34: 16
A35: =VLOOKUP(E35,'[2]Listas Desplegables'!$H$3:$J$7,2,FALSE) -> #N/A | B35: =VLOOKUP(E35,'[2]Listas Desplegables'!$H$3:$J$7,3,FALSE) -> #N/A | C35: 30 | D35: CONS65_2_EL TARRA | E35: CONVENCIÓN | F35: EL TARRA | G35: 34.5 | H35: 20.8141 | I35: 357 | M35: 0.2647822 | N35: 0.3778648 | O35: 4.638185 | P35: 0.4380348 | Q35: 1.991327 | R35: 1.432903 | S35: SDL | T35: Áerea | U35: Sí | W35: 4/0 - Aluminio | X35: 1.5070694 | Y35: 30.141389 | Z35: 20
A36: =VLOOKUP(E36,'[2]Listas Desplegables'!$H$3:$J$7,2,FALSE) -> #N/A | B36: =VLOOKUP(E36,'[2]Listas Desplegables'!$H$3:$J$7,3,FALSE) -> #N/A | C36: 31 | D36: BEL33_1_EL_ZULIA | E36: BELÉN | F36: EL ZULIA | G36: 34.5 | H36: 14.8159 | I36: 454 | M36: 0.2123465 | N36: 0.3569778 | O36: 4.752502 | P36: 0.3855992 | Q36: 1.97044 | R36: 1.443583 | S36: SDL | T36: Áerea | U36: Sí | W36: 266.8 - Aluminio | X36: 4.1439181 | Y36: 78.734444 | Z36: 19
A37: =VLOOKUP(E37,'[2]Listas Desplegables'!$H$3:$J$7,2,FALSE) -> #N/A | B37: =VLOOKUP(E37,'[2]Listas Desplegables'!$H$3:$J$7,3,FALSE) -> #N/A | C37: 32 | D37: BEL33_2_CULEBRA | E37: BELÉN | F37: CULEBRA | G37: 34.5 | H37: 14.1137 | I37: 454 | M37: 0.2123465 | N37: 0.3569778 | O37: 4.752502 | P37: 0.3855992 | Q37: 1.97044 | R37: 1.443583 | S37: SDL | T37: Áerea | U37: Sí | W37: 266.8 - Aluminio | X37: 5.0255093 | Y37: 30.153056 | Z37: 6
A38: =VLOOKUP(E38,'[2]Listas Desplegables'!$H$3:$J$7,2,FALSE) -> #N/A | B38: =VLOOKUP(E38,'[2]Listas Desplegables'!$H$3:$J$7,3,FALSE) -> #N/A | C38: 33 | D38: BEL36_1_CORNEJO | E38: BELÉN | F38: CORNEJO | G38: 34.5 | H38: 15.5733 | I38: 454 | M38: 0.2123465 | N38: 0.3569778 | O38: 4.752502 | P38: 0.3855992 | Q38: 1.97044 | R38: 1.443583 | S38: SDL | T38: Áerea | U38: Sí | W38: 266.8 - Aluminio | X38: 3.0663981 | Y38: 91.991944 | Z38: 30 | AA38: Se toman los datos desde la salida de la subestación Belén hasta la derivación que parte hacia la subestación Cornejo
A39: =VLOOKUP(E39,'[2]Listas Desplegables'!$H$3:$J$7,2,FALSE) -> #N/A | B39: =VLOOKUP(E39,'[2]Listas Desplegables'!$H$3:$J$7,3,FALSE) -> #N/A | C39: 34 | D39: BEL36_2_GUADUAS | E39: BELÉN | F39: GUADUAS | G39: 34.5 | H39: 7.1824 | I39: 454 | M39: 0.2123465 | N39: 0.3569778 | O39: 4.752502 | P39: 0.3855992 | Q39: 1.97044 | R39: 1.443583 | S39: SDL | T39: Áerea | U39: Sí | W39: 266.8 - Aluminio | X39: 5.8297222 | Y39: 11.659444 | Z39: 2 | AA39: Se toman los datos desde el punto de derivación de la Subestación Cornejo hasta la entrada de la subestación Guaduas
A40: =VLOOKUP(E40,'[2]Listas Desplegables'!$H$3:$J$7,2,FALSE) -> #N/A | B40: =VLOOKUP(E40,'[2]Listas Desplegables'!$H$3:$J$7,3,FALSE) -> #N/A | C40: 35 | D40: BEL36_3_SALAZAR | E40: BELÉN | F40: SALAZAR | G40: 34.5 | H40: 10.6954 | I40: 493 | M40: 0.1880238 | N40: 0.3462468 | O40: 4.844879 | P40: 0.3612764 | Q40: 1.959709 | R40: 1.451954 | S40: SDL | T40: Áerea | U40: Sí | W40: 300 - Aluminio | X40: 7.5031145 | Y40: 247.60278 | Z40: 33 | AA40: Se toman los datos desde el nodo FMVE4430 hasta la entrada S/E Salazar
C41: 36 | D41: CORNEJO_DERIVACIÓN_SALAZAR-GRAMALOTE | E41: CORNEJO | F41: Node_FMVE4430 | G41: 34.5 | H41: 15.663 | I41: 493 | M41: 0.1880238 | N41: 0.3462468 | O41: 4.844879 | P41: 0.3612764 | Q41: 1.959709 | R41: 1.451954 | S41: SDL | T41: Áerea | U41: Sí | W41: 300 - Aluminio | AA41: Se toman los datos desde el punto de derivación de la subestación Cornejo hasta el nodo físico FMVE4430 en el cual derivan dos circuitos de 34.5 kV (ver mas a detalle en los diagramas unifilares y archivos georeferenciados)
A42: =VLOOKUP(E42,'[2]Listas Desplegables'!$H$3:$J$7,2,FALSE) -> #N/A | B42: =VLOOKUP(E42,'[2]Listas Desplegables'!$H$3:$J$7,3,FALSE) -> #N/A | C42: 37 | D42: BEL36_4_GRAMALOTE | E42: BELÉN | F42: GRAMALOTE | G42: 34.5 | H42: 10.8042 | I42: 454 | M42: 0.2123465 | N42: 0.3569778 | O42: 4.752502 | P42: 0.3855992 | Q42: 1.97044 | R42: 1.443583 | S42: SDL | T42: Áerea | U42: Sí | W42: 266.8 - Aluminio | X42: 0.73324074 | Y42: 35.195556 | Z42: 48 | AA42: Se toman los datos desde la derivación en el nodo FMVE4430 hasta la entrada de la S/E Gramalote
A43: =VLOOKUP(E43,'[2]Listas Desplegables'!$H$3:$J$7,2,FALSE) -> #N/A | B43: =VLOOKUP(E43,'[2]Listas Desplegables'!$H$3:$J$7,3,FALSE) -> #N/A | C43: 38 | D43: BEL36_5_SARDINATA | E43: BELÉN | F43: SARDINATA | G43: 34.5 | H43: 25.5886 | I43: 454 | M43: 0.2123465 | N43: 0.3569778 | O43: 4.752502 | P43: 0.3855992 | Q43: 1.97044 | R43: 1.443583 | S43: SDL | T43: Áerea | U43: Sí | W43: 266.8 - Aluminio | X43: 0.14253704 | Y43: 2.1380556 | Z43: 15 | AA43: Se toman los datos desde la derivación de la S/E Gramalote hasta la entrada a la S/E Salazar
...

Sheet 2. Tr3
C3: Información General de Transformadores Tridevanados
C4: No. | D4: ='Manual de Uso'!C53 -> Nombre | E4: ='Manual de Uso'!C54 -> Subestación | F4: ='Manual de Uso'!C55 -> Nivel de tensión HV [kV] | G4: ='Manual de Uso'!C56 -> Nivel de tensión MV [kV] | H4: ='Manual de Uso'!C57 -> Nivel de tensión LV [kV] | I4: ='Manual de Uso'!C58 -> Capacidad HV [MVA] | J4: ='Manual de Uso'!C59 -> Capacidad MV [MVA] | K4: ='Manual de Uso'!C60 -> Capacidad LV [MVA] | L4: ='Manual de Uso'!C61 -> Grupo de conexión | M4: ='Manual de Uso'!C62 -> Impedancia HV-MV Secuencia +[%] | N4: ='Manual de Uso'!C63 -> Impedancia HV-LV Secuencia +[%] | O4: ='Manual de Uso'!C64 -> Impedancia MV-LV Secuencia +[%] | P4: ='Manual de Uso'!C65 -> Impedancia HV-MV Secuencia 0[%] | Q4: ='Manual de Uso'!C66 -> Impedancia HV-LV Secuencia 0[%] | R4: ='Manual de Uso'!C67 -> Impedancia MV-LV Secuencia 0[%] | S4: ='Manual de Uso'!C68 -> Posición Neutral Tap | T4: ='Manual de Uso'!C69 -> Posición Máxima Tap | U4: ='Manual de Uso'!C70 -> Posición Mínima Tap | V4: ='Manual de Uso'!C71 -> Delta Tap [%] | W4: ='Manual de Uso'!C72 -> Sobrecarga en emergencia | Y4: ='Manual de Uso'!C73 -> En Operación | Z4: ='Manual de Uso'!C74 -> FPO | AA4: ='Manual de Uso'!C75 -> Sistema | AB4: ='Manual de Uso'!C76 -> Pérdidas Cu HV-MV [kW] | AC4: ='Manual de Uso'!C77 -> Pérdidas Cu HV-LV [kW] | AD4: ='Manual de Uso'!C78 -> Pérdidas Cu MV-LV [kW] | AE4: ='Manual de Uso'!C79 -> Tiempo medio de reparación por evento [h] | AF4: ='Manual de Uso'!C80 -> Horas anuales de indisponibilidad [h] | AG4: ='Manual de Uso'!C81 -> Eventos anuales de indisponibilidad | AH4: ='Manual de Uso'!C82 -> Observaciones transportador
W5: Magnitud [%] | X5: Tiempo [minutos]
A6: =VLOOKUP(E6,'[2]Listas Desplegables'!$H$3:$J$7,2,FALSE) -> #N/A | B6: =VLOOKUP(E6,'[2]Listas Desplegables'!$H$3:$J$7,3,FALSE) -> #N/A | C6: 1 | D6: TI-01 | E6: San Mateo | F6: 230 | G6: 115 | H6: 13.8 | I6: 150 | J6: 150 | K6: 25 | L6: YN0yn0d0 | M6: 15.35 | N6: 5.88 | O6: 3.03 | P6: 15.35 | Q6: 3.0321 | R6: 5.88 | S6: 9 | T6: 17 | U6: 1 | V6: 1.25 | Y6: Sí | AA6: STR | AB6: 480 | AC6: 24.9 | AD6: 54.79 | AH6: Operado por ISA
A7: =VLOOKUP(E7,'[2]Listas Desplegables'!$H$3:$J$7,2,FALSE) -> #N/A | B7: =VLOOKUP(E7,'[2]Listas Desplegables'!$H$3:$J$7,3,FALSE) -> #N/A | C7: 2 | D7: TI-05 | E7: Ocaña | F7: 220 | G7: 115 | H7: 13.8 | I7: 90 | J7: 90 | K7: 30 | L7: YN0yn0d0 | M7: 8.7 | N7: 7 | O7: 3,5 | P7: 8.7 | Q7: 7 | R7: 3,5 | S7: 9 | T7: 21 | U7: 1 | V7: 1.25 | Y7: Sí | AA7: STR | AB7: 85,5 | AC7: 202 | AD7: 100,4 | AH7: Operado por ISA
A8: =VLOOKUP(E8,'[2]Listas Desplegables'!$H$3:$J$7,2,FALSE) -> #N/A | B8: =VLOOKUP(E8,'[2]Listas Desplegables'!$H$3:$J$7,3,FALSE) -> #N/A | C8: 3 | D8: TS-89 | E8: Ocaña | F8: 220 | G8: 115 | H8: 13.8 | I8: 90 | J8: 90 | K8: 30 | L8: YN0yn0d0 | M8: 8.7 | N8: 7 | O8: 3,5 | P8: 8.7 | Q8: 7 | R8: 3,5 | S8: 9 | T8: 21 | U8: 1 | V8: 1.25 | Y8: Sí | AA8: STR | AB8: 85,5 | AC8: 202 | AD8: 100,4 | AE8: 3.5211111 | AF8: 10.563333 | AG8: 3
A9: =VLOOKUP(E9,'[2]Listas Desplegables'!$H$3:$J$7,2,FALSE) -> #N/A | B9: =VLOOKUP(E9,'[2]Listas Desplegables'!$H$3:$J$7,3,FALSE) -> #N/A | C9: 4 | D9: TS-90 - OCAÑA 1 | E9: Ocaña | F9: 220 | G9: 115 | H9: 13.8 | I9: 90 | J9: 90 | K9: 30 | L9: YN0yn0d0 | M9: 8.7 | N9: 9.2 | O9: 6.1 | P9: 8.7 | Q9: 9.2 | R9: 6.1 | S9: 9 | T9: 21 | U9: 1 | V9: 1.25 | Y9: Sí | AA9: STR | AB9: 183 | AC9: 58.4 | AD9: 59 | AE9: 2.3372222 | AF9: 2.3372222 | AG9: 1
A10: =VLOOKUP(E10,'[2]Listas Desplegables'!$H$3:$J$7,2,FALSE) -> #N/A | B10: =VLOOKUP(E10,'[2]Listas Desplegables'!$H$3:$J$7,3,FALSE) -> #N/A | C10: 5 | D10: TS01 | E10: Belén | F10: 230 | G10: 115 | H10: 13.8 | I10: 150 | J10: 150 | K10: 50 | L10: YN0yn0d0 | M10: 16.01 | N10: 6.4 | O10: 3.4 | P10: 16.01 | Q10: 6.4 | R10: 3.4 | S10: 13 | T10: 27 | U10: 1 | V10: 1.25 | Y10: Sí | AA10: STR | AB10: 337.1 | AC10: 162.4 | AD10: 15 | AE10: 3.8810185 | AF10: 11.643056 | AG10: 3
A11: =VLOOKUP(E11,'[2]Listas Desplegables'!$H$3:$J$7,2,FALSE) -> #N/A | B11: =VLOOKUP(E11,'[2]Listas Desplegables'!$H$3:$J$7,3,FALSE) -> #N/A | C11: 6 | D11: TS2 | E11: San Mateo | F11: 230 | G11: 115 | H11: 13.8 | I11: 150 | J11: 150 | K11: 25 | L11: YN0yn0d0 | M11: 16 | N11: 6.1 | O11: 3 | P11: 16 | Q11: 6.1 | R11: 3 | S11: 9 | T11: 17 | U11: 1 | V11: 1.25 | Y11: Sí | AA11: STR | AB11: 162.4 | AC11: 15 | AD11: 15 | AE11: 32.354722 | AF11: 32.354722 | AG11: 1
A12: =VLOOKUP(E14,'[2]Listas Desplegables'!$H$3:$J$7,2,FALSE) -> #N/A | B12: =VLOOKUP(E14,'[2]Listas Desplegables'!$H$3:$J$7,3,FALSE) -> #N/A | C12: 7 | D12: TI-08 TOLEDO 50MVA | E12: Toledo | F12: 220 | G12: 34.5 | H12: 13.8 | I12: 50 | J12: 50 | K12: 16.6 | L12: YN0yn0d0 | M12: 17.1 | N12: 9.185 | O12: 3.741 | P12: 17.1 | Q12: 9.185 | R12: 3.741 | S12: 9 | T12: 21 | U12: 1 | V12: 1.012 | Y12: Sí | AA12: STN | AB12: 206.4 | AC12: 0 | AD12: 0 | AH12: Operado por ISA
A13: =VLOOKUP(E15,'[2]Listas Desplegables'!$H$3:$J$7,2,FALSE) -> #N/A | B13: =VLOOKUP(E15,'[2]Listas Desplegables'!$H$3:$J$7,3,FALSE) -> #N/A | C13: 8 | D13: TI07-SAMORE-50MVA | E13: Samore | F13: 220 | G13: 34.5 | H13: 13.8 | I13: 50 | J13: 50 | K13: 16.6 | L13: YN0yn0d1 | M13: 17 | N13: 10.469 | O13: 3.812 | P13: 17 | Q13: 10.469 | R13: 3.812 | S13: 9 | T13: 21 | U13: 1 | V13: 1.012 | Y13: Sí | AA13: STN | AB13: 206.4 | AC13: 50 | AD13: 0 | AH13: Operado por ISA
A14: =VLOOKUP(#REF!,'[2]Listas Desplegables'!$H$3:$J$7,2,FALSE) -> #REF! | B14: =VLOOKUP(#REF!,'[2]Listas Desplegables'!$H$3:$J$7,3,FALSE) -> #REF! | C14: 9
A15: =VLOOKUP(#REF!,'[2]Listas Desplegables'!$H$3:$J$7,2,FALSE) -> #REF! | B15: =VLOOKUP(#REF!,'[2]Listas Desplegables'!$H$3:$J$7,3,FALSE) -> #REF! | C15: 10
A16: =VLOOKUP(E16,'[2]Listas Desplegables'!$H$3:$J$7,2,FALSE) -> #N/A | B16: =VLOOKUP(E16,'[2]Listas Desplegables'!$H$3:$J$7,3,FALSE) -> #N/A | C16: 11
A17: =VLOOKUP(E17,'[2]Listas Desplegables'!$H$3:$J$7,2,FALSE) -> #N/A | B17: =VLOOKUP(E17,'[2]Listas Desplegables'!$H$3:$J$7,3,FALSE) -> #N/A | C17: 12
A18: =VLOOKUP(E18,'[2]Listas Desplegables'!$H$3:$J$7,2,FALSE) -> #N/A | B18: =VLOOKUP(E18,'[2]Listas Desplegables'!$H$3:$J$7,3,FALSE) -> #N/A | C18: 13
A19: =VLOOKUP(E19,'[2]Listas Desplegables'!$H$3:$J$7,2,FALSE) -> #N/A | B19: =VLOOKUP(E19,'[2]Listas Desplegables'!$H$3:$J$7,3,FALSE) -> #N/A | C19: 14
A20: =VLOOKUP(E20,'[2]Listas Desplegables'!$H$3:$J$7,2,FALSE) -> #N/A | B20: =VLOOKUP(E20,'[2]Listas Desplegables'!$H$3:$J$7,3,FALSE) -> #N/A | C20: 15
A21: =VLOOKUP(E21,'[2]Listas Desplegables'!$H$3:$J$7,2,FALSE) -> #N/A | B21: =VLOOKUP(E21,'[2]Listas Desplegables'!$H$3:$J$7,3,FALSE) -> #N/A | C21: 16
A22: =VLOOKUP(E22,'[2]Listas Desplegables'!$H$3:$J$7,2,FALSE) -> #N/A | B22: =VLOOKUP(E22,'[2]Listas Desplegables'!$H$3:$J$7,3,FALSE) -> #N/A | C22: 17
A23: =VLOOKUP(E23,'[2]Listas Desplegables'!$H$3:$J$7,2,FALSE) -> #N/A | B23: =VLOOKUP(E23,'[2]Listas Desplegables'!$H$3:$J$7,3,FALSE) -> #N/A | C23: 18
A24: =VLOOKUP(E24,'[2]Listas Desplegables'!$H$3:$J$7,2,FALSE) -> #N/A | B24: =VLOOKUP(E24,'[2]Listas Desplegables'!$H$3:$J$7,3,FALSE) -> #N/A | C24: 19
A25: =VLOOKUP(E25,'[2]Listas Desplegables'!$H$3:$J$7,2,FALSE) -> #N/A | B25: =VLOOKUP(E25,'[2]Listas Desplegables'!$H$3:$J$7,3,FALSE) -> #N/A | C25: 20
A26: =VLOOKUP(E26,'[2]Listas Desplegables'!$H$3:$J$7,2,FALSE) -> #N/A | B26: =VLOOKUP(E26,'[2]Listas Desplegables'!$H$3:$J$7,3,FALSE) -> #N/A | C26: 21
A27: =VLOOKUP(E27,'[2]Listas Desplegables'!$H$3:$J$7,2,FALSE) -> #N/A | B27: =VLOOKUP(E27,'[2]Listas Desplegables'!$H$3:$J$7,3,FALSE) -> #N/A | C27: 22
... A54: =VLOOKUP(E54,'[2]Listas Desplegables'!$H$3:$J$7,2,FALSE) -> #N/A | B54: =VLOOKUP(E54,'[2]Listas Desplegables'!$H$3:$J$7,3,FALSE) -> #N/A | C54: 49
A55: =VLOOKUP(E55,'[2]Listas Desplegables'!$H$3:$J$7,2,FALSE) -> #N/A | B55: =VLOOKUP(E55,'[2]Listas Desplegables'!$H$3:$J$7,3,FALSE) -> #N/A | C55: …

Sheet 3. Tr2
C3: Información General de Transformadores Bidevanados
C4: No. | D4: ='Manual de Uso'!C83 -> Nombre | E4: ='Manual de Uso'!C84 -> Subestación | F4: ='Manual de Uso'!C85 -> Nivel de tensión HV [kV] | G4: ='Manual de Uso'!C86 -> Nivel de tensión LV [kV] | H4: ='Manual de Uso'!C87 -> Capacidad [MVA] | I4: ='Manual de Uso'!C88 -> Grupo de conexión | J4: ='Manual de Uso'!C89 -> Impedancia Secuencia +[%] | K4: ='Manual de Uso'!C90 -> Impedancia Secuencia 0[%] | L4: ='Manual de Uso'!C91 -> Posición Neutral Tap | M4: ='Manual de Uso'!C92 -> Posición Máxima Tap | N4: ='Manual de Uso'!C93 -> Posición Mínima Tap | O4: ='Manual de Uso'!C94 -> Delta Tap [%] | P4: ='Manual de Uso'!C95 -> Sobrecarga en emergencia | R4: ='Manual de Uso'!C96 -> En Operación | S4: ='Manual de Uso'!C97 -> FPO | T4: ='Manual de Uso'!C98 -> Sistema | U4: ='Manual de Uso'!C99 -> Pérdidas Cu [kW] | V4: ='Manual de Uso'!C100 -> Tiempo medio de reparación por evento [h] | W4: ='Manual de Uso'!C101 -> Horas anuales de indisponibilidad [h] | X4: ='Manual de Uso'!C102 -> Eventos anuales de indisponibilidad | Y4: ='Manual de Uso'!C103 -> Observaciones transportador
P5: Magnitud [%] | Q5: Tiempo [minutos]
A6: =VLOOKUP(E6,'[2]Listas Desplegables'!$H$3:$J$7,2,FALSE) -> #N/A | B6: =VLOOKUP(E6,'[2]Listas Desplegables'!$H$3:$J$7,3,FALSE) -> #N/A | C6: 1 | D6: TS04-BELEN-25MVA | E6: Belén | F6: 115 | G6: 13.8 | H6: 25 | I6: YNyn0 | J6: 8.52 | K6: 8.52 | L6: 5 | M6: 15 | N6: 1 | O6: 1.25 | P6: 1.31 | Q6: 30 | R6: Sí | T6: STR | U6: 68.5 | V6: 17.857431 | W6: 71.429722 | X6: 4
A7: =VLOOKUP(E7,'[2]Listas Desplegables'!$H$3:$J$7,2,FALSE) -> #N/A | B7: =VLOOKUP(E7,'[2]Listas Desplegables'!$H$3:$J$7,3,FALSE) -> #N/A | C7: 2 | D7: TS05-BELEN-40MVA | E7: Belén | F7: 115 | G7: 13.8 | H7: 40 | I7: YNyn0 | J7: 12.45 | K7: 12.45 | L7: 5 | M7: 15 | N7: 1 | O7: 1.25 | P7: 1.05 | Q7: 30 | R7: Sí | T7: STR | U7: 115 | V7: 16.077167 | W7: 80.385833 | X7: 5
A8: =VLOOKUP(E8,'[2]Listas Desplegables'!$H$3:$J$7,2,FALSE) -> #N/A | B8: =VLOOKUP(E8,'[2]Listas Desplegables'!$H$3:$J$7,3,FALSE) -> #N/A | C8: 3 | D8: TS06-BELEN-47MVA | E8: Belén | F8: 115 | G8: 34.5 | H8: 47 | I8: YNyn0 | J8: 14.993 | K8: 14.993 | L8: 9 | M8: 17 | N8: 1 | O8: 1.25 | P8: 1.15 | Q8: 30 | R8: Sí | T8: STR | U8: 189.36 | V8: 31.506667 | W8: 31.506667 | X8: 1
A9: =VLOOKUP(E9,'[2]Listas Desplegables'!$H$3:$J$7,2,FALSE) -> #N/A | B9: =VLOOKUP(E9,'[2]Listas Desplegables'!$H$3:$J$7,3,FALSE) -> #N/A | C9: 4 | D9: TS07-SAN_MATEO-47MVA | E9: San Mateo | F9: 115 | G9: 34.5 | H9: 47 | I9: YNyn0 | J9: 14.3663 | K9: 14.3663 | L9: 7 | M9: 15 | N9: 1 | O9: 1.25 | P9: 1.11 | Q9: 30 | R9: Sí | T9: STR | U9: 189.36 | V9: 21.892315 | W9: 65.676944 | X9: 3
A10: =VLOOKUP(E10,'[2]Listas Desplegables'!$H$3:$J$7,2,FALSE) -> #N/A | B10: =VLOOKUP(E10,'[2]Listas Desplegables'!$H$3:$J$7,3,FALSE) -> #N/A | C10: 5 | D10: TS08-SAN_MATEO-47MVA | E10: San Mateo | F10: 115 | G10: 13.8 | H10: 47 | I10: YNyn0 | J10: 15.09 | K10: 15.09 | L10: 9 | M10: 33 | N10: 1 | O10: 0.62 | P10: 1.13 | Q10: 30 | R10: Sí | T10: STR | U10: 250 | V10: 14.771667 | W10: 44.315 | X10: 3
A11: =VLOOKUP(E11,'[2]Listas Desplegables'!$H$3:$J$7,2,FALSE) -> #N/A | B11: =VLOOKUP(E11,'[2]Listas Desplegables'!$H$3:$J$7,3,FALSE) -> #N/A | C11: 6 | D11: TS09-SAN_MATEO-40MVA | E11: San Mateo | F11: 115 | G11: 13.8 | H11: 40 | I11: YNyn0 | J11: 15.09 | K11: 15.09 | L11: 9 | M11: 33 | N11: 1 | O11: 0.62 | P11: 1.05 | Q11: 30 | R11: Sí | T11: STR | U11: 250 | V11: 21.864907 | W11: 65.594722 | X11: 3
A12: =VLOOKUP(E12,'[2]Listas Desplegables'!$H$3:$J$7,2,FALSE) -> #N/A | B12: =VLOOKUP(E12,'[2]Listas Desplegables'!$H$3:$J$7,3,FALSE) -> #N/A | C12: 7 | D12: TS10-ATALAYA-22MVA | E12: Atalaya | F12: 34.5 | G12: 13.8 | H12: 22 | I12: Dyn11 | J12: 5.75 | K12: 5.75 | L12: 3 | M12: 5 | N12: 1 | O12: 2.5 | R12: Sí | T12: SDL | U12: 90 | V12: 9.4780556 | W12: 18.956111 | X12: 2
A13: =VLOOKUP(E13,'[2]Listas Desplegables'!$H$3:$J$7,2,FALSE) -> #N/A | B13: =VLOOKUP(E13,'[2]Listas Desplegables'!$H$3:$J$7,3,FALSE) -> #N/A | C13: 8 | D13: TS12-SEVILLA-20MVA | E13: Sevilla | F13: 115 | G13: 13.8 | H13: 20 | I13: YNyn0 | J13: 9.5 | K13: 9.5 | L13: 7 | M13: 15 | N13: 1 | O13: 1.25 | P13: 1.2 | Q13: 30 | R13: Sí | T13: STR | U13: 96 | V13: 15.956736 | W13: 63.826944 | X13: 4
A14: =VLOOKUP(E14,'[2]Listas Desplegables'!$H$3:$J$7,2,FALSE) -> #N/A | B14: =VLOOKUP(E14,'[2]Listas Desplegables'!$H$3:$J$7,3,FALSE) -> #N/A | C14: 9 | D14: TS14-INSULA-40MVA | E14: Ínsula | F14: 115 | G14: 34.5 | H14: 40 | I14: YNyn0 | J14: 11.99 | K14: 11.99 | L14: 7 | M14: 15 | N14: 1 | O14: 1.25 | P14: 1.05 | Q14: 30 | R14: Sí | T14: STR | U14: 117.5 | V14: 3.0715278 | W14: 12.286111 | X14: 4
A15: =VLOOKUP(E15,'[2]Listas Desplegables'!$H$3:$J$7,2,FALSE) -> #N/A | B15: =VLOOKUP(E15,'[2]Listas Desplegables'!$H$3:$J$7,3,FALSE) -> #N/A | C15: 10 | D15: TS15-INSULA-25MVA | E15: Ínsula | F15: 115 | G15: 13.8 | H15: 25 | I15: YNyn0 | J15: 9.475 | K15: 9.475 | L15: 7 | M15: 15 | N15: 1 | O15: 1 | P15: 1.2 | Q15: 30 | R15: Sí | T15: STR | U15: 62.2727 | V15: 4.6858333 | W15: 9.3716667 | X15: 2
A16: =VLOOKUP(E16,'[2]Listas Desplegables'!$H$3:$J$7,2,FALSE) -> #N/A | B16: =VLOOKUP(E16,'[2]Listas Desplegables'!$H$3:$J$7,3,FALSE) -> #N/A | C16: 11 | D16: TS16-EL_SAMAN-18MVA | E16: El Saman | F16: 34.5 | G16: 13.8 | H16: 18 | I16: Dyn11 | J16: 7.524 | K16: 7.524 | L16: 3 | M16: 5 | N16: 1 | O16: 2.5 | R16: Sí | T16: SDL | U16: 82.2 | V16: 21.8625 | W16: 43.725 | X16: 2
A17: =VLOOKUP(E17,'[2]Listas Desplegables'!$H$3:$J$7,2,FALSE) -> #N/A | B17: =VLOOKUP(E17,'[2]Listas Desplegables'!$H$3:$J$7,3,FALSE) -> #N/A | C17: 12 | D17: TS17-ESCOBAL-12.5MVA | E17: Escobal | F17: 34.5 | G17: 13.8 | H17: 12.5 | I17: Dyn11 | J17: 7.45 | K17: 7.45 | L17: 3 | M17: 5 | N17: 1 | O17: 2.5 | R17: Sí | T17: SDL | U17: 53.5 | V17: 29.215903 | W17: 116.86361 | X17: 4
A18: =VLOOKUP(E18,'[2]Listas Desplegables'!$H$3:$J$7,2,FALSE) -> #N/A | B18: =VLOOKUP(E18,'[2]Listas Desplegables'!$H$3:$J$7,3,FALSE) -> #N/A | C18: 13 | D18: TS19-PLANTA_ZULIA-11MVA | E18: Planta Zulia | F18: 115 | G18: 13.8 | H18: 11 | I18: YNyn0 | J18: 11.1 | K18: 11.1 | L18: 6 | M18: 11 | N18: 1 | O18: 1 | P18: 1.18 | Q18: 30 | R18: Sí | T18: STR | U18: 69.2096 | V18: 3.6266667 | W18: 10.88 | X18: 3
A19: =VLOOKUP(E19,'[2]Listas Desplegables'!$H$3:$J$7,2,FALSE) -> #N/A | B19: =VLOOKUP(E19,'[2]Listas Desplegables'!$H$3:$J$7,3,FALSE) -> #N/A | C19: 14 | D19: TS20-PAMPLONA-12.5MVA | E19: Pamplona | F19: 34.5 | G19: 13.8 | H19: 12.5 | I19: Dyn11 | J19: 7.47 | K19: 7.47 | L19: 3 | M19: 5 | N19: 1 | O19: 2.5 | R19: Sí | T19: SDL | U19: 53.5 | V19: 0 | W19: 0 | X19: 0
A20: =VLOOKUP(E20,'[2]Listas Desplegables'!$H$3:$J$7,2,FALSE) -> #N/A | B20: =VLOOKUP(E20,'[2]Listas Desplegables'!$H$3:$J$7,3,FALSE) -> #N/A | C20: 15 | D20: TS22-LOS_PATIOS-12.5MVA | E20: Los Patios | F20: 34.5 | G20: 13.8 | H20: 12.5 | I20: Dyn11 | J20: 9.3125 | K20: 9.3125 | L20: 3 | M20: 5 | N20: 1 | O20: 2.5 | R20: Sí | T20: SDL | U20: 51.25 | V20: 6.3894444 | W20: 12.778889 | X20: 2
A21: =VLOOKUP(E21,'[2]Listas Desplegables'!$H$3:$J$7,2,FALSE) -> #N/A | B21: =VLOOKUP(E21,'[2]Listas Desplegables'!$H$3:$J$7,3,FALSE) -> #N/A | C21: 16 | D21: TS23-TIBU-18MVA | E21: Tibu | F21: 115 | G21: 13.8 | H21: 18 | I21: Dyn11 | J21: 11.1744 | K21: 11.1744 | L21: 3 | M21: 5 | N21: 1 | O21: 2.5 | P21: 1.11 | Q21: 30 | R21: Sí | T21: STR | U21: 75 | V21: 10.498333 | W21: 10.498333 | X21: 1
A22: =VLOOKUP(E22,'[2]Listas Desplegables'!$H$3:$J$7,2,FALSE) -> #N/A | B22: =VLOOKUP(E22,'[2]Listas Desplegables'!$H$3:$J$7,3,FALSE) -> #N/A | C22: 17 | D22: TS24-TIBU-12MVA | E22: Tibu | F22: 115 | G22: 34.5 | H22: 12 | I22: YNyn0 | J22: 8.8524 | K22: 8.8524 | L22: 3 | M22: 5 | N22: 1 | O22: 2.5 | P22: 1.15 | Q22: 30 | R22: Sí | T22: STR | U22: 51.36 | V22: 7.8519444 | W22: 7.8519444 | X22: 1
A23: =VLOOKUP(E23,'[2]Listas Desplegables'!$H$3:$J$7,2,FALSE) -> #N/A | B23: =VLOOKUP(E23,'[2]Listas Desplegables'!$H$3:$J$7,3,FALSE) -> #N/A | C23: 18 | D23: TS25-CONVENCION-10MVA | E23: Convencion | F23: 115 | G23: 34.5 | H23: 10 | I23: YNyn0 | J23: 11.4625 | K23: 11.4625 | L23: 3 | M23: 5 | N23: 1 | O23: 1.25 | P23: 1.49 | Q23: 30 | R23: Sí | T23: STR | U23: 61.5 | V23: 5.1324306 | W23: 20.529722 | X23: 4
A24: =VLOOKUP(E24,'[2]Listas Desplegables'!$H$3:$J$7,2,FALSE) -> #N/A | B24: =VLOOKUP(E24,'[2]Listas Desplegables'!$H$3:$J$7,3,FALSE) -> #N/A | C24: 19 | D24: TS26-CONVENCION-7MVA | E24: Convencion | F24: 34.5 | G24: 13.8 | H24: 7 | I24: Dyn11 | J24: 6.49 | K24: 6.49 | L24: 3 | M24: 5 | N24: 1 | O24: 2.5 | R24: Sí | T24: SDL | U24: 48.2 | V24: 5.8469841 | W24: 40.928889 | X24: 7
A25: =VLOOKUP(E25,'[2]Listas Desplegables'!$H$3:$J$7,2,FALSE) -> #N/A | B25: =VLOOKUP(E25,'[2]Listas Desplegables'!$H$3:$J$7,3,FALSE) -> #N/A | C25: 20 | D25: TS27-OCAÑA-30MVA | E25: Ocaña | F25: 115 | G25: 13.8 | H25: 30 | I25: Dyn11 | J25: 17.28 | K25: 17.28 | L25: 11 | M25: 26 | N25: 1 | O25: 1 | P25: 1.33 | Q25: 30 | R25: Sí | T25: STR | U25: 120 | V25: 13.343333 | W25: 13.343333 | X25: 1
A26: =VLOOKUP(E26,'[2]Listas Desplegables'!$H$3:$J$7,2,FALSE) -> #N/A | B26: =VLOOKUP(E26,'[2]Listas Desplegables'!$H$3:$J$7,3,FALSE) -> #N/A | C26: 21 | D26: TS28-OCAÑA-8MVA | E26: Ocaña | F26: 115 | G26: 34.5 | H26: 8 | I26: Dyn11 | J26: 11.38 | K26: 11.38 | L26: 3 | M26: 5 | N26: 1 | O26: 2.5 | P26: 1.25 | Q26: 30 | R26: Sí | T26: STR | U26: 47 | V26: 10.14963 | W26: 30.448889 | X26: 3
A27: =VLOOKUP(E27,'[2]Listas Desplegables'!$H$3:$J$7,2,FALSE) -> #N/A | B27: =VLOOKUP(E27,'[2]Listas Desplegables'!$H$3:$J$7,3,FALSE) -> #N/A | C27: 22 | D27: TS29-AYACUCHO-13MVA | E27: Ayacucho | F27: 115 | G27: 34.5 | H27: 13 | I27: YNyn0 | J27: 11.71 | K27: 11.71 | L27: 3 | M27: 5 | N27: 1 | O27: 2.5 | P27: 1.07 | Q27: 30 | R27: Sí | T27: STR | U27: 81.6287 | V27: 0 | W27: 0 | X27: 0
A28: =VLOOKUP(E28,'[2]Listas Desplegables'!$H$3:$J$7,2,FALSE) -> #N/A | B28: =VLOOKUP(E28,'[2]Listas Desplegables'!$H$3:$J$7,3,FALSE) -> #N/A | C28: 23 | D28: TS30-AYACUCHO-3MVA | E28: Ayacucho | F28: 34.5 | G28: 13.8 | H28: 3 | I28: Dyn11 | J28: 6.5 | K28: 6.5 | L28: 3 | M28: 5 | N28: 1 | O28: 2.5 | R28: Sí | T28: SDL | U28: 29 | V28: 0 | W28: 0 | X28: 0
A29: =VLOOKUP(E29,'[2]Listas Desplegables'!$H$3:$J$7,2,FALSE) -> #N/A | B29: =VLOOKUP(E29,'[2]Listas Desplegables'!$H$3:$J$7,3,FALSE) -> #N/A | C29: 24 | D29: TS31-AGUACHICA-32MVA | E29: Aguachica | F29: 115 | G29: 34.5 | H29: 32 | I29: YNyn0 | J29: 11.05 | K29: 11.05 | L29: 8 | M29: 16 | N29: 1 | O29: 1.25 | P29: 1.24 | Q29: 30 | R29: Sí | T29: STR | U29: 135 | V29: 7.0130556 | W29: 21.039167 | X29: 3
A30: =VLOOKUP(E30,'[2]Listas Desplegables'!$H$3:$J$7,2,FALSE) -> #N/A | B30: =VLOOKUP(E30,'[2]Listas Desplegables'!$H$3:$J$7,3,FALSE) -> #N/A | C30: 25 | D30: TS32-AGUACHICA-18MVA | E30: Aguachica | F30: 34.5 | G30: 13.8 | H30: 18 | I30: Dyn11 | J30: 9.804 | K30: 9.804 | L30: 3 | M30: 5 | N30: 1 | O30: 2.5 | R30: Sí | T30: SDL | U30: 68.6 | V30: 5.5018056 | W30: 11.003611 | X30: 2
A31: =VLOOKUP(E31,'[2]Listas Desplegables'!$H$3:$J$7,2,FALSE) -> #N/A | B31: =VLOOKUP(E31,'[2]Listas Desplegables'!$H$3:$J$7,3,FALSE) -> #N/A | C31: 26 | D31: TS34-CORNEJO-5MVA | E31: Cornejo | F31: 34.5 | G31: 13.8 | H31: 5 | I31: Dyn11 | J31: 5.82 | K31: 5.82 | L31: 3 | M31: 5 | N31: 1 | O31: 2.5 | R31: Sí | T31: SDL | U31: 16.5 | V31: 0.41666667 | W31: 0.41666667 | X31: 1
A32: =VLOOKUP(E32,'[2]Listas Desplegables'!$H$3:$J$7,2,FALSE) -> #N/A | B32: =VLOOKUP(E32,'[2]Listas Desplegables'!$H$3:$J$7,3,FALSE) -> #N/A | C32: 27 | D32: TS35-CULEBRA-4MVA | E32: Culebra | F32: 34.5 | G32: 13.8 | H32: 4 | I32: Dyn11 | J32: 6.57 | K32: 6.57 | L32: 3 | M32: 5 | N32: 1 | O32: 2.5 | R32: Sí | T32: SDL | U32: 36.1 | V32: 0 | W32: 0 | X32: 0
A33: =VLOOKUP(E33,'[2]Listas Desplegables'!$H$3:$J$7,2,FALSE) -> #N/A | B33: =VLOOKUP(E33,'[2]Listas Desplegables'!$H$3:$J$7,3,FALSE) -> #N/A | C33: 28 | D33: TS36-SALAZAR-3.5MVA | E33: Salazar | F33: 34.5 | G33: 13.8 | H33: 3.5 | I33: Dyn11 | J33: 5.7 | K33: 5.7 | L33: 3 | M33: 5 | N33: 1 | O33: 2.5 | R33: Sí | T33: SDL | U33: 21.5 | V33: 4.4804167 | W33: 8.9608333 | X33: 2
A34: =VLOOKUP(E34,'[2]Listas Desplegables'!$H$3:$J$7,2,FALSE) -> #N/A | B34: =VLOOKUP(E34,'[2]Listas Desplegables'!$H$3:$J$7,3,FALSE) -> #N/A | C34: 29 | D34: TS38-SARDINATA-4MVA | E34: Sardinata | F34: 34.5 | G34: 13.8 | H34: 4 | I34: Dyn11 | J34: 6.1 | K34: 6.1 | L34: 3 | M34: 5 | N34: 1 | O34: 2.5 | R34: Sí | T34: SDL | U34: 35 | V34: 11.466111 | W34: 11.466111 | X34: 1
A35: =VLOOKUP(E35,'[2]Listas Desplegables'!$H$3:$J$7,2,FALSE) -> #N/A | B35: =VLOOKUP(E35,'[2]Listas Desplegables'!$H$3:$J$7,3,FALSE) -> #N/A | C35: 30 | D35: TS39-EL_TARRA-5MVA | E35: El Tarra | F35: 34.5 | G35: 13.8 | H35: 5 | I35: Dyn5 | J35: 5.98 | K35: 5.98 | L35: 3 | M35: 5 | N35: 1 | O35: 2.5 | R35: Sí | T35: SDL | U35: 20.9 | V35: 0.016190476 | W35: 0.11333333 | X35: 7
A36: =VLOOKUP(E36,'[2]Listas Desplegables'!$H$3:$J$7,2,FALSE) -> #N/A | B36: =VLOOKUP(E36,'[2]Listas Desplegables'!$H$3:$J$7,3,FALSE) -> #N/A | C36: 31 | D36: TS40-GAMARRA-12MVA | E36: Gamarra | F36: 34.5 | G36: 13.8 | H36: 12 | I36: Dyn5 | J36: 8.85 | K36: 8.85 | L36: 3 | M36: 5 | N36: 1 | O36: 2.5 | R36: Sí | T36: SDL | U36: 51.36 | V36: 8.2333333 | W36: 8.2333333 | X36: 1
A37: =VLOOKUP(E37,'[2]Listas Desplegables'!$H$3:$J$7,2,FALSE) -> #N/A | B37: =VLOOKUP(E37,'[2]Listas Desplegables'!$H$3:$J$7,3,FALSE) -> #N/A | C37: 32 | D37: TS42-ORU-2MVA | E37: Oru | F37: 34.5 | G37: 13.8 | H37: 2 | I37: Dyn11 | J37: 5.98 | K37: 5.98 | L37: 3 | M37: 5 | N37: 1 | O37: 2.5 | R37: Sí | T37: SDL | U37: 20.9 | V37: 0.28006236 | W37: 13.723056 | X37: 49
A38: =VLOOKUP(E38,'[2]Listas Desplegables'!$H$3:$J$7,2,FALSE) -> #N/A | B38: =VLOOKUP(E38,'[2]Listas Desplegables'!$H$3:$J$7,3,FALSE) -> #N/A | C38: 33 | D38: TS43-PELAYA-4MVA | E38: Pelaya | F38: 34.5 | G38: 13.8 | H38: 4 | I38: Dyn11 | J38: 6.5 | K38: 6.5 | L38: 3 | M38: 5 | N38: 1 | O38: 2.5 | R38: Sí | T38: SDL | U38: 25.27 | V38: 9.4014815 | W38: 28.204444 | X38: 3
A39: =VLOOKUP(E39,'[2]Listas Desplegables'!$H$3:$J$7,2,FALSE) -> #N/A | B39: =VLOOKUP(E39,'[2]Listas Desplegables'!$H$3:$J$7,3,FALSE) -> #N/A | C39: 34 | D39: TS44-EL_ZULIA-3.5MVA | E39: El Zulia | F39: 34.5 | G39: 13.8 | H39: 4 | I39: Dyn11 | J39: 6.5 | K39: 6.5 | L39: 3 | M39: 5 | N39: 1 | O39: 2.5 | R39: Sí | T39: SDL | U39: 25.27 | V39: 0.5537037 | W39: 1.6611111 | X39: 3
A40: =VLOOKUP(E40,'[2]Listas Desplegables'!$H$3:$J$7,2,FALSE) -> #N/A | B40: =VLOOKUP(E40,'[2]Listas Desplegables'!$H$3:$J$7,3,FALSE) -> #N/A | C40: 35 | D40: TS45-ABREGO-6MVA | E40: Abrego | F40: 34.5 | G40: 13.8 | H40: 6 | I40: Dyn11 | J40: 7.2 | K40: 7.2 | L40: 3 | M40: 5 | N40: 1 | O40: 2.5 | R40: Sí | T40: SDL | U40: 36 | V40: 5.7638889 | W40: 5.7638889 | X40: 1
A41: =VLOOKUP(E41,'[2]Listas Desplegables'!$H$3:$J$7,2,FALSE) -> #N/A | B41: =VLOOKUP(E41,'[2]Listas Desplegables'!$H$3:$J$7,3,FALSE) -> #N/A | C41: 36 | D41: TS46-CAMPO_DOS-12MVA | E41: Campo Dos | F41: 34.5 | G41: 13.8 | H41: 12 | I41: Dyn11 | J41: 8.85 | K41: 8.85 | L41: 3 | M41: 5 | N41: 1 | O41: 2.5 | R41: Sí | T41: SDL | U41: 51.36 | V41: 0.71888177 | W41: 28.036389 | X41: 39
... A48: =VLOOKUP(E48,'[2]Listas Desplegables'!$H$3:$J$7,2,FALSE) -> #N/A | B48: =VLOOKUP(E48,'[2]Listas Desplegables'!$H$3:$J$7,3,FALSE) -> #N/A | C48: 43 | D48: TS67-LOS_ALPES-0.5MVA | E48: Los Alpes | F48: 34.5 | G48: 13.8 | H48: 0.5 | I48: Dyn11 | J48: 6.38 | K48: 6.38 | L48: 3 | M48: 5 | N48: 1 | O48: 2.5 | R48: Sí | T48: SDL | U48: 6.37 | V48: 0.95972222 | W48: 0.95972222 | X48: 1
...

Sheet 4. Subestaciones
C3: Información General de Subestaciones
C4: No. | D4: ='Manual de Uso'!C104 -> Nombre | E4: ='Manual de Uso'!C105 -> Agente Administrador | F4: ='Manual de Uso'!C106 -> Nivel de tensión [kV] | G4: ='Manual de Uso'!C107 -> Capacidad de interrupción [kA] | H4: ='Manual de Uso'!C108 -> Configuración | I4: ='Manual de Uso'!C109 -> Tipo | J4: ='Manual de Uso'!C110 -> En Operación | K4: ='Manual de Uso'!C111 -> FPO | L4: ='Manual de Uso'!C112 -> Departamento | M4: ='Manual de Uso'!C113 -> Municipio | N4: ='Manual de Uso'!C114 -> Observaciones transportador
A6: =VLOOKUP(E6,'[2]Listas Desplegables'!$H$3:$J$7,2,FALSE) -> #N/A | B6: =VLOOKUP(E6,'[2]Listas Desplegables'!$H$3:$J$7,3,FALSE) -> #N/A | C6: 1 | D6: SUBESTACIÓN BELEN | E6: INTERCOLOMBIA | F6: 230 | G6: 30 | H6: Anillo | I6: Convencional | J6: Sí | L6: Norte de Santander | M6: Cúcuta
C7: 2 | D7: SUBESTACIÓN BELEN | E7: CENS | F7: 115 | G7: 31.5 | H7: Anillo | I7: Convencional | J7: Sí | L7: Norte de Santander | M7: Cúcuta
C8: 3 | D8: SUBESTACIÓN BELEN | E8: CENS | F8: 34.5 | G8: 25 | H8: Barra sencilla | I8: Convencional | J8: Sí | L8: Norte de Santander | M8: Cúcuta
A9: =VLOOKUP(E9,'[2]Listas Desplegables'!$H$3:$J$7,2,FALSE) -> #N/A | B9: =VLOOKUP(E9,'[2]Listas Desplegables'!$H$3:$J$7,3,FALSE) -> #N/A | C9: 4 | D9: SUBESTACIÓN SAN MATEO | E9: INTERCOLOMBIA | F9: 230 | G9: 40 | H9: Barra Principal y Barra de Transferencia | I9: Convencional | J9: Sí | L9: Norte de Santander | M9: Cúcuta | N9: INFORMACION DE OTRO OPERADOR
C10: 5 | D10: SUBESTACIÓN SAN MATEO | E10: CENS | F10: 115 | G10: 31.5 | H10: Barra Principal y Barra de Transferencia | I10: Convencional | J10: Sí | L10: Norte de Santander | M10: Cúcuta
C11: 6 | D11: SUBESTACIÓN SAN MATEO | E11: CENS | F11: 34.5 | G11: 25 | H11: Barra sencilla | I11: Convencional | J11: Sí | L11: Norte de Santander | M11: Cúcuta
A12: =VLOOKUP(E12,'[2]Listas Desplegables'!$H$3:$J$7,2,FALSE) -> #N/A | B12: =VLOOKUP(E12,'[2]Listas Desplegables'!$H$3:$J$7,3,FALSE) -> #N/A | C12: 7 | D12: SUBESTACIÓN SEVILLA | E12: CENS | F12: 115 | G12: 31.5 | H12: Barra sencilla | I12: Convencional | J12: Sí | L12: Norte de Santander | M12: Cúcuta
A13: =VLOOKUP(E13,'[2]Listas Desplegables'!$H$3:$J$7,2,FALSE) -> #N/A | B13: =VLOOKUP(E13,'[2]Listas Desplegables'!$H$3:$J$7,3,FALSE) -> #N/A | C13: 8 | D13: SUBESTACIÓN PALERMO | E13: CENS | F13: 34.5 | G13: 25 | H13: Barra sencilla | I13: Convencional | J13: Sí | L13: Norte de Santander | M13: Chinácota
A14: =VLOOKUP(E14,'[2]Listas Desplegables'!$H$3:$J$7,2,FALSE) -> #N/A | B14: =VLOOKUP(E14,'[2]Listas Desplegables'!$H$3:$J$7,3,FALSE) -> #N/A | C14: 9 | D14: SUBESTACIÓN PAMPLONA | E14: CENS | F14: 34.5 | G14: 31.5 | H14: Barra sencilla | I14: Convencional | J14: Sí | L14: Norte de Santander | M14: Pamplona
A15: =VLOOKUP(E15,'[2]Listas Desplegables'!$H$3:$J$7,2,FALSE) -> #N/A | B15: =VLOOKUP(E15,'[2]Listas Desplegables'!$H$3:$J$7,3,FALSE) -> #N/A | C15: 10 | D15: SUBESTACIÓN PLANTA ZULIA | E15: CENS | F15: 115 | G15: 31.5 | H15: Barra sencilla | I15: Convencional | J15: Sí | L15: Norte de Santander | M15: Cúcuta
A16: =VLOOKUP(E16,'[2]Listas Desplegables'!$H$3:$J$7,2,FALSE) -> #N/A | B16: =VLOOKUP(E16,'[2]Listas Desplegables'!$H$3:$J$7,3,FALSE) -> #N/A | C16: 11 | D16: SUBESTACIÓN PLANTA TIBU | E16: CENS | F16: 115 | G16: 40 | H16: Barra sencilla | I16: Convencional | J16: Sí | L16: Norte de Santander | M16: Tibú
C17: 12 | D17: SUBESTACIÓN PLANTA TIBU | E17: CENS | F17: 34.5 | G17: 25 | H17: Barra sencilla | I17: Convencional | J17: Sí | L17: Norte de Santander | M17: Tibú
A18: =VLOOKUP(E18,'[2]Listas Desplegables'!$H$3:$J$7,2,FALSE) -> #N/A | B18: =VLOOKUP(E18,'[2]Listas Desplegables'!$H$3:$J$7,3,FALSE) -> #N/A | C18: 13 | D18: SUBESTACIÓN CONVENCION | E18: CENS | F18: 115 | G18: 15 | H18: Barra sencilla | I18: Convencional | J18: Sí | L18: Norte de Santander | M18: Convención
C19: 14 | D19: SUBESTACIÓN CONVENCION | E19: CENS | F19: 34.5 | G19: 25 | H19: Barra sencilla | I19: Convencional | J19: Sí | L19: Norte de Santander | M19: Convención
A20: =VLOOKUP(E20,'[2]Listas Desplegables'!$H$3:$J$7,2,FALSE) -> #N/A | B20: =VLOOKUP(E20,'[2]Listas Desplegables'!$H$3:$J$7,3,FALSE) -> #N/A | C20: 15 | D20: SUBESTACIÓN OCAÑA | E20: INTERCOLOMBIA | F20: 230 | G20: 31.5 | H20: Barra Principal y Barra de Transferencia | I20: Convencional | J20: Sí | L20: Norte de Santander | M20: Ocaña | N20: INFORMACION DE OTRO OPERADOR
C21: 16 | D21: SUBESTACIÓN OCAÑA | E21: CENS | F21: 115 | G21: 31.5 | H21: Barra Principal y Barra de Transferencia | I21: Convencional | J21: Sí | L21: Norte de Santander | M21: Ocaña
C22: 17 | D22: SUBESTACIÓN OCAÑA | E22: CENS | F22: 34.5 | G22: 25 | H22: Barra sencilla | I22: Convencional | J22: Sí | L22: Norte de Santander | M22: Ocaña
A23: =VLOOKUP(E23,'[2]Listas Desplegables'!$H$3:$J$7,2,FALSE) -> #N/A | B23: =VLOOKUP(E23,'[2]Listas Desplegables'!$H$3:$J$7,3,FALSE) -> #N/A | C23: 18 | D23: SUBESTACIÓN AGUACHICA | E23: CENS | F23: 115 | G23: 31.5 | H23: Barra sencilla | I23: Convencional | J23: Sí | L23: Cesar | M23: Aguachica
C24: 19 | D24: SUBESTACIÓN AGUACHICA | E24: CENS | F24: 34.5 | G24: 25 | H24: Barra sencilla | I24: Convencional | J24: Sí | L24: Cesar | M24: Aguachica
A25: =VLOOKUP(E25,'[2]Listas Desplegables'!$H$3:$J$7,2,FALSE) -> #N/A | B25: =VLOOKUP(E25,'[2]Listas Desplegables'!$H$3:$J$7,3,FALSE) -> #N/A | C25: 20 | D25: SUBESTACIÓN AYACUCHO | E25: CENS | F25: 115 | G25: 31.5 | H25: Barra sencilla | I25: Convencional | J25: Sí | L25: Cesar | M25: La Gloria
C26: 21 | D26: SUBESTACIÓN AYACUCHO | E26: CENS | F26: 34.5 | G26: 25 | H26: Barra sencilla | I26: Convencional | J26: Sí | L26: Cesar | M26: La Gloria
A27: =VLOOKUP(E27,'[2]Listas Desplegables'!$H$3:$J$7,2,FALSE) -> #N/A | B27: =VLOOKUP(E27,'[2]Listas Desplegables'!$H$3:$J$7,3,FALSE) -> #N/A | C27: 22 | D27: SUBESTACIÓN SAMORE | E27: INTERCOLOMBIA | F27: 230 | G27: 31.5 | H27: Barra Principal y Barra de Transferencia | I27: Convencional | J27: Sí | L27: Norte de Santander | M27: Toledo | N27: INFORMACION DE OTRO OPERADOR
A28: =VLOOKUP(E28,'[2]Listas Desplegables'!$H$3:$J$7,2,FALSE) -> #N/A | B28: =VLOOKUP(E28,'[2]Listas Desplegables'!$H$3:$J$7,3,FALSE) -> #N/A | C28: 23 | D28: SUBESTACIÓN TOLEDO | E28: INTERCOLOMBIA | F28: 230 | G28: 31.5 | H28: Barra sencilla | I28: Convencional | J28: Sí | L28: Norte de Santander | M28: Toledo | N28: INFORMACION DE OTRO OPERADOR
C29: 24 | D29: SUBESTACIÓN TOLEDO | E29: CENS | F29: 34.5 | H29: Barra sencilla | I29: Convencional | J29: Sí | L29: Norte de Santander | M29: Toledo | N29: INFORMACION DE OTRO OPERADOR
A30: =VLOOKUP(E30,'[2]Listas Desplegables'!$H$3:$J$7,2,FALSE) -> #N/A | B30: =VLOOKUP(E30,'[2]Listas Desplegables'!$H$3:$J$7,3,FALSE) -> #N/A | C30: 25 | D30: SUBESTACIÓN PATIOS | E30: CENS | F30: 34.5 | G30: 12.5 | H30: Barra sencilla | I30: Convencional | J30: Sí | L30: Norte de Santander | M30: Los Patios
A31: =VLOOKUP(E31,'[2]Listas Desplegables'!$H$3:$J$7,2,FALSE) -> #N/A | B31: =VLOOKUP(E31,'[2]Listas Desplegables'!$H$3:$J$7,3,FALSE) -> #N/A | C31: 26 | D31: SUBESTACIÓN CORNEJO | E31: CENS | F31: 34.5 | G31: 12.5 | H31: Barra sencilla | I31: Convencional | J31: Sí | L31: Norte de Santander | M31: El Zulia
A32: =VLOOKUP(E32,'[2]Listas Desplegables'!$H$3:$J$7,2,FALSE) -> #N/A | B32: =VLOOKUP(E32,'[2]Listas Desplegables'!$H$3:$J$7,3,FALSE) -> #N/A | C32: 27 | D32: SUBESTACIÓN CULEBRA | E32: CENS | F32: 34.5 | G32: 16 | H32: Barra sencilla | I32: Convencional | J32: Sí | L32: Norte de Santander | M32: El Zulia
A33: =VLOOKUP(E33,'[2]Listas Desplegables'!$H$3:$J$7,2,FALSE) -> #N/A | B33: =VLOOKUP(E33,'[2]Listas Desplegables'!$H$3:$J$7,3,FALSE) -> #N/A | C33: 28 | D33: SUBESTACIÓN SALAZAR | E33: CENS | F33: 34.5 | G33: 16 | H33: Barra sencilla | I33: Convencional | J33: Sí | L33: Norte de Santander | M33: Salazar
A34: =VLOOKUP(#REF!,'[2]Listas Desplegables'!$H$3:$J$7,2,FALSE) -> #REF! | B34: =VLOOKUP(#REF!,'[2]Listas Desplegables'!$H$3:$J$7,3,FALSE) -> #REF! | C34: 29 | D34: SUBESTACIÓN SARDINATA | E34: CENS | F34: 34.5 | G34: 25 | H34: Barra sencilla | I34: Convencional | J34: Sí | L34: Norte de Santander | M34: Sardinata
A35: =VLOOKUP(E34,'[2]Listas Desplegables'!$H$3:$J$7,2,FALSE) -> #N/A | B35: =VLOOKUP(E34,'[2]Listas Desplegables'!$H$3:$J$7,3,FALSE) -> #N/A | C35: 30 | D35: SUBESTACIÓN EL TARRA | E35: CENS | F35: 34.5 | G35: 16 | H35: Barra sencilla | I35: Convencional | J35: Sí | L35: Norte de Santander | M35: El Tarra
A36: =VLOOKUP(E35,'[2]Listas Desplegables'!$H$3:$J$7,2,FALSE) -> #N/A | B36: =VLOOKUP(E35,'[2]Listas Desplegables'!$H$3:$J$7,3,FALSE) -> #N/A | C36: 31 | D36: SUBESTACIÓN LA GABARRA | E36: CENS | F36: 34.5 | G36: 12.5 | H36: Barra sencilla | I36: Convencional | J36: Sí | L36: Norte de Santander | M36: Tibú
A37: =VLOOKUP(E36,'[2]Listas Desplegables'!$H$3:$J$7,2,FALSE) -> #N/A | B37: =VLOOKUP(E36,'[2]Listas Desplegables'!$H$3:$J$7,3,FALSE) -> #N/A | C37: 32 | D37: SUBESTACIÓN SAN PABLO | E37: CENS | F37: 34.5 | G37: 16 | H37: Barra sencilla | I37: Convencional | J37: Sí | L37: Norte de Santander | M37: Teorama
A38: =VLOOKUP(E37,'[2]Listas Desplegables'!$H$3:$J$7,2,FALSE) -> #N/A | B38: =VLOOKUP(E37,'[2]Listas Desplegables'!$H$3:$J$7,3,FALSE) -> #N/A | C38: 33 | D38: SUBESTACIÓN ORU | E38: CENS | F38: 34.5 | G38: 12.5 | H38: Barra sencilla | I38: Convencional | J38: Sí | L38: Norte de Santander | M38: El Tarra
A39: =VLOOKUP(E38,'[2]Listas Desplegables'!$H$3:$J$7,2,FALSE) -> #N/A | B39: =VLOOKUP(E38,'[2]Listas Desplegables'!$H$3:$J$7,3,FALSE) -> #N/A | C39: 34 | D39: SUBESTACIÓN PELAYA | E39: CENS | F39: 34.5 | G39: 12.5 | H39: Barra sencilla | I39: Convencional | J39: Sí | L39: Cesar | M39: Pelaya
