Workbook

Sheet Manual de Uso
B2: MANUAL DE USO PARA EL REPORTE DE INFORMACIÓN REQUERIDA DE LOS TRANSPORTADORES
B7: INTRODUCCIÓN
B8: El presente formato se establece en cumplimiento de lo establecido en el articulo 7 de la Resolución CREG 075 de 2021, para facilitar el reporte uniforme de la información que los transportadores deben entregar para la realización de los estudios de conexión y disponibilidad de espacio físico. El uso del presente formato es transitorio, y se requerirá hasta que entre en funcionamiento el sistema de información de la ventanilla única de la UPME, a través del cual se reportará y actualizará la información requerida para estudios de conexión.
B14: CONTENIDO
B15: El Formato se encuentra dividido en 9 secciones según el tipo de activo a reportar: 1. Información de líneas de transmisión y distribución 2. Información de transformadores tridevanados 3. Información de transformadores bidevanados 4. Información de subestaciones 5. Información de demandas 6. Información de compensaciones 7. Información de compensaciones dinámicas 8. Información de dispositivos DFACTS 9. Información de disponibilidad de espacio físico
B26: MANUAL DE USO
B27: Dentro de cada sección se solicita que el Transportador compile información característica de cada uno de los tipos de activo. A continuación, se presenta la información y una descripción de lo requerido:
B29: Líneas de transmisión y distribución | C29: Nombre | D29: Nombre de línea de transmisión o distribución.
C30: Subestación 1 | D30: Subestación o punto de la red a la cual se conecta uno de los extremos de la línea
C31: Subestación 2 | D31: Subestación o punto de la red a la cual se conecta el otro extremo de la línea
C32: Nivel de tensión [kV] | D32: Nivel de tensión nominal en kilovoltios al cual opera la línea
C33: Longitud [km] | D33: Longitud en kilometros de la línea
C34: Capacidad transporte nominal [A] | D34: Capacidad de transporte de corriente nominal de la línea de transmisión en estado estable en amperios
C35: Capacidad transporte térmico [A] | D35: Capacidad nominal de transporte de corriente del conductor de menor capacidad utilizado en la línea de transmisión en amperios
C36: Capacidad transporte emergencia [A] | D36: Capacidad de corriente máxima que puede soportar la línea ante condiciones de emergencia en amperios
C37: Causa límite de capacidad | D37: Declarar cuál es el elemento que impone el límite operativo, es decir el que restringe la máxima corriente. Entre los elementos están: línea de transmisión (Cable), bajantes de conexión con los pararrayos y los transformadores de potencial, trampas de onda, transformadores de corriente, interruptores, seccionadores
C38: R1 [Ohm/km] | D38: Resistencia de secuencia positiva por unidad de longitud en ohmios por kilometro
C39: X1 [Ohm/km] | D39: Reactancia de secuencia positiva por unidad de longitud en ohmios por kilometro
C40: B1 [uS/km] | D40: Susceptancia de secuancia positiva por unidad de longitud en microsiemens por kilometro
C41: R0 [Ohm/km] | D41: Resistencia de secuencia cero por unidad de longitud en ohmios por kilometro
... C45: Tipo | D45: Tipo de línea. Se debe escoger en la lista desplegable entre: Áerea o Subterranea
C46: En Operación | D46: Se debe escoger en la lista desplegable entre: Sí, cuando el activo se encuentre en operación al momento de realizar la entrega de la información, o No, si el activo tiene una fecha de puesta en operación futura | I46: Activos de uso de STN
C47: FPO | D47: Si el activo no se encuentra en operación, se debe especificar la Fecha de Puesta en Operación planteada en formato dd/mm/aaaa. | I47: Activos de uso de STR y SDL
C48: Conductor | D48: Se debe indicar el calibre y material del conductor predominante en la línea de transmisión o distribución | I48: Activos de conexión del OR al STN
C49: Tiempo medio de reparación por evento [h] | D49: Tiempo de medio en horas que puede durar cada evento de indisponibilidad del activo | I49: Activos de conexión a un STR o a un SDL
C50: Horas anuales de indisponibilidad [h] | D50: Tiempo anual de indisponibilidad del activo en horas
C51: Eventos anuales de indisponibilidad | D51: Número de eventos de indisponibilidad del activo
C52: Operador | D52: Compañía que opera la línea de transmisión ante el CND
C53: Tipo activo Uso/Conexión | D53: Activos de uso de STN: son aquellos activos de transporte de electricidad que operan a tensiones iguales o superiores a 220 kV, son remunerados mediante Cargos por Uso del STN y pueden estar constituidos por una o varias UC. (Resolución CREG 011 de 2009. Activos de uso de STR y SDL: son aquellos activos de transporte de electricidad que operan a tensiones inferiores a 220 kV que son utilizados por más de un usuario y son remunerados mediante cargos por uso de STR o SDL. (Resolución CREG 015 de 2018) Nota: Los activos que sean remunerados mediante cargos por uso del STN o STR y que están constituidos por una o varias unidades constructivas y que pertenezcan a nivel inferior a 220 kV se deberán clasificar como Activos de Uso del STN o STR de acuerdo a como sean remunerados Activos de conexión del OR al STN: son los bienes que se requieren para que un operador de red se conecte físicamente al Sistema de Transmisión Nacional, STN. Activos de conexión a un STR o a un SDL: son los bienes que se requieren para que un OR se conecte físicamente a un Sistema de Transmisión Regional, STR, o a un Sistema de Distribución Local, SDL, de otro OR (Operador de Red). También son activos de conexión los utilizados exclusivamente por un usuario final para conectarse a los niveles de tensión 4, 3, 2 o 1. Un usuario está conectado al nivel de tensión en el que está instalado su equipo de medida individual (Resolución CREG 015 de 2018))
C54: Observaciones transportador | D54: Sección de libre diligenciamiento, donde el transportador debe indicar explicítamente cualquier condición operativa o de planeación que no este incluida en las demás variables. Ejemplo: La línea opera normalmente abierta al lado de la subestación A o se tiene planeado una repotenciación de la línea hasta una capacidad de X Amperios, la cual entrará en operación desde dd/mm/aaaa.
B55: Transformadores tridevanados | C55: Nombre | D55: Nombre del transformador tridevanado. Se sugiere sea nombre de la subestación seguido de los niveles de tensión del transformador
C56: Subestación | D56: Subestación en la cual se encuentra ubicado el transformador
C57: Nivel de tensión HV [kV] | D57: Nivel de tensión nominal de diseño de los bornes de alta tensión del transformador en kilovoltios
C58: Nivel de tensión MV [kV] | D58: Nivel de tensión nominal de diseño de los bornes de media tensión del transformador en kilovoltios
C59: Nivel de tensión LV [kV] | D59: Nivel de tensión nominal de diseño de los bornes de baja tensión del transformador en kilovoltios
C60: Capacidad HV [MVA] | D60: Capacidad nominal en el devanado de alta tensión del transformador en MVA
C61: Capacidad MV [MVA] | D61: Capacidad nominal en el devanado de media tensión del transformador en MVA
C62: Capacidad LV [MVA] | D62: Capacidad nominal en el devanado de baja tensión del transformador en MVA
C63: Grupo de conexión | D63: Convención utilizada para describir las configuraciones de los distintos devanados del transformador y el desfase en los angulos de fase según norma IEC 60076-1 2011. Ejemplo: YNyn0d5
C64: Impedancia HV-MV Secuencia +[%] | D64: Impedancia de corto circuito entre los devanados de alta y media tensión en secuencia positiva como porcentaje de la impedancia de referencia
...

Sheet 1. Líneas
C3: Información General de Líneas
C4: No. | D4: ='Manual de Uso'!C29 -> Nombre | E4: ='Manual de Uso'!C30 -> Subestación 1 | F4: ='Manual de Uso'!C31 -> Subestación 2 | G4: ='Manual de Uso'!C32 -> Nivel de tensión [kV] | H4: ='Manual de Uso'!C33 -> Longitud [km] | I4: ='Manual de Uso'!C34 -> Capacidad transporte nominal [A] | J4: ='Manual de Uso'!C35 -> Capacidad transporte térmico [A] | K4: ='Manual de Uso'!C36 -> Capacidad transporte emergencia [A] | L4: ='Manual de Uso'!C37 -> Causa límite de capacidad | M4: ='Manual de Uso'!C38 -> R1 [Ohm/km] | N4: ='Manual de Uso'!C39 -> X1 [Ohm/km] | O4: ='Manual de Uso'!C40 -> B1 [uS/km] | P4: ='Manual de Uso'!C41 -> R0 [Ohm/km] | Q4: ='Manual de Uso'!C42 -> X0 [Ohm/km] | R4: ='Manual de Uso'!C43 -> B0 [uS/km] | S4: ='Manual de Uso'!C44 -> Sistema | T4: ='Manual de Uso'!C45 -> Tipo | U4: ='Manual de Uso'!C46 -> En Operación | V4: ='Manual de Uso'!C47 -> FPO | W4: ='Manual de Uso'!C48 -> Conductor | X4: ='Manual de Uso'!C49 -> Tiempo medio de reparación por evento [h] | Y4: ='Manual de Uso'!C50 -> Horas anuales de indisponibilidad [h] | Z4: ='Manual de Uso'!C51 -> Eventos anuales de indisponibilidad | AA4: ='Manual de Uso'!C52 -> Operador | AB4: ='Manual de Uso'!C53 -> Tipo activo Uso/Conexión | AC4: ='Manual de Uso'!C54 -> Observaciones transportador
A6: =VLOOKUP(E6,'[1]Listas Desplegables'!$H$3:$J$7,2,FALSE()) -> #N/A | B6: =VLOOKUP(E6,'[1]Listas Desplegables'!$H$3:$J$7,3,FALSE()) -> #N/A | C6: 1 | D6: Guatiguara - Palenque 2 230 | E6: PT Guatiguara - Palenque 2 | F6: PT B1D1 | G6: 230 | H6: 42.13 | I6: 1017 | J6: 1017 | K6: 1100.394 | L6: Capacidad del Conductor | M6: 0.052000949 | N6: 0.48699976 | O6: 3.4469998 | P6: 0.36 | Q6: 1.5079991 | R6: 2.2120009 | S6: STN | T6: Áerea | U6: Sí | W6: Aluminio | X6: 0 | Y6: 0 | Z6: 0 | AA6: ISA | AB6: Activos de uso de STN
A7: =VLOOKUP(E7,'[1]Listas Desplegables'!$H$3:$J$7,2,FALSE()) -> #N/A | B7: =VLOOKUP(E7,'[1]Listas Desplegables'!$H$3:$J$7,3,FALSE()) -> #N/A | C7: 2 | D7: Palenque - Sogamoso 1 230 | E7: PT B1D3 | F7: PT Sogamoso - Guatiguara 1 220 | G7: 230 | H7: 38.45 | I7: 1017 | J7: 1017 | K7: 1100.394 | L7: Capacidad del Conductor | M7: 0.05190117 | N7: 0.48730039 | O7: 3.4470013 | P7: 0.36170091 | Q7: 1.5126996 | R7: 2.2128999 | S7: STN | T7: Áerea | U7: Sí | W7: Aluminio | X7: 0 | Y7: 0 | Z7: 0 | AA7: ISA | AB7: Activos de uso de STN
A8: =VLOOKUP(E8,'[1]Listas Desplegables'!$H$3:$J$7,2,FALSE()) -> #N/A | B8: =VLOOKUP(E8,'[1]Listas Desplegables'!$H$3:$J$7,3,FALSE()) -> #N/A | C8: 3 | D8: Barbosa - Paipa 2 115 | E8: PT Barbosa - Paipa 2 115 | F8: PT Paipa - Barbosa 2 115 | G8: 115 | H8: 81.378 | I8: 770 | J8: 770 | K8: 980.98 | L8: Capacidad del Conductor | M8: 0.11500037 | N8: 0.39399961 | O8: 3.6529996 | P8: 0.54600015 | Q8: 1.2039999 | R8: 2.1759997 | S8: STR | T8: Áerea | U8: Sí | W8: Aluminio | X8: 0 | Y8: 0 | Z8: 0 | AA8: ESSA | AB8: Activos de uso de STR y SDL
A9: =VLOOKUP(E9,'[1]Listas Desplegables'!$H$3:$J$7,2,FALSE()) -> #N/A | B9: =VLOOKUP(E9,'[1]Listas Desplegables'!$H$3:$J$7,3,FALSE()) -> #N/A | C9: 4 | D9: Ocaña - Sn Alberto 1 115 | E9: PT Ocana - Sn Alberto 1 115 | F9: PT Ocaña - Sn Alberto 1 115 | G9: 115 | H9: 59.9 | I9: 325 | J9: 325 | K9: 530.4 | L9: Capacidad del Conductor | M9: 0.12089983 | N9: 0.48810017 | O9: 3.392601 | P9: 0.44720033 | Q9: 1.6316995 | R9: 1.8938998 | S9: STR | T9: Áerea | U9: Sí | W9: Aluminio | X9: 0 | Y9: 0 | Z9: 0 | AA9: ESSA | AB9: Activos de uso de STR y SDL | AC9: Nombre del activo en la informacion georeferenciada: LINEA 323
A10: =VLOOKUP(E10,'[1]Listas Desplegables'!$H$3:$J$7,2,FALSE()) -> #N/A | B10: =VLOOKUP(E10,'[1]Listas Desplegables'!$H$3:$J$7,3,FALSE()) -> #N/A | C10: 5 | D10: Guatiguara - Palenque 1 230 | E10: PT Guatiguara - Palenque 1 | F10: PT B1D2 | G10: 230 | H10: 42.13 | I10: 1017 | J10: 1017 | K10: 1100.394 | L10: Capacidad del Conductor | M10: 0.052000949 | N10: 0.48699976 | O10: 3.4469998 | P10: 0.36 | Q10: 1.5079991 | R10: 2.2120009 | S10: STN | T10: Áerea | U10: Sí | W10: Aluminio | X10: 0 | Y10: 0 | Z10: 0 | AA10: ISA | AB10: Activos de uso de STN
A11: =VLOOKUP(E11,'[1]Listas Desplegables'!$H$3:$J$7,2,FALSE()) -> #N/A | B11: =VLOOKUP(E11,'[1]Listas Desplegables'!$H$3:$J$7,3,FALSE()) -> #N/A | C11: 6 | D11: Palenque - Sogamoso 2 230 | E11: PT B2D3 | F11: PT Sogamoso - Guatiguara 2 220 | G11: 230 | H11: 38.45 | I11: 1017 | J11: 1017 | K11: 1100.394 | L11: Capacidad del Conductor | M11: 0.05190117 | N11: 0.48730039 | O11: 3.4470013 | P11: 0.36170091 | Q11: 1.5126996 | R11: 2.2128999 | S11: STN | T11: Áerea | U11: Sí | W11: Aluminio | X11: 0 | Y11: 0 | Z11: 0 | AA11: ISA | AB11: Activos de uso de STN
A12: =VLOOKUP(E12,'[1]Listas Desplegables'!$H$3:$J$7,2,FALSE()) -> #N/A | B12: =VLOOKUP(E12,'[1]Listas Desplegables'!$H$3:$J$7,3,FALSE()) -> #N/A | C12: 7 | D12: Barranca - Wilches 2 115 | E12: PT 12 | F12: PT Barranca - Wilches 2 115 | G12: 115 | H12: 34.1 | I12: 500 | J12: 500 | K12: 625 | L12: Capacidad del Conductor | M12: 0.14 | N12: 0.486 | O12: 3.4 | P12: 0.32 | Q12: 1.612 | R12: 1.63 | S12: STR | T12: Áerea | U12: Sí | W12: Aluminio | X12: 0.026666667 | Y12: 0.13333333 | Z12: 5 | AA12: ESSA | AB12: Activos de uso de STR y SDL | AC12: Nombre del activo en la informacion georeferenciada: LINEA 322
A13: =VLOOKUP(E13,'[1]Listas Desplegables'!$H$3:$J$7,2,FALSE()) -> #N/A | B13: =VLOOKUP(E13,'[1]Listas Desplegables'!$H$3:$J$7,3,FALSE()) -> #N/A | C13: 8 | D13: Los Palos - Principal 1 115 | E13: PT Florida - Los Palos 1 115 | F13: PT Los Palos 115 | G13: 115 | H13: 3.977 | I13: 592 | J13: 592 | K13: 599.696 | L13: Capacidad del Conductor | M13: 0.13930098 | N13: 0.48139301 | O13: 3.432688 | P13: 0.58918783 | Q13: 1.2721901 | R13: 2.3103093 | S13: STR | T13: Áerea | U13: Sí | W13: Aluminio | X13: 0.35 | Y13: 0.35 | Z13: 1 | AA13: ESSA | AB13: Activos de uso de STR y SDL | AC13: Nombre del activo en la informacion georeferenciada:LINEA 415
A14: =VLOOKUP(E14,'[1]Listas Desplegables'!$H$3:$J$7,2,FALSE()) -> #N/A | B14: =VLOOKUP(E14,'[1]Listas Desplegables'!$H$3:$J$7,3,FALSE()) -> #N/A | C14: 9 | D14: LN 472 BUENOS AIRES - LOAD 472 34.5 | E14: Buenos Aires 34.5 | F14: Nodo 472.1 | G14: 34.5 | H14: 2.7 | I14: 458 | J14: 458 | K14: 458 | L14: Capacidad del Conductor | M14: 0.20959259 | N14: 0.37885185 | O14: 4.4143333 | P14: 0.54448148 | Q14: 1.8570741 | R14: 1.7218889 | S14: SDL | T14: Áerea | U14: Sí | W14: 3F_35_ACSR_266_AIRE | X14: 1.9938426 | Y14: 11.963056 | Z14: 6 | AA14: ESSA | AB14: Activos de uso de STR y SDL | AC14: Nombre del activo en la informacion georeferenciada: LINEA 472
A15: =VLOOKUP(E15,'[1]Listas Desplegables'!$H$3:$J$7,2,FALSE()) -> #N/A | B15: =VLOOKUP(E15,'[1]Listas Desplegables'!$H$3:$J$7,3,FALSE()) -> #N/A | C15: 10 | D15: LN 462 BUENAVISTA - Bypass 460-462 | E15: Buenavista 34.5 | F15: Nodo Bypass 462-460 | G15: 34.5 | H15: 5.23 | I15: 465 | J15: 418.965 | K15: 465 | L15: Protecciones | M15: 0.090879541 | N15: 0.13780115 | O15: 95.32369 | P15: 0.14449331 | Q15: 0.35 | R15: 95.32369 | S15: SDL | T15: Áerea | U15: Sí | W15: 3F_35_CU_500_XLPE | X15: 0 | Y15: 0 | Z15: 0 | AA15: ESSA | AB15: Activos de uso de STR y SDL
A16: =VLOOKUP(E16,'[1]Listas Desplegables'!$H$3:$J$7,2,FALSE()) -> #N/A | B16: =VLOOKUP(E16,'[1]Listas Desplegables'!$H$3:$J$7,3,FALSE()) -> #N/A | C16: 11 | D16: LN 460 LOAD 460 - Bypass 460-462 | E16: Nodo Bypass 460-462 | F16: Nodo 460.2 | G16: 34.5 | H16: 1.38 | I16: 458 | J16: 458 | K16: 458 | L16: Capacidad del Conductor | M16: 0.20963768 | N16: 0.37884058 | O16: 4.4143478 | P16: 0.54449275 | Q16: 1.8571014 | R16: 1.7218841 | S16: SDL | T16: Áerea | U16: Sí | W16: 3F_35_ACSR_266_AIRE | X16: 0 | Y16: 0 | Z16: 0 | AA16: ESSA | AB16: Activos de uso de STR y SDL
A17: =VLOOKUP(E17,'[1]Listas Desplegables'!$H$3:$J$7,2,FALSE()) -> #N/A | B17: =VLOOKUP(E17,'[1]Listas Desplegables'!$H$3:$J$7,3,FALSE()) -> #N/A | C17: 12 | D17: LN 476 MSol - Acuarela | E17: Mesa del Sol 34.5 | F17: Acuarela 34.5 | G17: 34.5 | H17: 10.77 | I17: 458 | J17: 458 | K17: 458 | L17: Capacidad del Conductor | M17: 0.20961003 | N17: 0.37883937 | O17: 4.4143361 | P17: 0.54450325 | Q17: 1.8570845 | R17: 1.7219034 | S17: SDL | T17: Áerea | U17: Sí | W17: 3F_35_ACSR_266_AIRE | X17: 0 | Y17: 0 | Z17: 0 | AA17: ESSA | AB17: Activos de uso de STR y SDL
A18: =VLOOKUP(E18,'[1]Listas Desplegables'!$H$3:$J$7,2,FALSE()) -> #N/A | B18: =VLOOKUP(E18,'[1]Listas Desplegables'!$H$3:$J$7,3,FALSE()) -> #N/A | C18: 13 | D18: LN 417 Palos - Rionegro 34.5 | E18: Palos 34.5 | F18: Nodo 417.1 | G18: 34.5 | H18: 0.09 | I18: 458 | J18: 458 | K18: 458 | L18: Capacidad del Conductor | M18: 0.21 | N18: 0.37888889 | O18: 4.4144444 | P18: 0.54444444 | Q18: 1.8566667 | R18: 1.7222222 | S18: SDL | T18: Áerea | U18: Sí | W18: 3F_35_ACSR_266_AIRE | X18: 0 | Y18: 0 | Z18: 0 | AA18: ESSA | AB18: Activos de uso de STR y SDL
A19: =VLOOKUP(E19,'[1]Listas Desplegables'!$H$3:$J$7,2,FALSE()) -> #N/A | B19: =VLOOKUP(E19,'[1]Listas Desplegables'!$H$3:$J$7,3,FALSE()) -> #N/A | C19: 14 | D19: LN 462 BUENOS AIRES - Bypass 460-462 | E19: Nodo Bypass 462-460 | F19: Buenos Aires 34.5 | G19: 34.5 | H19: 0.0186 | I19: 465 | J19: 465 | K19: 465 | L19: Capacidad del Conductor | M19: 0.091397849 | N19: 0.13978495 | O19: 95.322581 | P19: 0.14516129 | Q19: 0.34946237 | R19: 95.322581 | S19: SDL | T19: Áerea | U19: Sí | W19: 3F_35_CU_500_XLPE | X19: 0 | Y19: 0 | Z19: 0 | AA19: ESSA | AB19: Activos de uso de STR y SDL
A20: =VLOOKUP(E20,'[1]Listas Desplegables'!$H$3:$J$7,2,FALSE()) -> #N/A | B20: =VLOOKUP(E20,'[1]Listas Desplegables'!$H$3:$J$7,3,FALSE()) -> #N/A | C20: 15 | D20: LN 459 MSol - Acuarela | E20: Mesa del Sol 34.5 | F20: Acuarela 34.5 | G20: 34.5 | H20: 10.77 | I20: 458 | J20: 458 | K20: 458 | L20: Capacidad del Conductor | M20: 0.20961003 | N20: 0.37883937 | O20: 4.4143361 | P20: 0.54450325 | Q20: 1.8570845 | R20: 1.7219034 | S20: SDL | T20: Áerea | U20: Sí | W20: 3F_35_ACSR_266_AIRE | X20: 0 | Y20: 0 | Z20: 0 | AA20: ESSA | AB20: Activos de uso de STR y SDL
A21: =VLOOKUP(E21,'[1]Listas Desplegables'!$H$3:$J$7,2,FALSE()) -> #N/A | B21: =VLOOKUP(E21,'[1]Listas Desplegables'!$H$3:$J$7,3,FALSE()) -> #N/A | C21: 16 | D21: LN 406 PALENQUE - SUP 408 34.5 | E21: Palenque 1 34.5 | F21: 406.1 | G21: 34.5 | H21: 0.051 | I21: 465 | J21: 367.815 | K21: 465 | L21: Protecciones | M21: 0.045098039 | N21: 0.068627451 | O21: 190.64706 | P21: 0.07254902 | Q21: 0.1745098 | R21: 190.64706 | S21: SDL | T21: Áerea | U21: Sí | W21: 3F_35_CU_500_XLPE | X21: 8.5647222 | Y21: 8.5647222 | Z21: 1 | AA21: ESSA | AB21: Activos de uso de STR y SDL | AC21: Nombre del activo en la informacion georeferenciada: LINEA 406
A22: =VLOOKUP(E22,'[1]Listas Desplegables'!$H$3:$J$7,2,FALSE()) -> #N/A | B22: =VLOOKUP(E22,'[1]Listas Desplegables'!$H$3:$J$7,3,FALSE()) -> #N/A | C22: 17 | D22: LN 428 PALENQUE - LEBRIJA SUP 409 34.5 | E22: Nodo 428.1 | F22: Palenque 2 34.5 | G22: 34.5 | H22: 0.102 | I22: 465 | J22: 272.025 | K22: 465 | L22: Protecciones | M22: 0.045098039 | N22: 0.068627451 | O22: 190.64706 | P22: 0.07254902 | Q22: 0.1745098 | R22: 190.64706 | S22: SDL | T22: Áerea | U22: Sí | W22: 3F_35_CU_500_XLPE | X22: 0 | Y22: 0 | Z22: 0 | AA22: ESSA | AB22: Activos de uso de STR y SDL
A23: =VLOOKUP(E23,'[1]Listas Desplegables'!$H$3:$J$7,2,FALSE()) -> #N/A | B23: =VLOOKUP(E23,'[1]Listas Desplegables'!$H$3:$J$7,3,FALSE()) -> #N/A | C23: 18 | D23: LN 438 REC CANTALTA - ZAPATOCA 34.5 | E23: Nodo 438 Zapatoca 34.5 | F23: Zapatoca 34.5 | G23: 34.5 | H23: 0.032 | I23: 458 | J23: 458 | K23: 458 | L23: Capacidad del Conductor | M23: 0.209375 | N23: 0.378125 | O23: 4.415625 | P23: 0.54375 | Q23: 1.85625 | R23: 1.721875 | S23: SDL | T23: Áerea | U23: Sí | W23: 3F_35_ACSR_266_AIRE | X23: 0.59015185 | Y23: 44.261389 | Z23: 75 | AA23: ESSA | AB23: Activos de uso de STR y SDL | AC23: Nombre del activo en la informacion georeferenciada: LINEA 438
A24: =VLOOKUP(E24,'[1]Listas Desplegables'!$H$3:$J$7,2,FALSE()) -> #N/A | B24: =VLOOKUP(E24,'[1]Listas Desplegables'!$H$3:$J$7,3,FALSE()) -> #N/A | C24: 19 | D24: LN 449 DER 467 - LA FERIA 34.5 | E24: Nodo 449 Feria | F24: Nodo 449 - SUPLENCIA 451 | G24: 34.5 | H24: 0.22 | I24: 458 | J24: 449.756 | K24: 458 | L24: Protecciones | M24: 0.20954545 | N24: 0.37863636 | O24: 4.4145455 | P24: 0.54454545 | Q24: 1.8572727 | R24: 1.7218182 | S24: SDL | T24: Áerea | U24: Sí | W24: 3F_35_ACSR_266_AIRE | X24: 1.4142105 | Y24: 53.74 | Z24: 38 | AA24: ESSA | AB24: Activos de uso de STR y SDL | AC24: Nombre del activo en la informacion georeferenciada: LINEA 449
A25: =VLOOKUP(E25,'[1]Listas Desplegables'!$H$3:$J$7,2,FALSE()) -> #N/A | B25: =VLOOKUP(E25,'[1]Listas Desplegables'!$H$3:$J$7,3,FALSE()) -> #N/A | C25: 20 | D25: LN 410 PALENQUE - SUP 409 34.5 | E25: Nodo 410 Sup 409 | F25: Palenque 1 34.5 | G25: 34.5 | H25: 0.088 | I25: 465 | J25: 272.025 | K25: 465 | L25: Protecciones | M25: 0.045454545 | N25: 0.069318182 | O25: 190.64773 | P25: 0.072727273 | Q25: 0.175 | R25: 190.64773 | S25: SDL | T25: Áerea | U25: Sí | W25: 3F_35_CU_500_XLPE | X25: 1.4082287 | Y25: 97.167778 | Z25: 69 | AA25: ESSA | AB25: Activos de uso de STR y SDL | AC25: Nombre del activo en la informacion georeferenciada: LINEA 410
A26: =VLOOKUP(E26,'[1]Listas Desplegables'!$H$3:$J$7,2,FALSE()) -> #N/A | B26: =VLOOKUP(E26,'[1]Listas Desplegables'!$H$3:$J$7,3,FALSE()) -> #N/A | C26: 21 | D26: LN 419 ZAPATOCA - NODO 419 34.5 | E26: Nodo 419 Zapatoca 34.5 | F26: Zapatoca 34.5 | G26: 34.5 | H26: 0.032 | I26: 458 | J26: 458 | K26: 458 | L26: Capacidad del Conductor | M26: 0.209375 | N26: 0.378125 | O26: 4.415625 | P26: 0.54375 | Q26: 1.85625 | R26: 1.721875 | S26: SDL | T26: Áerea | U26: Sí | W26: 3F_35_ACSR_266_AIRE | X26: 0.56840038 | Y26: 16.483611 | Z26: 29 | AA26: ESSA | AB26: Activos de uso de STR y SDL | AC26: Nombre del activo en la informacion georeferenciada: LINEA 419
A27: =VLOOKUP(E27,'[1]Listas Desplegables'!$H$3:$J$7,2,FALSE()) -> #N/A | B27: =VLOOKUP(E27,'[1]Listas Desplegables'!$H$3:$J$7,3,FALSE()) -> #N/A | C27: 22 | D27: LN 426 Conuco - Lod 426 34.5_a | E27: Nodo 426.4 | F27: Conuco 34.5 | G27: 34.5 | H27: 3.1947 | I27: 458 | J27: 458 | K27: 458 | L27: Capacidad del Conductor | M27: 0.20959715 | N27: 0.37884621 | O27: 4.4143425 | P27: 0.54449557 | Q27: 1.8570758 | R27: 1.7219144 | S27: SDL | T27: Áerea | U27: Sí | W27: 3F_35_ACSR_266_AIRE | X27: 0 | Y27: 0 | Z27: 0 | AA27: ESSA | AB27: Activos de uso de STR y SDL
A28: =VLOOKUP(E28,'[1]Listas Desplegables'!$H$3:$J$7,2,FALSE()) -> #N/A | B28: =VLOOKUP(E28,'[1]Listas Desplegables'!$H$3:$J$7,3,FALSE()) -> #N/A | C28: 23 | D28: LN L4110 NODO 4110 - SUPLECNIA 439 34.5 | E28: Nodo 4110 Suplencia 439 | F28: Nodo Load 4110 | G28: 34.5 | H28: 0.42 | I28: 458 | J28: 458 | K28: 458 | L28: Capacidad del Conductor | M28: 0.20952381 | N28: 0.37880952 | O28: 4.4142857 | P28: 0.54452381 | Q28: 1.8571429 | R28: 1.7219048 | S28: SDL | T28: Áerea | U28: Sí | W28: 3F_35_ACSR_266_AIRE | X28: 0 | Y28: 0 | Z28: 0 | AA28: ESSA | AB28: Activos de uso de STR y SDL | AC28: 0
A29: =VLOOKUP(E29,'[1]Listas Desplegables'!$H$3:$J$7,2,FALSE()) -> #N/A | B29: =VLOOKUP(E29,'[1]Listas Desplegables'!$H$3:$J$7,3,FALSE()) -> #N/A | C29: 24 | D29: LN 407 Palenque - Lod 407 34.5 | E29: 407.1 | F29: Palenque 2 34.5 | G29: 34.5 | H29: 0.051 | I29: 465 | J29: 252.03 | K29: 465 | L29: Protecciones | M29: 0.045098039 | N29: 0.068627451 | O29: 190.64706 | P29: 0.07254902 | Q29: 0.1745098 | R29: 190.64706 | S29: SDL | T29: Áerea | U29: Sí | W29: 3F_35_CU_500_XLPE | X29: 0 | Y29: 0 | Z29: 0 | AA29: ESSA | AB29: Activos de uso de STR y SDL
A30: =VLOOKUP(E30,'[1]Listas Desplegables'!$H$3:$J$7,2,FALSE()) -> #N/A | B30: =VLOOKUP(E30,'[1]Listas Desplegables'!$H$3:$J$7,3,FALSE()) -> #N/A | C30: 25 | D30: LN 407 hacia Sup 408 | E30: 407.1 | F30: 407.5 | G30: 34.5 | H30: 0.005 | I30: 465 | J30: 465 | K30: 465 | L30: Capacidad del Conductor | M30: 0.1 | N30: 0.14 | O30: 95.32 | P30: 0.14 | Q30: 0.34 | R30: 95.32 | S30: SDL | T30: Áerea | U30: Sí | W30: 3F_35_CU_500_XLPE | X30: 0 | Y30: 0 | Z30: 0 | AA30: ESSA | AB30: Activos de uso de STR y SDL
A31: =VLOOKUP(E31,'[1]Listas Desplegables'!$H$3:$J$7,2,FALSE()) -> #N/A | B31: =VLOOKUP(E31,'[1]Listas Desplegables'!$H$3:$J$7,3,FALSE()) -> #N/A | C31: 26 | D31: LN 432 SAN MARTIN - SAN ROQUE 34.5 | E31: San Martin 34.5 | F31: San Roque 34.5 | G31: 34.5 | H31: 7.98 | I31: 458 | J31: 458 | K31: 458 | L31: Capacidad del Conductor | M31: 0.20961153 | N31: 0.37883459 | O31: 4.4143358 | P31: 0.54449875 | Q31: 1.8570927 | R31: 1.7219048 | S31: SDL | T31: Áerea | U31: Sí | W31: 3F_35_ACSR_266_AIRE | X31: 0 | Y31: 0 | Z31: 0 | AA31: ESSA | AB31: Activos de uso de STR y SDL | AC31: 0
A32: =VLOOKUP(E32,'[1]Listas Desplegables'!$H$3:$J$7,2,FALSE()) -> #N/A | B32: =VLOOKUP(E32,'[1]Listas Desplegables'!$H$3:$J$7,3,FALSE()) -> #N/A | C32: 27 | D32: LN 405 PALENQUE - R.MINAS 34.5 | E32: Palenque 1 34.5 | F32: Realminas 34.5 | G32: 34.5 | H32: 4.85 | I32: 458 | J32: 458 | K32: 458 | L32: Capacidad del Conductor | M32: 0.20960825 | N32: 0.37884536 | O32: 4.4143299 | P32: 0.54449485 | Q32: 1.8570928 | R32: 1.7218969 | S32: SDL | T32: Áerea | U32: Sí | W32: 3F_35_ACSR_266_AIRE | X32: 0 | Y32: 0 | Z32: 0 | AA32: ESSA | AB32: Activos de uso de STR y SDL | AC32: Nombre del activo en la informacion georeferenciada: LINEA 405
A33: =VLOOKUP(E33,'[1]Listas Desplegables'!$H$3:$J$7,2,FALSE()) -> #N/A | B33: =VLOOKUP(E33,'[1]Listas Desplegables'!$H$3:$J$7,3,FALSE()) -> #N/A | C33: 28 | D33: LN 431 SAN ALBERTO - SAN MARTIN 34.5 | E33: Nodo 431 Load | F33: Nodo 431 SUP 430 | G33: 34.5 | H33: 15.525 | I33: 458 | J33: 399.834 | K33: 458 | L33: Protecciones | M33: 0.20961031 | N33: 0.37884058 | O33: 4.4143317 | P33: 0.54450242 | Q33: 1.8570886 | R33: 1.7219002 | S33: SDL | T33: Áerea | U33: Sí | W33: 3F_35_ACSR_266_AIRE | X33: 1.120678 | Y33: 66.12 | Z33: 59 | AA33: ESSA | AB33: Activos de uso de STR y SDL | AC33: Nombre del activo en la informacion georeferenciada: LINEA 431
A34: =VLOOKUP(E34,'[1]Listas Desplegables'!$H$3:$J$7,2,FALSE()) -> #N/A | B34: =VLOOKUP(E34,'[1]Listas Desplegables'!$H$3:$J$7,3,FALSE()) -> #N/A | C34: 29 | D34: LN 439 NODO 439 - SUPLENCIA 4110 34.5 | E34: Nodo 439 Suplencia 4110 | F34: Nodo 439 | G34: 34.5 | H34: 1 | I34: 458 | J34: 458 | K34: 458 | L34: Capacidad del Conductor | M34: 0.2096 | N34: 0.3788 | O34: 4.4143 | P34: 0.5445 | Q34: 1.8571 | R34: 1.7219 | S34: SDL | T34: Áerea | U34: Sí | W34: 3F_35_ACSR_266_AIRE | X34: 0.35545455 | Y34: 15.64 | Z34: 44 | AA34: ESSA | AB34: Activos de uso de STR y SDL | AC34: Nombre del activo en la informacion georeferenciada: LINEA 439
A35: =VLOOKUP(E35,'[1]Listas Desplegables'!$H$3:$J$7,2,FALSE()) -> #N/A | B35: =VLOOKUP(E35,'[1]Listas Desplegables'!$H$3:$J$7,3,FALSE()) -> #N/A | C35: 30 | D35: LN 409 PALENQUE - SUP 428 34.5 | E35: Nodo 409.6 - 428 | F35: Nodo 409 Sup 410 | G35: 34.5 | H35: 1.84 | I35: 458 | J35: 458 | K35: 458 | L35: Capacidad del Conductor | M35: 0.20961957 | N35: 0.3788587 | O35: 4.4143478 | P35: 0.54451087 | Q35: 1.8570652 | R35: 1.7219022 | S35: SDL | T35: Áerea | U35: Sí | W35: 3F_35_ACSR_266_AIRE | X35: 0.90707627 | Y35: 107.035 | Z35: 118 | AA35: ESSA | AB35: Activos de uso de STR y SDL | AC35: Nombre del activo en la informacion georeferenciada: LINEA 409
A36: =VLOOKUP(E36,'[1]Listas Desplegables'!$H$3:$J$7,2,FALSE()) -> #N/A | B36: =VLOOKUP(E36,'[1]Listas Desplegables'!$H$3:$J$7,3,FALSE()) -> #N/A | C36: 31 | D36: LN 432 LOS ANGELES - AGROINCE 34.5 | E36: Los Angeles 34.5 | F36: AGROINCE 34.5 | G36: 34.5 | H36: 6.98 | I36: 355 | J36: 355 | K36: 355 | L36: Capacidad del Conductor | M36: 0.26161891 | N36: 0.40604585 | O36: 4.2960888 | P36: 0.59651862 | Q36: 1.884298 | R36: 1.703639 | S36: SDL | T36: Áerea | U36: Sí | W36: 3F_35_ACSR_4/0_AIRE | X36: 0 | Y36: 0 | Z36: 0 | AA36: ESSA | AB36: Activos de uso de STR y SDL | AC36: 0
A37: =VLOOKUP(E37,'[1]Listas Desplegables'!$H$3:$J$7,2,FALSE()) -> #N/A | B37: =VLOOKUP(E37,'[1]Listas Desplegables'!$H$3:$J$7,3,FALSE()) -> #N/A | C37: 32 | D37: LN 408 hacia SUP 406 | E37: Nodo Load 408.2 | F37: 408.4 | G37: 34.5 | H37: 0.005 | I37: 458 | J37: 458 | K37: 458 | L37: Capacidad del Conductor | M37: 0.2 | N37: 0.38 | O37: 4.42 | P37: 0.54 | Q37: 1.86 | R37: 1.72 | S37: SDL | T37: Áerea | U37: Sí | W37: 3F_35_ACSR_266_AIRE | X37: 0 | Y37: 0 | Z37: 0 | AA37: ESSA | AB37: Activos de uso de STR y SDL
A38: =VLOOKUP(E38,'[1]Listas Desplegables'!$H$3:$J$7,2,FALSE()) -> #N/A | B38: =VLOOKUP(E38,'[1]Listas Desplegables'!$H$3:$J$7,3,FALSE()) -> #N/A | C38: 33 | D38: LN 416 Palos - Sup 417 | E38: Palos 34.5 | F38: Nodo 416.1 | G38: 34.5 | H38: 0.07 | I38: 458 | J38: 399.834 | K38: 458 | L38: Protecciones | M38: 0.21 | N38: 0.37857143 | O38: 4.4142857 | P38: 0.54428571 | Q38: 1.8571429 | R38: 1.7214286 | S38: SDL | T38: Áerea | U38: Sí | W38: 3F_35_ACSR_266_AIRE | X38: 0 | Y38: 0 | Z38: 0 | AA38: ESSA | AB38: Activos de uso de STR y SDL
A39: =VLOOKUP(E39,'[1]Listas Desplegables'!$H$3:$J$7,2,FALSE()) -> #N/A | B39: =VLOOKUP(E39,'[1]Listas Desplegables'!$H$3:$J$7,3,FALSE()) -> #N/A | C39: 34 | D39: LN 408 hacia Sup 407 | E39: 408.3 | F39: 408.4 | G39: 34.5 | H39: 0.005 | I39: 640 | J39: 640 | K39: 640 | L39: Capacidad del Conductor | M39: 0.04 | N39: 0.12 | O39: 0 | P39: 0.08 | Q39: 0.32 | R39: 0 | S39: SDL | T39: Áerea | U39: Sí | W39: 3F_35_CU_1000_XLPE | X39: 0 | Y39: 0 | Z39: 0 | AA39: ESSA | AB39: Activos de uso de STR y SDL
A40: =VLOOKUP(E40,'[1]Listas Desplegables'!$H$3:$J$7,2,FALSE()) -> #N/A | B40: =VLOOKUP(E40,'[1]Listas Desplegables'!$H$3:$J$7,3,FALSE()) -> #N/A | C40: 35 | D40: Línea 430 Cachira - Limites 34.5 kV | E40: Nodo 430.4 Cachira | F40: Nodo 430.5 Limites | G40: 34.5 | H40: 3.6 | I40: 458 | J40: 192.36 | K40: 458 | L40: Protecciones | M40: 0.20961111 | N40: 0.37883333 | O40: 4.4143333 | P40: 0.5445 | Q40: 1.8570833 | R40: 1.7219167 | S40: SDL | T40: Áerea | U40: Sí | W40: 3F_35_ACSR_266_AIRE | X40: 0 | Y40: 0 | Z40: 0 | AA40: ESSA | AB40: Activos de uso de STR y SDL
A41: =VLOOKUP(E41,'[1]Listas Desplegables'!$H$3:$J$7,2,FALSE()) -> #N/A | B41: =VLOOKUP(E41,'[1]Listas Desplegables'!$H$3:$J$7,3,FALSE()) -> #N/A | C41: 36 | D41: Linea 447 Condor | E41: Condor 3 34.5 | F41: Condor 34.5 | G41: 34.5 | H41: 0.2 | I41: 767 | J41: 767 | K41: 767 | L41: Capacidad del Conductor | M41: 0.114 | N41: 0.429 | O41: 6.563 | P41: 0.531 | Q41: 1.492 | R41: 3.496 | S41: SDL | T41: Áerea | U41: Sí | W41: Aluminio | X41: 0 | Y41: 0 | Z41: 0 | AA41: ESSA | AB41: Activos de uso de STR y SDL
A42: =VLOOKUP(E42,'[1]Listas Desplegables'!$H$3:$J$7,2,FALSE()) -> #N/A | B42: =VLOOKUP(E42,'[1]Listas Desplegables'!$H$3:$J$7,3,FALSE()) -> #N/A | C42: 37 | D42: LN 443 SUPLENCIA 421 - S CRISTOBAL 34.5 | E42: Nodo 443.1 | F42: San Cristobal 34.5 | G42: 34.5 | H42: 1.39 | I42: 458 | J42: 458 | K42: 458 | L42: Capacidad del Conductor | M42: 0.20964029 | N42: 0.37884892 | O42: 4.4143165 | P42: 0.54453237 | Q42: 1.8571223 | R42: 1.7218705 | S42: SDL | T42: Áerea | U42: Sí | W42: 3F_35_ACSR_266_AIRE | X42: 1.2410703 | Y42: 84.392778 | Z42: 68 | AA42: ESSA | AB42: Activos de uso de STR y SDL | AC42: Nombre del activo en la informacion georeferenciada: LINEA 443
A43: =VLOOKUP(E43,'[1]Listas Desplegables'!$H$3:$J$7,2,FALSE()) -> #N/A | B43: =VLOOKUP(E43,'[1]Listas Desplegables'!$H$3:$J$7,3,FALSE()) -> #N/A | C43: 38 | D43: LN 449 Nodo La Feria - La Feria 34.5 | E43: Feria 34.5 | F43: Nodo 449 Feria | G43: 34.5 | H43: 0.124 | I43: 355 | J43: 355 | K43: 355 | L43: Capacidad del Conductor | M43: 0.26129032 | N43: 0.40564516 | O43: 4.2959677 | P43: 0.59677419 | Q43: 1.8846774 | R43: 1.7040323 | S43: SDL | T43: Áerea | U43: Sí | W43: 3F_35_ACSR_4/0_AIRE | X43: 1.4142105 | Y43: 53.74 | Z43: 38 | AA43: ESSA | AB43: Activos de uso de STR y SDL | AC43: Nombre del activo en la informacion georeferenciada: LINEA 449
...

Sheet 2. Tr3
C3: Información General de Transformadores Tridevanados
C4: No. | D4: ='Manual de Uso'!C55 -> Nombre | E4: ='Manual de Uso'!C56 -> Subestación | F4: ='Manual de Uso'!C57 -> Nivel de tensión HV [kV] | G4: ='Manual de Uso'!C58 -> Nivel de tensión MV [kV] | H4: ='Manual de Uso'!C59 -> Nivel de tensión LV [kV] | I4: ='Manual de Uso'!C60 -> Capacidad HV [MVA] | J4: ='Manual de Uso'!C61 -> Capacidad MV [MVA] | K4: ='Manual de Uso'!C62 -> Capacidad LV [MVA] | L4: ='Manual de Uso'!C63 -> Grupo de conexión | M4: ='Manual de Uso'!C64 -> Impedancia HV-MV Secuencia +[%] | N4: ='Manual de Uso'!C65 -> Impedancia HV-LV Secuencia +[%] | O4: ='Manual de Uso'!C66 -> Impedancia MV-LV Secuencia +[%] | P4: ='Manual de Uso'!C67 -> Impedancia HV-MV Secuencia 0[%] | Q4: ='Manual de Uso'!C68 -> Impedancia HV-LV Secuencia 0[%] | R4: ='Manual de Uso'!C69 -> Impedancia MV-LV Secuencia 0[%] | S4: ='Manual de Uso'!C70 -> Posición Neutral Tap | T4: ='Manual de Uso'!C71 -> Posición Máxima Tap | U4: ='Manual de Uso'!C72 -> Posición Mínima Tap | V4: ='Manual de Uso'!C73 -> Delta Tap [%] | W4: ='Manual de Uso'!C74 -> Sobrecarga en emergencia | Y4: ='Manual de Uso'!C75 -> En Operación | Z4: ='Manual de Uso'!C76 -> FPO | AA4: ='Manual de Uso'!C77 -> Sistema | AB4: ='Manual de Uso'!C78 -> Pérdidas Cu HV-MV [kW] | AC4: ='Manual de Uso'!C79 -> Pérdidas Cu HV-LV [kW] | AD4: ='Manual de Uso'!C80 -> Pérdidas Cu MV-LV [kW] | AE4: ='Manual de Uso'!C81 -> Tiempo medio de reparación por evento [h] | AF4: ='Manual de Uso'!C82 -> Horas anuales de indisponibilidad [h] | AG4: ='Manual de Uso'!C83 -> Eventos anuales de indisponibilidad | AH4: ='Manual de Uso'!C84 -> Operador | AI4: ='Manual de Uso'!C85 -> Tipo activo Uso/Conexión | AJ4: ='Manual de Uso'!C86 -> Observaciones transportador
W5: Magnitud [%] | X5: Tiempo [minutos]
A6: =VLOOKUP(E6,'[1]Listas Desplegables'!$H$3:$J$7,2,FALSE()) -> #N/A | B6: =VLOOKUP(E6,'[1]Listas Desplegables'!$H$3:$J$7,3,FALSE()) -> #N/A | C6: 1 | D6: Piedecuesta 230/115 | E6: Guatiguara 220 | F6: 230 | G6: 115 | H6: 13.8 | I6: 150 | J6: 150 | K6: 25 | L6: YNa0d11 | M6: 16.56 | N6: 6.49 | O6: 3.16 | P6: 6.49 | Q6: 16.56 | R6: 3.16 | S6: 11 | T6: 27 | U6: 1 | V6: 0.96 | W6: 130 | X6: 30 | Y6: Sí | AA6: STN | AB6: 359.622 | AC6: 34.905 | AD6: 42.096 | AE6: 0 | AF6: 0 | AG6: 0 | AH6: ESSA | AI6: Activos de uso de STN
A7: =VLOOKUP(E7,'[1]Listas Desplegables'!$H$3:$J$7,2,FALSE()) -> #N/A | B7: =VLOOKUP(E7,'[1]Listas Desplegables'!$H$3:$J$7,3,FALSE()) -> #N/A | C7: 2 | D7: Palos 230/115 | E7: Palos 220 | F7: 230 | G7: 115 | H7: 13.2 | I7: 150 | J7: 150 | K7: 25 | L7: YNa0d11 | M7: 16.33 | N7: 6.66 | O7: 3.08 | P7: 6.66 | Q7: 16.33 | R7: 3.08 | S7: 11 | T7: 27 | U7: 1 | V7: 0.96 | W7: 130 | X7: 0 | Y7: Sí | AA7: STN | AB7: 352.5 | AC7: 34.905 | AD7: 36.192 | AE7: 0.1 | AF7: 0.1 | AG7: 1 | AH7: ESSA | AI7: Activos de uso de STN
A8: =VLOOKUP(E8,'[1]Listas Desplegables'!$H$3:$J$7,2,FALSE()) -> #N/A | B8: =VLOOKUP(E8,'[1]Listas Desplegables'!$H$3:$J$7,3,FALSE()) -> #N/A | C8: 3 | D8: Bucaramanga 5 230/115 | E8: Bmanga 220 | F8: 230 | G8: 115 | H8: 13.8 | I8: 150 | J8: 150 | K8: 25 | L8: YNa0d11 | M8: 16.73 | N8: 6.52001 | O8: 3.34 | P8: 6.52 | Q8: 16.73 | R8: 3.34 | S8: 11 | T8: 27 | U8: 1 | V8: 0.96 | W8: 130 | X8: 30 | Y8: Sí | AA8: STN | AB8: 352.5 | AC8: 34.905 | AD8: 36.192 | AE8: 24.266667 | AF8: 48.533333 | AG8: 2 | AH8: ESSA | AI8: Activos de uso de STN
A9: =VLOOKUP(E9,'[1]Listas Desplegables'!$H$3:$J$7,2,FALSE()) -> #N/A | B9: =VLOOKUP(E9,'[1]Listas Desplegables'!$H$3:$J$7,3,FALSE()) -> #N/A | C9: 4 | D9: Bucaramanga 4 230/115 | E9: Bmanga 220 | F9: 230 | G9: 115 | H9: 13.8 | I9: 150 | J9: 150 | K9: 25 | L9: YNa0d11 | M9: 16.37 | N9: 6.59999 | O9: 3.46999 | P9: 6.5999 | Q9: 16.37 | R9: 3.4699 | S9: 11 | T9: 27 | U9: 1 | V9: 0.96 | W9: 130 | X9: 30 | Y9: Sí | AA9: STN | AB9: 352.5 | AC9: 34.905 | AD9: 36.192 | AE9: 0.041666667 | AF9: 0.083333333 | AG9: 2 | AH9: ESSA | AI9: Activos de uso de STN
A10: =VLOOKUP(E10,'[1]Listas Desplegables'!$H$3:$J$7,2,FALSE()) -> #N/A | B10: =VLOOKUP(E10,'[1]Listas Desplegables'!$H$3:$J$7,3,FALSE()) -> #N/A | C10: 5 | D10: Palenque 1 230/115 | E10: Palenque 220 | F10: 230 | G10: 115 | H10: 13.8 | I10: 150 | J10: 150 | K10: 25 | L10: YNyn0d11 | M10: 16.35 | N10: 6.65 | O10: 3.5 | P10: 6.65 | Q10: 16.35 | R10: 3.5 | S10: 11 | T10: 27 | U10: 1 | V10: 0.965 | W10: 130 | X10: 30 | Y10: Sí | AA10: STN | AB10: 329.82 | AC10: 34.813926 | AD10: 35.86435 | AE10: 0.55 | AF10: 1.1 | AG10: 2 | AH10: ESSA | AI10: Activos de uso de STN
A11: =VLOOKUP(E11,'[1]Listas Desplegables'!$H$3:$J$7,2,FALSE()) -> #N/A | B11: =VLOOKUP(E11,'[1]Listas Desplegables'!$H$3:$J$7,3,FALSE()) -> #N/A | C11: 6 | D11: Palenque 2 230/115 | E11: Palenque 220 | F11: 230 | G11: 115 | H11: 13.8 | I11: 150 | J11: 150 | K11: 25 | L11: YNyn0d11 | M11: 16.38 | N11: 6.63 | O11: 3.5 | P11: 6.63 | Q11: 16.38 | R11: 3.5 | S11: 11 | T11: 27 | U11: 1 | V11: 0.965 | W11: 130 | X11: 30 | Y11: Sí | AA11: STN | AB11: 329.82 | AC11: 34.7839 | AD11: 35.8643 | AE11: 0 | AF11: 0 | AG11: 0 | AH11: ESSA | AI11: Activos de uso de STN
A12: =VLOOKUP(E12,'[1]Listas Desplegables'!$H$3:$J$7,2,FALSE()) -> #N/A | B12: =VLOOKUP(E12,'[1]Listas Desplegables'!$H$3:$J$7,3,FALSE()) -> #N/A | C12: 7 | D12: Barranca 4 220/115 | E12: Barranca 220 | F12: 220 | G12: 115 | H12: 13.8 | I12: 90 | J12: 90 | K12: 30 | L12: YNyn0d1 | M12: 9.88 | N12: 9.37 | O12: 6.3 | P12: 9.37 | Q12: 9.88 | R12: 6.3 | S12: 9 | T12: 21 | U12: 1 | V12: 1.25 | W12: 130 | X12: 30 | Y12: Sí | AA12: STN | AB12: 86 | AC12: 209.47 | AD12: 100.44 | AE12: 0 | AF12: 0 | AG12: 0 | AH12: ESSA | AI12: Activos de uso de STN
A13: =VLOOKUP(E13,'[1]Listas Desplegables'!$H$3:$J$7,2,FALSE()) -> #N/A | B13: =VLOOKUP(E13,'[1]Listas Desplegables'!$H$3:$J$7,3,FALSE()) -> #N/A | C13: 8 | D13: Barranca 5 115/34.5/13.8 | E13: Barranca 115 | F13: 115 | G13: 34.5 | H13: 13.8 | I13: 40 | J13: 40 | K13: 4.7 | L13: YNyn0d11 | M13: 12.52 | N13: 2.48 | O13: 4.32 | P13: 2.48 | Q13: 12.52 | R13: 4.32 | S13: 0 | T13: 8 | U13: -8 | V13: 1.25 | W13: 130 | X13: 30 | Y13: Sí | AA13: STR | AB13: 97.3 | AC13: 16.89 | AD13: 37.34 | AE13: 0 | AF13: 0 | AG13: 0 | AH13: ESSA | AI13: Activos de uso de STR y SDL
A14: =VLOOKUP(E14,'[1]Listas Desplegables'!$H$3:$J$7,2,FALSE()) -> #N/A | B14: =VLOOKUP(E14,'[1]Listas Desplegables'!$H$3:$J$7,3,FALSE()) -> #N/A | C14: 9 | D14: Bmanga 2 115/34.5/13.8 | E14: Bmanga 115 | F14: 115 | G14: 34.5 | H14: 13.8 | I14: 40 | J14: 40 | K14: 4.7 | L14: YNyn0d11 | M14: 12.39 | N14: 2.47 | O14: 4.31 | P14: 2.47 | Q14: 12.39 | R14: 4.31 | S14: 9 | T14: 17 | U14: 1 | V14: 1.25 | W14: 130 | X14: 30 | Y14: Sí | AA14: STR | AB14: 97.34 | AC14: - | AD14: - | AE14: 0 | AF14: 0 | AG14: 0 | AH14: ESSA | AI14: Activos de uso de STR y SDL
A15: =VLOOKUP(E15,'[1]Listas Desplegables'!$H$3:$J$7,2,FALSE()) -> #N/A | B15: =VLOOKUP(E15,'[1]Listas Desplegables'!$H$3:$J$7,3,FALSE()) -> #N/A | C15: 10 | D15: Barranca 7 115/34.5/13.8 | E15: Barranca 115 | F15: 115 | G15: 34.5 | H15: 13.8 | I15: 40 | J15: 40 | K15: 13.3 | L15: YNyn0d1 | M15: 8.37 | N15: 6.1799 | O15: 2.91 | P15: 6.1799 | Q15: 8.37 | R15: 2.91 | S15: 9 | T15: 17 | U15: 1 | V15: 1.25 | W15: 127 | X15: 30 | Y15: Sí | AA15: STR | AB15: 97.3 | AC15: - | AD15: - | AE15: 0 | AF15: 0 | AG15: 0 | AH15: ESSA | AI15: Activos de uso de STR y SDL
A16: =VLOOKUP(E16,'[1]Listas Desplegables'!$H$3:$J$7,2,FALSE()) -> #N/A | B16: =VLOOKUP(E16,'[1]Listas Desplegables'!$H$3:$J$7,3,FALSE()) -> #N/A | C16: 11 | D16: Cimitarra 1 115/34.5 | E16: Cimitarra 115 | F16: 115 | G16: 34.5 | H16: 13.8 | I16: 20 | J16: 20 | K16: 6.7 | L16: YNyn0d11 | M16: 13.09 | N16: 2.47998 | O16: 4.32001 | P16: 2.48 | Q16: 13.09 | R16: 4.32 | S16: 9 | T16: 17 | U16: 1 | V16: 1.25 | W16: 130 | X16: 30 | Y16: Sí | AA16: STR | AB16: 78.06 | AC16: 16.72 | AD16: - | AE16: 0 | AF16: 0 | AG16: 0 | AH16: ESSA | AI16: Activos de uso de STR y SDL
A17: =VLOOKUP(E17,'[1]Listas Desplegables'!$H$3:$J$7,2,FALSE()) -> #N/A | B17: =VLOOKUP(E17,'[1]Listas Desplegables'!$H$3:$J$7,3,FALSE()) -> #N/A | C17: 12 | D17: Florida 3 115/34.5/13.8 | E17: Florida ESSA 115 | F17: 115 | G17: 34.5 | H17: 13.8 | I17: 40 | J17: 40 | K17: 13.3 | L17: YNyn0d1 | M17: 8.36 | N17: 6.17999 | O17: 2.91001 | P17: 6.18 | Q17: 8.36 | R17: 2.91 | S17: 9 | T17: 17 | U17: 1 | V17: 1.25 | W17: 130 | X17: 30 | Y17: Sí | AA17: STR | AB17: 78.06 | AC17: 16.72 | AD17: - | AE17: 0 | AF17: 0 | AG17: 0 | AH17: ESSA | AI17: Activos de uso de STR y SDL
A18: =VLOOKUP(E18,'[1]Listas Desplegables'!$H$3:$J$7,2,FALSE()) -> #N/A | B18: =VLOOKUP(E18,'[1]Listas Desplegables'!$H$3:$J$7,3,FALSE()) -> #N/A | C18: 13 | D18: T2 Buenavista 115/34.5/13.8 | E18: Buenavista 115 | F18: 115 | G18: 34.5 | H18: 13.8 | I18: 40 | J18: 40 | K18: 13.3 | L18: YNyn0d11 | M18: 8.43 | N18: 2.92999 | O18: 6.4799 | P18: 2.92999 | Q18: 8.43 | R18: 6.47999 | S18: 9 | T18: 17 | U18: 1 | V18: 1.25 | W18: 125 | X18: 30 | Y18: Sí | AA18: STR | AB18: 97.34 | AC18: - | AD18: - | AE18: 0 | AF18: 0 | AG18: 0 | AH18: ESSA | AI18: Activos de uso de STR y SDL
A19: =VLOOKUP(E19,'[1]Listas Desplegables'!$H$3:$J$7,2,FALSE()) -> #N/A | B19: =VLOOKUP(E19,'[1]Listas Desplegables'!$H$3:$J$7,3,FALSE()) -> #N/A | C19: 14 | D19: T4 Palenque 115/34.5/13.8 | E19: Palenque 115 | F19: 115 | G19: 34.5 | H19: 13.8 | I19: 40 | J19: 40 | K19: 13.3 | L19: YNyn0d11 | M19: 11.49 | N19: 6.95001 | O19: 12.31001 | P19: 6.95 | Q19: 11.49 | R19: 12.31 | S19: 9 | T19: 17 | U19: 1 | V19: 1.25 | W19: 120 | X19: 30 | Y19: Sí | AA19: STR | AB19: 97.3 | AC19: - | AD19: - | AE19: 0 | AF19: 0 | AG19: 0 | AH19: ESSA | AI19: Activos de uso de STR y SDL
A20: =VLOOKUP(E20,'[1]Listas Desplegables'!$H$3:$J$7,2,FALSE()) -> #N/A | B20: =VLOOKUP(E20,'[1]Listas Desplegables'!$H$3:$J$7,3,FALSE()) -> #N/A | C20: 15 | D20: Barbosa 1 115/34.5 | E20: Barbosa 115 | F20: 115 | G20: 34.5 | H20: 13.8 | I20: 40 | J20: 40 | K20: 13.3 | L20: YNyn0d11 | M20: 8.741 | N20: 6.18 | O20: 2.91001 | P20: 6.18 | Q20: 8.741 | R20: 2.91 | S20: 9 | T20: 17 | U20: 1 | V20: 1.25 | W20: 130 | X20: 30 | Y20: Sí | AA20: STR | AB20: 78.06 | AC20: 16.72 | AD20: - | AE20: 0 | AF20: 0 | AG20: 0 | AH20: ESSA | AI20: Activos de uso de STR y SDL
A21: =VLOOKUP(E21,'[1]Listas Desplegables'!$H$3:$J$7,2,FALSE()) -> #N/A | B21: =VLOOKUP(E21,'[1]Listas Desplegables'!$H$3:$J$7,3,FALSE()) -> #N/A | C21: 16 | D21: Barranca 6 115/34.5/13.8 | E21: Barranca 115 | F21: 115 | G21: 34.5 | H21: 13.8 | I21: 40 | J21: 40 | K21: 13.3 | L21: YNyn0d11 | M21: 8.6 | N21: 2.93 | O21: 6.60002 | P21: 2.93 | Q21: 8.6 | R21: 6.6 | S21: 9 | T21: 17 | U21: 1 | V21: 1.25 | W21: 127 | X21: 30 | Y21: Sí | AA21: STR | AB21: 98.74 | AC21: - | AD21: - | AE21: 0 | AF21: 0 | AG21: 0 | AH21: ESSA | AI21: Activos de uso de STR y SDL
A22: =VLOOKUP(E22,'[1]Listas Desplegables'!$H$3:$J$7,2,FALSE()) -> #N/A | B22: =VLOOKUP(E22,'[1]Listas Desplegables'!$H$3:$J$7,3,FALSE()) -> #N/A | C22: 17 | D22: T1 Oiba 115/34.5 kV 40 MVA | E22: Oiba 115 | F22: 115 | G22: 34.5 | H22: 13.8 | I22: 40 | J22: 40 | K22: 13.8 | L22: YNyn0d11 | M22: 8.48 | N22: 6.484 | O22: 2.926 | P22: 6.484 | Q22: 8.84 | R22: 2.926 | S22: 9 | T22: 17 | U22: 1 | V22: 1.25 | W22: 130 | X22: 30 | Y22: Sí | AA22: STR | AB22: 96.882 | AC22: - | AD22: - | AE22: 0 | AF22: 0 | AG22: 0 | AH22: ESSA | AI22: Activos de uso de STR y SDL
A23: =VLOOKUP(E23,'[1]Listas Desplegables'!$H$3:$J$7,2,FALSE()) -> #N/A | B23: =VLOOKUP(E23,'[1]Listas Desplegables'!$H$3:$J$7,3,FALSE()) -> #N/A | C23: 18 | D23: Florida 1 115/34.5/13.8 | E23: Florida ESSA 115 | F23: 115 | G23: 34.5 | H23: 13.8 | I23: 40 | J23: 40 | K23: 13.3 | L23: YNyn0d1 | M23: 8.37 | N23: 6.18 | O23: 2.91 | P23: 6.18 | Q23: 8.37 | R23: 2.91 | S23: 9 | T23: 1 | U23: 17 | V23: 1.25 | W23: 130 | X23: 30 | Y23: Sí | AA23: STR | AB23: 97.3 | AC23: 16.89 | AD23: 37.34 | AE23: 0 | AF23: 0 | AG23: 0 | AH23: ESSA | AI23: Activos de uso de STR y SDL
A24: =VLOOKUP(E24,'[1]Listas Desplegables'!$H$3:$J$7,2,FALSE()) -> #N/A | B24: =VLOOKUP(E24,'[1]Listas Desplegables'!$H$3:$J$7,3,FALSE()) -> #N/A | C24: 19 | D24: T5 Palenque 115/34.5/13.8 | E24: Palenque 115 | F24: 115 | G24: 34.5 | H24: 13.8 | I24: 40 | J24: 40 | K24: 4.7 | L24: YNyn0d11 | M24: 12.77 | N24: 2.45 | O24: 4.34 | P24: 2.45 | Q24: 12.77 | R24: 4.34 | S24: 0 | T24: 8 | U24: -8 | V24: 1.25 | W24: 120 | X24: 30 | Y24: Sí | AA24: STR | AB24: 97.3 | AC24: 16.89 | AD24: 37.34 | AE24: 0 | AF24: 0 | AG24: 0 | AH24: ESSA | AI24: Activos de uso de STR y SDL
A25: =VLOOKUP(E25,'[1]Listas Desplegables'!$H$3:$J$7,2,FALSE()) -> #N/A | B25: =VLOOKUP(E25,'[1]Listas Desplegables'!$H$3:$J$7,3,FALSE()) -> #N/A | C25: 20 | D25: SanGil 3 115/34.5/13.8 | E25: San Gil 115 | F25: 115 | G25: 34.5 | H25: 13.8 | I25: 40 | J25: 40 | K25: 13.3 | L25: YNyn0d11 | M25: 8.46 | N25: 2.926 | O25: 6.484 | P25: 2.926 | Q25: 8.84 | R25: 6.484 | S25: 9 | T25: 17 | U25: 1 | V25: 1.25 | W25: 130 | X25: 30 | Y25: Sí | AA25: STR | AB25: 97.341 | AC25: 16.89 | AD25: 37.34 | AE25: 0 | AF25: 0 | AG25: 0 | AH25: ESSA | AI25: Activos de uso de STR y SDL
A26: =VLOOKUP(E26,'[1]Listas Desplegables'!$H$3:$J$7,2,FALSE()) -> #N/A | B26: =VLOOKUP(E26,'[1]Listas Desplegables'!$H$3:$J$7,3,FALSE()) -> #N/A | C26: 21 | D26: Realminas 5 115/34.5/13.8 | E26: Realminas 115 | F26: 115 | G26: 34.5 | H26: 13.8 | I26: 40 | J26: 40 | K26: 13.3 | L26: YNyn0d11 | M26: 8.46 | N26: 8.3 | O26: 6.59999 | P26: 8.3 | Q26: 8.46 | R26: 6.6 | S26: 9 | T26: 17 | U26: 1 | V26: 1.25 | W26: 130 | X26: 30 | Y26: Sí | AA26: STR | AB26: 96.66 | AC26: - | AD26: - | AE26: 0 | AF26: 0 | AG26: 0 | AH26: ESSA | AI26: Activos de uso de STR y SDL
A27: =VLOOKUP(E27,'[1]Listas Desplegables'!$H$3:$J$7,2,FALSE()) -> #N/A | B27: =VLOOKUP(E27,'[1]Listas Desplegables'!$H$3:$J$7,3,FALSE()) -> #N/A | C27: 22 | D27: T3 Palenque 115/34.5 40 MVA | E27: Palenque 115 | F27: 115 | G27: 34.5 | H27: 13.8 | I27: 40 | J27: 40 | K27: 13.3 | L27: YNyn0d11 | M27: 8.47 | N27: 2.926 | O27: 6.4838 | P27: 2.926 | Q27: 8.84 | R27: 6.484 | S27: 9 | T27: 17 | U27: 1 | V27: 1.25 | W27: 130 | X27: 30 | Y27: Sí | AA27: STR | AB27: 97.3 | AC27: 16.89 | AD27: 37.34 | AE27: 0 | AF27: 0 | AG27: 0 | AH27: ESSA | AI27: Activos de uso de STR y SDL
A28: =VLOOKUP(E28,'[1]Listas Desplegables'!$H$3:$J$7,2,FALSE()) -> #N/A | B28: =VLOOKUP(E28,'[1]Listas Desplegables'!$H$3:$J$7,3,FALSE()) -> #N/A | C28: 23 | D28: T5 Mesa del Sol 115/34.5 25 MVA | E28: Mesa del Sol 115 | F28: 115 | G28: 34.5 | H28: 13.2 | I28: 25 | J28: 25 | K28: 8.3 | L28: YNyn0d11 | M28: 9.74 | N28: 5.52 | O28: 1.67 | P28: 4.3749 | Q28: 8.05 | R28: 1.5747 | S28: 10 | T28: 19 | U28: 1 | V28: 1.25 | W28: 120 | X28: 120 | Y28: Sí | AA28: STR | AB28: 105.842 | AC28: 16.96 | AD28: 15.2 | AE28: 0 | AF28: 0 | AG28: 0 | AH28: ESSA | AI28: Activos de uso de STR y SDL
A29: =VLOOKUP(E29,'[1]Listas Desplegables'!$H$3:$J$7,2,FALSE()) -> #N/A | B29: =VLOOKUP(E29,'[1]Listas Desplegables'!$H$3:$J$7,3,FALSE()) -> #N/A | C29: 24 | D29: Rio Frio T2 115/34.5/13.8 | E29: Rio Frio 115 | F29: 115 | G29: 34.5 | H29: 13.8 | I29: 40 | J29: 40 | K29: 13.3 | L29: YNyn0d11 | M29: 8.4 | N29: 8.3 | O29: 6.6 | P29: 8.685357 | Q29: 8.79 | R29: 6.90643 | S29: 9 | T29: 17 | U29: 1 | V29: 1.25 | W29: 130 | X29: 0 | Y29: Sí | AA29: STR | AB29: 97.3 | AC29: - | AD29: - | AE29: 0 | AF29: 0 | AG29: 0 | AH29: ESSA | AI29: Activos de uso de STR y SDL
A30: =VLOOKUP(E30,'[1]Listas Desplegables'!$H$3:$J$7,2,FALSE()) -> #N/A | B30: =VLOOKUP(E30,'[1]Listas Desplegables'!$H$3:$J$7,3,FALSE()) -> #N/A | C30: 25 | D30: T 2 Palos 115/34.5/13.8 | E30: Palos 115 | F30: 115 | G30: 34.5 | H30: 13.8 | I30: 40 | J30: 40 | K30: 4.7 | L30: YNyn0d11 | M30: 11.33 | N30: 10.79 | O30: 8.6 | P30: 10.79 | Q30: 11.33 | R30: 8.6 | S30: 9 | T30: 17 | U30: 1 | V30: 1.25 | W30: 130 | X30: 30 | Y30: Sí | AA30: STR | AB30: 96.13 | AC30: - | AD30: - | AE30: 0 | AF30: 0 | AG30: 0 | AH30: ESSA | AI30: Activos de uso de STR y SDL
A31: =VLOOKUP(E31,'[1]Listas Desplegables'!$H$3:$J$7,2,FALSE()) -> #N/A | B31: =VLOOKUP(E31,'[1]Listas Desplegables'!$H$3:$J$7,3,FALSE()) -> #N/A | C31: 26 | D31: Realminas 3 115/34.5/13.8 | E31: Realminas 115 | F31: 115 | G31: 34.5 | H31: 13.8 | I31: 40 | J31: 40 | K31: 13.3 | L31: YNyn0d11 | M31: 8.67 | N31: 8.3 | O31: 6.59999 | P31: 8.3 | Q31: 8.67 | R31: 6.6 | S31: 9 | T31: 17 | U31: 1 | V31: 1.25 | W31: 130 | X31: 30 | Y31: Sí | AA31: STR | AB31: 96.66 | AC31: - | AD31: - | AE31: 0 | AF31: 0 | AG31: 0 | AH31: ESSA | AI31: Activos de uso de STR y SDL
A32: =VLOOKUP(E32,'[1]Listas Desplegables'!$H$3:$J$7,2,FALSE()) -> #N/A | B32: =VLOOKUP(E32,'[1]Listas Desplegables'!$H$3:$J$7,3,FALSE()) -> #N/A | C32: 27 | D32: T 7 Palos 115/34.5/13.8 | E32: Palos 115 | F32: 115 | G32: 34.5 | H32: 13.8 | I32: 40 | J32: 40 | K32: 13.3 | L32: YNyn0d0 | M32: 11.36 | N32: 10.79 | O32: 8.60002 | P32: 10.79 | Q32: 11.36 | R32: 8.6 | S32: 9 | T32: 17 | U32: 1 | V32: 1.25 | W32: 130 | X32: 30 | Y32: Sí | AA32: STR | AB32: 97.3 | AC32: - | AD32: - | AE32: 0 | AF32: 0 | AG32: 0 | AH32: ESSA | AI32: Activos de uso de STR y SDL
A33: =VLOOKUP(E33,'[1]Listas Desplegables'!$H$3:$J$7,2,FALSE()) -> #N/A | B33: =VLOOKUP(E33,'[1]Listas Desplegables'!$H$3:$J$7,3,FALSE()) -> #N/A | C33: 28 | D33: Realminas 1 115/34.5/13.8 | E33: Realminas 115 | F33: 115 | G33: 34.5 | H33: 13.8 | I33: 40 | J33: 40 | K33: 13.3 | L33: YNyn0d1 | M33: 8.4 | N33: 8.3 | O33: 6.2 | P33: 8.3 | Q33: 8.4 | R33: 6.2 | S33: 9 | T33: 17 | U33: 1 | V33: 1.25 | W33: 130 | X33: 30 | Y33: Sí | AA33: STR | AB33: 96.66 | AC33: - | AD33: - | AE33: 0 | AF33: 0 | AG33: 0 | AH33: ESSA | AI33: Activos de uso de STR y SDL
A34: =VLOOKUP(E34,'[1]Listas Desplegables'!$H$3:$J$7,2,FALSE()) -> #N/A | B34: =VLOOKUP(E34,'[1]Listas Desplegables'!$H$3:$J$7,3,FALSE()) -> #N/A | C34: 29 | D34: SanGil 1 115/34.5/13.8 | E34: San Gil 115 | F34: 115 | G34: 34.5 | H34: 13.8 | I34: 40 | J34: 40 | K34: 13.3 | L34: YNyn0d11 | M34: 8.68 | N34: 8.31001 | O34: 6.59999 | P34: 8.31 | Q34: 8.68 | R34: 6.6 | S34: 9 | T34: 17 | U34: 1 | V34: 1.25 | W34: 130 | X34: 30 | Y34: Sí | AA34: STR | AB34: 96.66 | AC34: - | AD34: - | AE34: 0 | AF34: 0 | AG34: 0 | AH34: ESSA | AI34: Activos de uso de STR y SDL
A35: =VLOOKUP(E35,'[1]Listas Desplegables'!$H$3:$J$7,2,FALSE()) -> #N/A | B35: =VLOOKUP(E35,'[1]Listas Desplegables'!$H$3:$J$7,3,FALSE()) -> #N/A | C35: 30 | D35: Condor 115/34.5 50 MVA | E35: Condor 115 | F35: 115 | G35: 34.5 | H35: 13.8 | I35: 50 | J35: 50 | K35: 16.7 | L35: YN0yn0yn0 | M35: 10.3 | N35: 3 | O35: 7.9 | P35: 0 | Q35: 0 | R35: 0 | S35: 0 | T35: 9 | U35: -9 | V35: 1.25 | W35: 100 | X35: 30 | Y35: Sí | AA35: STR | AB35: 0 | AC35: 0 | AD35: 0 | AE35: 0 | AF35: 0 | AG35: 0 | AH35: ESSA | AI35: Activos de conexión a un STR o a un SDL
A36: =VLOOKUP(E36,'[1]Listas Desplegables'!$H$3:$J$7,2,FALSE()) -> #N/A | B36: =VLOOKUP(E36,'[1]Listas Desplegables'!$H$3:$J$7,3,FALSE()) -> #N/A | C36: 31 | D36: T1 Lizama 20 MVA 115/34.5 kV | E36: Lizama 115 | F36: 115 | G36: 34.5 | H36: 13.8 | I36: 15 | J36: 15 | K36: 3 | L36: YNd1 | M36: 9.3 | N36: 8.93 | O36: 3 | P36: 8.93 | Q36: 0 | R36: 0 | S36: 17 | T36: 33 | U36: 1 | V36: 0.625 | W36: 120 | X36: 30 | Y36: Sí | AA36: STR | AB36: 0 | AC36: - | AD36: 0 | AE36: 0 | AF36: 0 | AG36: 0 | AH36: ESSA | AI36: Activos de uso de STR y SDL
A37: =VLOOKUP(E37,'[1]Listas Desplegables'!$H$3:$J$7,2,FALSE()) -> #N/A | B37: =VLOOKUP(E37,'[1]Listas Desplegables'!$H$3:$J$7,3,FALSE()) -> #N/A | C37: 32 | D37: Rio Frio T1 115/34.5/13.8 | E37: Rio Frio 115 | F37: 115 | G37: 34.5 | H37: 13.8 | I37: 40 | J37: 40 | K37: 13.3 | L37: YNyn0d11 | M37: 8.42 | N37: 8.3 | O37: 6.6 | P37: 8.694299 | Q37: 8.82 | R37: 6.91354 | S37: 9 | T37: 17 | U37: 1 | V37: 1.25 | W37: 130 | X37: 0 | Y37: Sí | AA37: STR | AB37: 98.743 | AC37: - | AD37: - | AE37: 0 | AF37: 0 | AG37: 0 | AH37: ESSA | AI37: Activos de uso de STR y SDL
A38: =VLOOKUP(E38,'[1]Listas Desplegables'!$H$3:$J$7,2,FALSE()) -> #N/A | B38: =VLOOKUP(E38,'[1]Listas Desplegables'!$H$3:$J$7,3,FALSE()) -> #N/A | C38: 33 | D38: T6 Mesa del Sol 115/34.5 25 MVA | E38: Mesa del Sol 115 | F38: 115 | G38: 34.5 | H38: 13.2 | I38: 25 | J38: 25 | K38: 8.3 | L38: YNyn0d11 | M38: 9.77 | N38: 5.52 | O38: 1.67 | P38: 4.3749 | Q38: 8.05 | R38: 1.59 | S38: 10 | T38: 19 | U38: 1 | V38: 1.25 | W38: 120 | X38: 120 | Y38: Sí | AA38: STR | AB38: 106.638 | AC38: 16.96 | AD38: 15.2 | AE38: 0 | AF38: 0 | AG38: 0 | AH38: ESSA | AI38: Activos de uso de STR y SDL
A39: =VLOOKUP(E39,'[1]Listas Desplegables'!$H$3:$J$7,2,FALSE()) -> #N/A | B39: =VLOOKUP(E39,'[1]Listas Desplegables'!$H$3:$J$7,3,FALSE()) -> #N/A | C39: 34 | D39: T4 SanSilvestre 115/34.5/13.8 | E39: San Silvestre 115 | F39: 115 | G39: 34.5 | H39: 13.8 | I39: 40 | J39: 40 | K39: 13.3 | L39: YNyn0d11 | M39: 8.51 | N39: 8.29999 | O39: 6.60002 | P39: 8.3 | Q39: 8.84 | R39: 6.6 | S39: 9 | T39: 17 | U39: 1 | V39: 1.25 | W39: 120 | X39: 30 | Y39: Sí | AA39: STR | AB39: 96.86 | AC39: - | AD39: - | AE39: 0 | AF39: 0 | AG39: 0 | AH39: ESSA | AI39: Activos de uso de STR y SDL
A40: =VLOOKUP(E40,'[1]Listas Desplegables'!$H$3:$J$7,2,FALSE()) -> #N/A | B40: =VLOOKUP(E40,'[1]Listas Desplegables'!$H$3:$J$7,3,FALSE()) -> #N/A | C40: 35 | D40: Wilches 1 115/34.5/13.8 | E40: Wilches 115 | F40: 115 | G40: 34.5 | H40: 13.8 | I40: 40 | J40: 40 | K40: 13.3 | L40: YNyn0d1 | M40: 8.7 | N40: 6.42001 | O40: 2.92001 | P40: 6.42001 | Q40: 8.7 | R40: 2.92001 | S40: 9 | T40: 17 | U40: 1 | V40: 1.25 | W40: 130 | X40: 30 | Y40: Sí | AA40: STR | AB40: 97.3 | AC40: - | AD40: - | AE40: 0 | AF40: 0 | AG40: 0 | AH40: ESSA | AI40: Activos de uso de STR y SDL
A41: =VLOOKUP(E41,'[1]Listas Desplegables'!$H$3:$J$7,2,FALSE()) -> #N/A | B41: =VLOOKUP(E41,'[1]Listas Desplegables'!$H$3:$J$7,3,FALSE()) -> #N/A | C41: 36 | D41: T3 SanSilvestre 115/34.5/13.8 | E41: San Silvestre 115 | F41: 115 | G41: 34.5 | H41: 13.8 | I41: 40 | J41: 40 | K41: 13.3 | L41: YNyn0d11 | M41: 10.75 | N41: 6.17999 | O41: 2.91001 | P41: 6.1799 | Q41: 9.7 | R41: 2.91 | S41: 7 | T41: 15 | U41: 1 | V41: 1.25 | W41: 120 | X41: 30 | Y41: Sí | AA41: STR | AB41: 96.86 | AC41: - | AD41: - | AE41: 0 | AF41: 0 | AG41: 0 | AH41: ESSA | AI41: Activos de uso de STR y SDL
A42: =VLOOKUP(E42,'[1]Listas Desplegables'!$H$3:$J$7,2,FALSE()) -> #N/A | B42: =VLOOKUP(E42,'[1]Listas Desplegables'!$H$3:$J$7,3,FALSE()) -> #N/A | C42: 37 | D42: T1 Sabana 115/34.5/13.8 | E42: Sabana 115 | F42: 115 | G42: 34.5 | H42: 13.8 | I42: 20 | J42: 20 | K42: 6.7 | L42: YNyn0d11 | M42: 12.67 | N42: 6.67 | O42: 1.87 | P42: 6.67 | Q42: 12.67 | R42: 1.87 | S42: 9 | T42: 17 | U42: 1 | V42: 1.25 | W42: 130 | X42: 30 | Y42: Sí | AA42: STR | AB42: 97.34 | AC42: - | AD42: - | AE42: 0 | AF42: 0 | AG42: 0 | AH42: ESSA | AI42: Activos de uso de STR y SDL
...

Sheet 3. Tr2
C3: Información General de Transformadores Bidevanados
C4: No. | D4: ='Manual de Uso'!C87 -> Nombre | E4: ='Manual de Uso'!C88 -> Subestación | F4: ='Manual de Uso'!C89 -> Nivel de tensión HV [kV] | G4: ='Manual de Uso'!C90 -> Nivel de tensión LV [kV] | H4: ='Manual de Uso'!C91 -> Capacidad [MVA] | I4: ='Manual de Uso'!C92 -> Grupo de conexión | J4: ='Manual de Uso'!C93 -> Impedancia Secuencia +[%] | K4: ='Manual de Uso'!C94 -> Impedancia Secuencia 0[%] | L4: ='Manual de Uso'!C95 -> Posición Neutral Tap | M4: ='Manual de Uso'!C96 -> Posición Máxima Tap | N4: ='Manual de Uso'!C97 -> Posición Mínima Tap | O4: ='Manual de Uso'!C98 -> Delta Tap [%] | P4: ='Manual de Uso'!C99 -> Sobrecarga en emergencia | R4: ='Manual de Uso'!C100 -> En Operación | S4: ='Manual de Uso'!C101 -> FPO | T4: ='Manual de Uso'!C102 -> Sistema | U4: ='Manual de Uso'!C103 -> Pérdidas Cu [kW] | V4: ='Manual de Uso'!C104 -> Tiempo medio de reparación por evento [h] | W4: ='Manual de Uso'!C105 -> Horas anuales de indisponibilidad [h] | X4: ='Manual de Uso'!C106 -> Eventos anuales de indisponibilidad | Y4: ='Manual de Uso'!C107 -> Operador | Z4: ='Manual de Uso'!C108 -> Tipo activo Uso/Conexión | AA4: ='Manual de Uso'!C109 -> Observaciones transportador
P5: Magnitud [%] | Q5: Tiempo [minutos]
A6: =VLOOKUP(E6,'[1]Listas Desplegables'!$H$3:$J$7,2,FALSE()) -> #N/A | B6: =VLOOKUP(E6,'[1]Listas Desplegables'!$H$3:$J$7,3,FALSE()) -> #N/A | C6: 1 | D6: T-2 Principal 34.5/13.8 | E6: - Principal 34.5 | F6: 34.5 | G6: 13.8 | H6: 12.5 | I6: Dyn11 | J6: 9.1 | K6: 9.1 | L6: 3 | M6: 5 | N6: 1 | O6: 2.5 | P6: 100 | Q6: 30 | R6: Sí | T6: SDL | U6: 117.6652 | Y6: ESSA | Z6: Activos de uso de STR y SDL
A7: =VLOOKUP(E7,'[1]Listas Desplegables'!$H$3:$J$7,2,FALSE()) -> #N/A | B7: =VLOOKUP(E7,'[1]Listas Desplegables'!$H$3:$J$7,3,FALSE()) -> #N/A | C7: 2 | D7: T1 Carmen 34.5/13.8 | E7: Carmen 34.5 | F7: 34.5 | G7: 13.8 | H7: 6 | I7: Dyn11 | J7: 6.8 | K7: 6.8 | L7: 3 | M7: 5 | N7: 1 | O7: 2.5 | P7: 100 | Q7: 30 | R7: Sí | T7: SDL | U7: 117.6652 | Y7: ESSA | Z7: Activos de uso de STR y SDL
A8: =VLOOKUP(E8,'[1]Listas Desplegables'!$H$3:$J$7,2,FALSE()) -> #N/A | B8: =VLOOKUP(E8,'[1]Listas Desplegables'!$H$3:$J$7,3,FALSE()) -> #N/A | C8: 3 | D8: Cascada 2 1.5 MVA 13.8/6.3 | E8: Nodo Cascada 6.2 | F8: 13.8 | G8: 6.3 | H8: 1.5 | I8: YNd5 | J8: 4.8 | K8: 4.8 | L8: 3 | M8: 5 | N8: 1 | O8: 2.5 | P8: 120 | Q8: 30 | R8: Sí | T8: SDL | U8: 15.77 | Y8: ESSA | Z8: Activos de uso de STR y SDL
A9: =VLOOKUP(E9,'[1]Listas Desplegables'!$H$3:$J$7,2,FALSE()) -> #N/A | B9: =VLOOKUP(E9,'[1]Listas Desplegables'!$H$3:$J$7,3,FALSE()) -> #N/A | C9: 4 | D9: Charala 34.5/13.8 | E9: Charalá 34.5 | F9: 34.5 | G9: 13.8 | H9: 6 | I9: Dyn11 | J9: 7.3 | K9: 7.3 | L9: 3 | M9: 5 | N9: 1 | O9: 2.5 | P9: 129 | Q9: 30 | R9: Sí | T9: SDL | U9: 25.0332 | Y9: ESSA | Z9: Activos de uso de STR y SDL
A10: =VLOOKUP(E10,'[1]Listas Desplegables'!$H$3:$J$7,2,FALSE()) -> #N/A | B10: =VLOOKUP(E10,'[1]Listas Desplegables'!$H$3:$J$7,3,FALSE()) -> #N/A | C10: 5 | D10: Bosque 1 34.5/13.8 | E10: Bosque 2 34.5 | F10: 34.5 | G10: 13.8 | H10: 25 | I10: Dyn11 | J10: 8.9 | K10: 8.9 | L10: 3 | M10: 5 | N10: 1 | O10: 2.5 | P10: 103 | Q10: 30 | R10: Sí | T10: SDL | U10: 233.4552 | Y10: ESSA | Z10: Activos de uso de STR y SDL
A11: =VLOOKUP(E11,'[1]Listas Desplegables'!$H$3:$J$7,2,FALSE()) -> #N/A | B11: =VLOOKUP(E11,'[1]Listas Desplegables'!$H$3:$J$7,3,FALSE()) -> #N/A | C11: 6 | D11: Bucarica 1 34.5/13.8 | E11: Bucarica 34.5 | F11: 34.5 | G11: 13.8 | H11: 15 | I11: Dyn11 | J11: 11.1 | K11: 11.1 | L11: 3 | M11: 5 | N11: 1 | O11: 2.5 | P11: 129 | Q11: 30 | R11: Sí | T11: SDL | U11: 140.8232 | Y11: ESSA | Z11: Activos de uso de STR y SDL
A12: =VLOOKUP(E12,'[1]Listas Desplegables'!$H$3:$J$7,2,FALSE()) -> #N/A | B12: =VLOOKUP(E12,'[1]Listas Desplegables'!$H$3:$J$7,3,FALSE()) -> #N/A | C12: 7 | D12: Capitanejo 34.5/13.8 | E12: Capitanejo 34.5 | F12: 34.5 | G12: 13.8 | H12: 2 | I12: Dyn11 | J12: 5.3 | K12: 5.3 | L12: 3 | M12: 5 | N12: 1 | O12: 2.5 | P12: 134 | Q12: 30 | R12: Sí | T12: SDL | U12: 20.4016 | Y12: ESSA | Z12: Activos de uso de STR y SDL
A13: =VLOOKUP(E13,'[1]Listas Desplegables'!$H$3:$J$7,2,FALSE()) -> #N/A | B13: =VLOOKUP(E13,'[1]Listas Desplegables'!$H$3:$J$7,3,FALSE()) -> #N/A | C13: 8 | D13: Bellavista 34.5/13.8 | E13: Bellavista 34.5 | F13: 34.5 | G13: 13.8 | H13: 6 | I13: Dyn11 | J13: 7.2 | K13: 7.2 | L13: 3 | M13: 5 | N13: 1 | O13: 2.5 | P13: 130 | Q13: 30 | R13: Sí | T13: SDL | U13: 57.4544 | Y13: ESSA | Z13: Activos de uso de STR y SDL
A14: =VLOOKUP(E14,'[1]Listas Desplegables'!$H$3:$J$7,2,FALSE()) -> #N/A | B14: =VLOOKUP(E14,'[1]Listas Desplegables'!$H$3:$J$7,3,FALSE()) -> #N/A | C14: 9 | D14: Bosque 2 34.5/13.8 | E14: Bosque 1 34.5 | F14: 34.5 | G14: 13.8 | H14: 12.5 | I14: Dyn11 | J14: 8.9 | K14: 8.9 | L14: 3 | M14: 5 | N14: 1 | O14: 2.5 | P14: 123 | Q14: 30 | R14: Sí | T14: SDL | U14: 117.6652 | Y14: ESSA | Z14: Activos de uso de STR y SDL
A15: =VLOOKUP(E15,'[1]Listas Desplegables'!$H$3:$J$7,2,FALSE()) -> #N/A | B15: =VLOOKUP(E15,'[1]Listas Desplegables'!$H$3:$J$7,3,FALSE()) -> #N/A | C15: 10 | D15: Caneyes 2 34.5/13.8 | E15: Caneyes 2 34.5 | F15: 34.5 | G15: 13.8 | H15: 25 | I15: Dyn11 | J15: 8.6 | K15: 8.6 | L15: 3 | M15: 5 | N15: 1 | O15: 2.5 | P15: 130 | Q15: 30 | R15: No | S15: 46752 | T15: SDL | U15: 117.6652 | Y15: ESSA | Z15: Activos de uso de STR y SDL | AA15: Nuevo transformador a instalar en el año 2027
A16: =VLOOKUP(E16,'[1]Listas Desplegables'!$H$3:$J$7,2,FALSE()) -> #N/A | B16: =VLOOKUP(E16,'[1]Listas Desplegables'!$H$3:$J$7,3,FALSE()) -> #N/A | C16: 11 | D16: T1 Buenavista 34.5/13.8 | E16: Buenavista 34.5 | F16: 34.5 | G16: 13.8 | H16: 12.5 | I16: Dyn11 | J16: 7.6 | K16: 7.6 | L16: 3 | M16: 5 | N16: 1 | O16: 2.5 | P16: 100 | Q16: 30 | R16: Sí | T16: SDL | U16: 117.6652 | Y16: ESSA | Z16: Activos de uso de STR y SDL
