Workbook

Sheet Manual de Uso
B2: MANUAL DE USO PARA EL REPORTE DE INFORMACIÓN REQUERIDA DE LOS TRANSPORTADORES
B7: INTRODUCCIÓN
B8: El presente formato se establece en cumplimiento de lo establecido en el articulo 7 de la Resolución CREG 075 de 2021, para facilitar el reporte uniforme de la información que los transportadores deben entregar para la realización de los estudios de conexión y disponibilidad de espacio físico. El uso del presente formato es transitorio, y se requerirá hasta que entre en funcionamiento el sistema de información de la ventanilla única de la UPME, a través del cual se reportará y actualizará la información requerida para estudios de conexión.
B14: CONTENIDO
B15: El Formato se encuentra dividido en 9 secciones según el tipo de activo a reportar: 1. Información de líneas de transmisión y distribución 2. Información de transformadores tridevanados 3. Información de transformadores bidevanados 4. Información de subestaciones 5. Información de demandas 6. Información de compensaciones 7. Información de compensaciones dinámicas 8. Información de dispositivos DFACTS 9. Información de disponibilidad de espacio físico
B26: MANUAL DE USO
B27: Dentro de cada sección se solicita que el Transportador compile información característica de cada uno de los tipos de activo. A continuación, se presenta la información y una descripción de lo requerido:
B29: Líneas de transmisión y distribución | C29: Nombre | D29: Nombre de línea de transmisión o distribución.
C30: Subestación 1 | D30: Subestación o punto de la red a la cual se conecta uno de los extremos de la línea
C31: Subestación 2 | D31: Subestación o punto de la red a la cual se conecta el otro extremo de la línea
C32: Nivel de tensión [kV] | D32: Nivel de tensión nominal en kilovoltios al cual opera la línea
C33: Longitud [km] | D33: Longitud en kilometros de la línea
C34: Capacidad transporte nominal [A] | D34: Capacidad de transporte de corriente nominal de la línea de transmisión en estado estable en amperios
C35: Capacidad transporte térmico [A] | D35: Capacidad nominal de transporte de corriente del conductor de menor capacidad utilizado en la línea de transmisión en amperios
C36: Capacidad transporte emergencia [A] | D36: Capacidad de corriente máxima que puede soportar la línea ante condiciones de emergencia en amperios
C37: Causa límite de capacidad | D37: Declarar cuál es el elemento que impone el límite operativo, es decir el que restringe la máxima corriente. Entre los elementos están: línea de transmisión (Cable), bajantes de conexión con los pararrayos y los transformadores de potencial, trampas de onda, transformadores de corriente, interruptores, seccionadores
C38: R1 [Ohm/km] | D38: Resistencia de secuencia positiva por unidad de longitud en ohmios por kilometro
C39: X1 [Ohm/km] | D39: Reactancia de secuencia positiva por unidad de longitud en ohmios por kilometro
C40: B1 [uS/km] | D40: Susceptancia de secuancia positiva por unidad de longitud en microsiemens por kilometro
C41: R0 [Ohm/km] | D41: Resistencia de secuencia cero por unidad de longitud en ohmios por kilometro
... C45: Tipo | D45: Tipo de línea. Se debe escoger en la lista desplegable entre: Áerea o Subterranea
C46: En Operación | D46: Se debe escoger en la lista desplegable entre: Sí, cuando el activo se encuentre en operación al momento de realizar la entrega de la información, o No, si el activo tiene una fecha de puesta en operación futura | I46: Activos de uso de STN
C47: FPO | D47: Si el activo no se encuentra en operación, se debe especificar la Fecha de Puesta en Operación planteada en formato dd/mm/aaaa. | I47: Activos de uso de STR y SDL
C48: Conductor | D48: Se debe indicar el calibre y material del conductor predominante en la línea de transmisión o distribución | I48: Activos de conexión del OR al STN
C49: Tiempo medio de reparación por evento [h] | D49: Tiempo de medio en horas que puede durar cada evento de indisponibilidad del activo | I49: Activos de conexión a un STR o a un SDL
C50: Horas anuales de indisponibilidad [h] | D50: Tiempo anual de indisponibilidad del activo en horas
C51: Eventos anuales de indisponibilidad | D51: Número de eventos de indisponibilidad del activo
C52: Operador | D52: Compañía que opera la línea de transmisión ante el CND
C53: Tipo activo Uso/Conexión | D53: Activos de uso de STN: son aquellos activos de transporte de electricidad que operan a tensiones iguales o superiores a 220 kV, son remunerados mediante Cargos por Uso del STN y pueden estar constituidos por una o varias UC. (Resolución CREG 011 de 2009. Activos de uso de STR y SDL: son aquellos activos de transporte de electricidad que operan a tensiones inferiores a 220 kV que son utilizados por más de un usuario y son remunerados mediante cargos por uso de STR o SDL. (Resolución CREG 015 de 2018) Nota: Los activos que sean remunerados mediante cargos por uso del STN o STR y que están constituidos por una o varias unidades constructivas y que pertenezcan a nivel inferior a 220 kV se deberán clasificar como Activos de Uso del STN o STR de acuerdo a como sean remunerados Activos de conexión del OR al STN: son los bienes que se requieren para que un operador de red se conecte físicamente al Sistema de Transmisión Nacional, STN. Activos de conexión a un STR o a un SDL: son los bienes que se requieren para que un OR se conecte físicamente a un Sistema de Transmisión Regional, STR, o a un Sistema de Distribución Local, SDL, de otro OR (Operador de Red). También son activos de conexión los utilizados exclusivamente por un usuario final para conectarse a los niveles de tensión 4, 3, 2 o 1. Un usuario está conectado al nivel de tensión en el que está instalado su equipo de medida individual (Resolución CREG 015 de 2018))
C54: Observaciones transportador | D54: Sección de libre diligenciamiento, donde el transportador debe indicar explicítamente cualquier condición operativa o de planeación que no este incluida en las demás variables. Ejemplo: La línea opera normalmente abierta al lado de la subestación A o se tiene planeado una repotenciación de la línea hasta una capacidad de X Amperios, la cual entrará en operación desde dd/mm/aaaa.
B55: Transformadores tridevanados | C55: Nombre | D55: Nombre del transformador tridevanado. Se sugiere sea nombre de la subestación seguido de los niveles de tensión del transformador
C56: Subestación | D56: Subestación en la cual se encuentra ubicado el transformador
C57: Nivel de tensión HV [kV] | D57: Nivel de tensión nominal de diseño de los bornes de alta tensión del transformador en kilovoltios
C58: Nivel de tensión MV [kV] | D58: Nivel de tensión nominal de diseño de los bornes de media tensión del transformador en kilovoltios
C59: Nivel de tensión LV [kV] | D59: Nivel de tensión nominal de diseño de los bornes de baja tensión del transformador en kilovoltios
C60: Capacidad HV [MVA] | D60: Capacidad nominal en el devanado de alta tensión del transformador en MVA
C61: Capacidad MV [MVA] | D61: Capacidad nominal en el devanado de media tensión del transformador en MVA
C62: Capacidad LV [MVA] | D62: Capacidad nominal en el devanado de baja tensión del transformador en MVA
C63: Grupo de conexión | D63: Convención utilizada para describir las configuraciones de los distintos devanados del transformador y el desfase en los angulos de fase según norma IEC 60076-1 2011. Ejemplo: YNyn0d5
C64: Impedancia HV-MV Secuencia +[%] | D64: Impedancia de corto circuito entre los devanados de alta y media tensión en secuencia positiva como porcentaje de la impedancia de referencia
...

Sheet Unifilares Atlantico
B9: UNIFILAR ACTUAL | N9: UNIFILAR FUTURO
C45: UNIFILAR SDL SE MALAMBO | O45: UNIFILAR SDL SE BARANOA | Z45: UNIFILAR SDL SE'S LAS FLORES, RIOMAR y SILENCIO
AK47: UNIFILAR SDL SE NUEVA GALAPA
AK61: UNIFILAR SDL SE PALERMO
C65: Unifilar SDL SE's El Río, Unión y Magdalena
U74: UNIFILAR SDL SE SALAMINA
C86: UNIFILAR SDL SE SABANALARGA

Sheet Unifiliares Magdalena y Guajira
D4: Diagramas Unifilares Actuales De La Guajira y Magdalena | Y4: Diagramas Unifilares Futuros De La Guajira y Magdalena
C53: UNIFILAR SDL SE SAN JUAN | J53: UNIFILAR SDL SE RIOHACHA | Y53: UNIFILAR SDL SE SANTA MARTA
D75: UNIFILAR SDL SE CUESTECITAS | K75: UNIFILAR SDL SE FUNDACIÓN | U75: UNIFILAR SDL SE RÍO CÓRDOBA | Z75: UNIFILAR SDL SE GAIRA
D96: UNIFILAR SDL SE PLATO

Sheet 1. Líneas
C3: Información General de Líneas
C4: No. | D4: ='Manual de Uso'!C29 -> Nombre | E4: ='Manual de Uso'!C30 -> Subestación 1 | F4: ='Manual de Uso'!C31 -> Subestación 2 | G4: ='Manual de Uso'!C32 -> Nivel de tensión [kV] | H4: ='Manual de Uso'!C33 -> Longitud [km] | I4: ='Manual de Uso'!C34 -> Capacidad transporte nominal [A] | J4: ='Manual de Uso'!C35 -> Capacidad transporte térmico [A] | K4: ='Manual de Uso'!C36 -> Capacidad transporte emergencia [A] | L4: ='Manual de Uso'!C37 -> Causa límite de capacidad | M4: ='Manual de Uso'!C38 -> R1 [Ohm/km] | N4: ='Manual de Uso'!C39 -> X1 [Ohm/km] | O4: ='Manual de Uso'!C40 -> B1 [uS/km] | P4: ='Manual de Uso'!C41 -> R0 [Ohm/km] | Q4: ='Manual de Uso'!C42 -> X0 [Ohm/km] | R4: ='Manual de Uso'!C43 -> B0 [uS/km] | S4: ='Manual de Uso'!C44 -> Sistema | T4: ='Manual de Uso'!C45 -> Tipo | U4: ='Manual de Uso'!C46 -> En Operación | V4: ='Manual de Uso'!C47 -> FPO | W4: ='Manual de Uso'!C48 -> Conductor | X4: ='Manual de Uso'!C49 -> Tiempo medio de reparación por evento [h] | Y4: ='Manual de Uso'!C50 -> Horas anuales de indisponibilidad [h] | Z4: ='Manual de Uso'!C51 -> Eventos anuales de indisponibilidad | AA4: ='Manual de Uso'!C52 -> Operador | AB4: ='Manual de Uso'!C53 -> Tipo activo Uso/Conexión | AC4: ='Manual de Uso'!C54 -> Observaciones transportador
A6: =VLOOKUP(E6,'[1]Listas Desplegables'!$H$3:$J$7,2,FALSE()) -> #N/A | B6: =VLOOKUP(E6,'[1]Listas Desplegables'!$H$3:$J$7,3,FALSE()) -> #N/A | C6: 1 | D6: LN701 | E6: Oasis | F6: Termoflores | G6: 110 | H6: 3.2 | I6: 945 | J6: 979 | K6: 979 | L6: Línea de transmisión | M6: 0.0303 | N6: 0.1997 | O6: 6.456 | P6: 0.368 | Q6: 1.481 | R6: 1.827 | S6: STR | T6: Áerea | U6: Sí | W6: 927,2 AAAC | Y6: 74.1 | Z6: 1
A7: =VLOOKUP(E7,'[1]Listas Desplegables'!$H$3:$J$7,2,FALSE()) -> #N/A | B7: =VLOOKUP(E7,'[1]Listas Desplegables'!$H$3:$J$7,3,FALSE()) -> #N/A | C7: 2 | D7: LN703 | E7: Caracolí | F7: Silencio | G7: 110 | H7: 12.5 | I7: 691 | J7: 706 | K7: 706 | L7: Línea de transmisión | M7: 0.0736 | N7: 0.4552 | O7: 3.6814 | P7: 0.2417 | Q7: 1.5823 | R7: 2.189 | S7: STR | T7: Áerea | U7: Sí | W7: 927,2 AAAC | Y7: 153.34 | Z7: 1
A8: =VLOOKUP(E8,'[1]Listas Desplegables'!$H$3:$J$7,2,FALSE()) -> #N/A | B8: =VLOOKUP(E8,'[1]Listas Desplegables'!$H$3:$J$7,3,FALSE()) -> #N/A | C8: 3 | D8: LN704 | E8: Tebsa | F8: Cordialidad | G8: 110 | H8: 8.62 | I8: 640 | J8: 794 | K8: 690 | L8: Línea de transmisión | M8: 0.074 | N8: 0.4757 | O8: 3.52 | P8: 0.4246 | Q8: 1.4121 | R8: 2.14 | S8: STR | T8: Áerea | U8: Sí | W8: 927,2 AAAC | Y8: 29.55 | Z8: 1
A9: =VLOOKUP(E9,'[1]Listas Desplegables'!$H$3:$J$7,2,FALSE()) -> #N/A | B9: =VLOOKUP(E9,'[1]Listas Desplegables'!$H$3:$J$7,3,FALSE()) -> #N/A | C9: 4 | D9: LN705 | E9: Baranoa | F9: Malambo | G9: 110 | H9: 17.7 | I9: 530 | J9: 580 | K9: 580 | L9: Línea de transmisión | M9: 0.1194 | N9: 0.4952 | O9: 3.34 | P9: 0.4512 | Q9: 1.4377 | R9: 2.06 | S9: STR | T9: Áerea | U9: Sí | W9: 559,5 AAAC | Y9: 30.21 | Z9: 1
A10: =VLOOKUP(E10,'[1]Listas Desplegables'!$H$3:$J$7,2,FALSE()) -> #N/A | B10: =VLOOKUP(E10,'[1]Listas Desplegables'!$H$3:$J$7,3,FALSE()) -> #N/A | C10: 5 | D10: LN706 | E10: Tebsa | F10: El Rio | G10: 110 | H10: 7.39 | I10: 650 | J10: 794 | K10: 690 | L10: Línea de transmisión | M10: 0.0733 | N10: 0.4367 | O10: 3.833 | P10: 0.3832 | Q10: 1.5675 | R10: 2.092 | S10: STR | T10: Áerea | U10: Sí | W10: 927,2 AAAC | Y10: 26.67 | Z10: 1
A11: =VLOOKUP(E11,'[1]Listas Desplegables'!$H$3:$J$7,2,FALSE()) -> #N/A | B11: =VLOOKUP(E11,'[1]Listas Desplegables'!$H$3:$J$7,3,FALSE()) -> #N/A | C11: 6 | D11: LN707 | E11: Tebsa | F11: La Unión | G11: 110 | H11: 3.56 | I11: 640 | J11: 794 | K11: 690 | L11: Línea de transmisión | M11: 0.0735 | N11: 0.4722 | O11: 3.535 | P11: 0.3961 | Q11: 1.4648 | R11: 2.037 | S11: STR | T11: Áerea | U11: Sí | W11: 927,2 AAAC | Y11: 105.19 | Z11: 1
A12: =VLOOKUP(E12,'[1]Listas Desplegables'!$H$3:$J$7,2,FALSE()) -> #N/A | B12: =VLOOKUP(E12,'[1]Listas Desplegables'!$H$3:$J$7,3,FALSE()) -> #N/A | C12: 7 | D12: LN708 | E12: Tebsa | F12: Veinte de Julio | G12: 110 | H12: 3.22 | I12: 640 | J12: 794 | K12: 690 | L12: Línea de transmisión | M12: 0.0736 | N12: 0.4465 | O12: 3.767 | P12: 0.3984 | Q12: 1.5146 | R12: 2.14 | S12: STR | T12: Áerea | U12: Sí | W12: 927,2 AAAC | Y12: 42.3 | Z12: 1
A13: =VLOOKUP(E13,'[1]Listas Desplegables'!$H$3:$J$7,2,FALSE()) -> #N/A | B13: =VLOOKUP(E13,'[1]Listas Desplegables'!$H$3:$J$7,3,FALSE()) -> #N/A | C13: 8 | D13: LN709 | E13: Caracolí | F13: Silencio | G13: 110 | H13: 12.5 | I13: 691 | J13: 706 | K13: 706 | L13: Línea de transmisión | M13: 0.0736 | N13: 0.4552 | O13: 3.6814 | P13: 0.2417 | Q13: 1.5823 | R13: 2.189 | S13: STR | T13: Áerea | U13: Sí | W13: 927,2 AAAC | Y13: 163.22 | Z13: 1
A14: =VLOOKUP(E14,'[1]Listas Desplegables'!$H$3:$J$7,2,FALSE()) -> #N/A | B14: =VLOOKUP(E14,'[1]Listas Desplegables'!$H$3:$J$7,3,FALSE()) -> #N/A | C14: 9 | D14: LN722 | E14: Oasis | F14: Silencio | G14: 110 | H14: 4.6 | I14: 900 | J14: 900 | K14: 900 | L14: Línea de transmisión | M14: 0.0311 | N14: 0.1281 | O14: 30.159 | P14: 0.261 | Q14: 0.1058 | R14: 0 | S14: STR | T14: Subterránea | U14: Sí | W14: 750 XLPE Cu | Y14: 30.7 | Z14: 1
A15: =VLOOKUP(E15,'[1]Listas Desplegables'!$H$3:$J$7,2,FALSE()) -> #N/A | B15: =VLOOKUP(E15,'[1]Listas Desplegables'!$H$3:$J$7,3,FALSE()) -> #N/A | C15: 10 | D15: LN723 | E15: Oasis | F15: Centro | G15: 110 | H15: 7.87 | I15: 400 | J15: 420 | K15: 520 | L15: Línea de transmisión | M15: 0.0622 | N15: 0.2561 | O15: 60.319 | P15: 0.5219 | Q15: 0.2115 | R15: 0 | S15: STR | T15: Subterránea | U15: Sí | W15: 750 XLPE Cu | Y15: 1480.68 | Z15: 1
A16: =VLOOKUP(E16,'[1]Listas Desplegables'!$H$3:$J$7,2,FALSE()) -> #N/A | B16: =VLOOKUP(E16,'[1]Listas Desplegables'!$H$3:$J$7,3,FALSE()) -> #N/A | C16: 11 | D16: LN724 | E16: Silencio | F16: Centro | G16: 110 | H16: 3.26 | I16: 900 | J16: 900 | K16: 900 | L16: Línea de transmisión | M16: 0.0311 | N16: 0.1281 | O16: 30.159 | P16: 0.261 | Q16: 0.1058 | R16: 0 | S16: STR | T16: Subterránea | U16: Sí | W16: 750 XLPE Cu | Y16: 10.95 | Z16: 1
A17: =VLOOKUP(E17,'[1]Listas Desplegables'!$H$3:$J$7,2,FALSE()) -> #N/A | B17: =VLOOKUP(E17,'[1]Listas Desplegables'!$H$3:$J$7,3,FALSE()) -> #N/A | C17: 12 | D17: LN725 | E17: Las Flores | F17: Termoflores | G17: 110 | H17: 0.6 | I17: 790 | J17: 794 | K17: 790 | L17: Línea de transmisión | M17: 0.062 | N17: 0.4 | O17: 36.454 | P17: 0.278 | Q17: 1.062 | R17: 18.34 | S17: STR | T17: Áerea | U17: Sí | W17: 927,2 AAAC | Y17: 0 | Z17: 0
... A44: =VLOOKUP(E44,'[1]Listas Desplegables'!$H$3:$J$7,2,FALSE()) -> #N/A | B44: =VLOOKUP(E44,'[1]Listas Desplegables'!$H$3:$J$7,3,FALSE()) -> #N/A | C44: 39 | D44: LN521 | E44: Sabanalarga | F44: Arroyo de Piedra | G44: 34.5 | H44: 21 | I44: 300 | J44: 494.5 | K44: 300 | L44: Protecciones | M44: 0.18313 | N44: 0.4286 | O44: 4.00076 | P44: 0.77532 | Q44: 1.90661 | R44: 1.6003 | S44: SDL | T44: Áerea | U44: Sí | W44: 336,4 ACSR | Y44: 136.43972 | Z44: 83
A45: =VLOOKUP(E45,'[1]Listas Desplegables'!$H$3:$J$7,2,FALSE()) -> #N/A | B45: =VLOOKUP(E45,'[1]Listas Desplegables'!$H$3:$J$7,3,FALSE()) -> #N/A | C45: 40 | D45: LN522 | E45: Sabanalarga | F45: Baranoa | G45: 34.5 | H45: 14.7 | I45: 153 | J45: 153 | K45: 168.3 | L45: Línea de transmisión | M45: 0.46032 | N45: 0.46374 | O45: 3.65287 | P45: 0.76289 | Q45: 1.87537 | R45: 0.91322 | S45: SDL | T45: Áerea | U45: Sí | W45: 2 Al | Y45: 0 | Z45: 0 | AC45: Normalmente abierta en ambos extremos
A46: =VLOOKUP(E46,'[1]Listas Desplegables'!$H$3:$J$7,2,FALSE()) -> #N/A | B46: =VLOOKUP(E46,'[1]Listas Desplegables'!$H$3:$J$7,3,FALSE()) -> #N/A | C46: 41 | D46: LN523 | E46: Sabanalarga | F46: Manatí | G46: 34.5 | H46: 25.3 | I46: 577 | J46: 577 | K46: 634.7 | L46: Línea de transmisión | M46: 0.1797 | N46: 0.42062 | O46: 4.11507 | P46: 0.35759 | Q46: 1.81946 | R46: 1.37169 | S46: SDL | T46: Áerea | U46: Sí | W46: 477 ACSR | Y46: 78.996389 | Z46: 66
A47: =VLOOKUP(E47,'[1]Listas Desplegables'!$H$3:$J$7,2,FALSE()) -> #N/A | B47: =VLOOKUP(E47,'[1]Listas Desplegables'!$H$3:$J$7,3,FALSE()) -> #N/A | C47: 42 | D47: LN524 | E47: Sabanalarga | F47: Ponedera | G47: 34.5 | H47: 22.2 | I47: 300 | J47: 330 | K47: 330 | L47: Transformador de corriente | M47: 0.45911 | N47: 0.46247 | O47: 3.05513 | P47: 0.63696 | Q47: 1.86133 | R47: 1.52756 | S47: SDL | T47: Áerea | U47: Sí | W47: 477 ACSR | Y47: 87.488056 | Z47: 78
A48: =VLOOKUP(E48,'[1]Listas Desplegables'!$H$3:$J$7,2,FALSE()) -> #N/A | B48: =VLOOKUP(E48,'[1]Listas Desplegables'!$H$3:$J$7,3,FALSE()) -> #N/A | C48: 43 | D48: LN530 | E48: Unión | F48: Magdalena | G48: 34.5 | H48: 2.5 | I48: 451.83934 | J48: 728 | K48: 497.02328 | L48: Protecciones | M48: 0.0783 | N48: 0.4191 | O48: 2.149 | P48: 0.434 | Q48: 3.128 | R48: 1.551 | S48: SDL | T48: Áerea | U48: Sí | W48: 500 Cu | Y48: 27.571944 | Z48: 15
A49: =VLOOKUP(E49,'[1]Listas Desplegables'!$H$3:$J$7,2,FALSE()) -> #N/A | B49: =VLOOKUP(E49,'[1]Listas Desplegables'!$H$3:$J$7,3,FALSE()) -> #N/A | C49: 44 | D49: LN534 | E49: Las Flores | F49: Riomar | G49: 34.5 | H49: 2 | I49: 579 | J49: 636.9 | K49: 636.9 | L49: Línea de transmisión | M49: 0.1282 | N49: 0.4193 | O49: 2.1 | P49: 0.484 | Q49: 3.128 | R49: 1.68 | S49: SDL | T49: Áerea | U49: Sí | W49: 500 Cu | Y49: 160.94444 | Z49: 36
A50: =VLOOKUP(E50,'[1]Listas Desplegables'!$H$3:$J$7,2,FALSE()) -> #N/A | B50: =VLOOKUP(E50,'[1]Listas Desplegables'!$H$3:$J$7,3,FALSE()) -> #N/A | C50: 45 | D50: LN535 | E50: Las Flores | F50: Riomar | G50: 34.5 | H50: 2 | I50: 579 | J50: 636.9 | K50: 636.9 | L50: Línea de transmisión | M50: 0.1282 | N50: 0.4193 | O50: 2.1 | P50: 0.484 | Q50: 3.128 | R50: 1.68 | S50: SDL | T50: Áerea | U50: Sí | W50: 500 Cu | Y50: 177.00583 | Z50: 53
A51: =VLOOKUP(E51,'[1]Listas Desplegables'!$H$3:$J$7,2,FALSE()) -> #N/A | B51: =VLOOKUP(E51,'[1]Listas Desplegables'!$H$3:$J$7,3,FALSE()) -> #N/A | C51: 46 | D51: LN574 | E51: Las Flores | F51: Puerta de Oro | G51: 34.5 | H51: 13.2 | I51: 426 | J51: 468.6 | K51: 468.6 | L51: Línea de transmisión | M51: 0.117 | N51: 0.3659096 | O51: 4.516404 | P51: 0.2946529 | Q51: 1.524566 | R51: 1.519227 | S51: SDL | T51: Áerea | U51: Sí | W51: 4/0 CU | Y51: 112.0725 | Z51: 41
A52: =VLOOKUP(E52,'[1]Listas Desplegables'!$H$3:$J$7,2,FALSE()) -> #N/A | B52: =VLOOKUP(E52,'[1]Listas Desplegables'!$H$3:$J$7,3,FALSE()) -> #N/A | C52: 47 | D52: LN575 | E52: Malambo | F52: Sabanagrande | G52: 34.5 | H52: 8 | I52: 360 | J52: 577 | K52: 400 | L52: Transformador de corriente | M52: 0.117 | N52: 0.3659096 | O52: 4.516404 | P52: 0.2946529 | Q52: 1.524566 | R52: 1.519227 | S52: SDL | T52: Áerea | U52: Sí | W52: 477 ACSR | Y52: 55.154167 | Z52: 26
A53: =VLOOKUP(E53,'[1]Listas Desplegables'!$H$3:$J$7,2,FALSE()) -> #N/A | B53: =VLOOKUP(E53,'[1]Listas Desplegables'!$H$3:$J$7,3,FALSE()) -> #N/A | C53: 48 | D53: LN5116 | E53: Aracataca | F53: Guacamayal | G53: 34.5 | H53: 20.5 | I53: 300 | J53: 330 | K53: 330 | L53: Transformador de corriente | M53: 0.161 | N53: 0.5006 | O53: 3.30579 | P53: 0.6856 | Q53: 1.351023 | R53: 2.624 | S53: SDL | T53: Áerea | U53: Sí | W53: 4/0 AL | Y53: 57.163056 | Z53: 84
A54: =VLOOKUP(E54,'[1]Listas Desplegables'!$H$3:$J$7,2,FALSE()) -> #N/A | B54: =VLOOKUP(E54,'[1]Listas Desplegables'!$H$3:$J$7,3,FALSE()) -> #N/A | C54: 49 | D54: LN5135 | E54: Manaure | F54: Uribia | G54: 34.5 | H54: 17.8 | I54: 144 | J54: 152 | K54: 152 | L54: Protecciones | M54: 0.2080036 | N54: 0.3943662 | O54: 4.297874 | P54: 0.3678517 | Q54: 1.55367 | R54: 1.567685 | S54: SDL | T54: Áerea | U54: Sí | W54: 559,5 AAAC | Y54: 211.95528 | Z54: 73
A55: =VLOOKUP(E55,'[1]Listas Desplegables'!$H$3:$J$7,2,FALSE()) -> #N/A | B55: =VLOOKUP(E55,'[1]Listas Desplegables'!$H$3:$J$7,3,FALSE()) -> #N/A | C55: 50 | D55: LN5136 | E55: Salamina | F55: Remolino | G55: 34.5 | H55: 26 | I55: 324 | J55: 392 | K55: 342 | L55: Línea de transmisión | M55: 0.165 | N55: 0.3856644 | O55: 4.405156 | P55: 0.3426529 | Q55: 1.524616 | R55: 1.581516 | S55: SDL | T55: Áerea | U55: Sí | W55: 336,4 ACSR | Y55: 51.707222 | Z55: 47
A56: =VLOOKUP(E56,'[1]Listas Desplegables'!$H$3:$J$7,2,FALSE()) -> #N/A | B56: =VLOOKUP(E56,'[1]Listas Desplegables'!$H$3:$J$7,3,FALSE()) -> #N/A | C56: 51 | D56: LN5138 | E56: Santa marta | F56: Bonda | G56: 34.5 | H56: 6 | I56: 427 | J56: 427 | K56: 470 | L56: Línea de transmisión | M56: 0.2308013 | N56: 0.3943556 | O56: 4.297874 | P56: 0.4052405 | Q56: 1.953836 | R56: 1.567685 | S56: SDL | T56: Áerea | U56: Sí | W56: 266,8 ACSR | Y56: 0 | Z56: 0
A57: =VLOOKUP(E57,'[1]Listas Desplegables'!$H$3:$J$7,2,FALSE()) -> #N/A | B57: =VLOOKUP(E57,'[1]Listas Desplegables'!$H$3:$J$7,3,FALSE()) -> #N/A | C57: 52 | D57: LN518 | E57: Fundación | F57: Aracataca | G57: 34.5 | H57: 10.5 | I57: 400 | J57: 434 | K57: 440 | L57: Línea de transmisión | M57: 0.33138 | N57: 0.46189 | O57: 4.63536 | P57: 0.6561 | Q57: 1.5842 | R57: 1.1202 | S57: SDL | T57: Áerea | U57: Sí | W57: 312.8 AAAC | Y57: 11.11 | Z57: 5
... A61: =VLOOKUP(E61,'[1]Listas Desplegables'!$H$3:$J$7,2,FALSE()) -> #N/A | B61: =VLOOKUP(E61,'[1]Listas Desplegables'!$H$3:$J$7,3,FALSE()) -> #N/A | C61: 56 | D61: LN529-1 | E61: Riohacha | F61: Tballenas | G61: 34.5 | H61: 35 | I61: 300 | J61: 454 | K61: 330 | L61: Transformador de corriente | M61: 0.1797 | N61: 0.4206 | O61: 4.1151 | P61: 0.3576 | Q61: 1.8195 | R61: 1.3717 | S61: SDL | T61: Áerea | U61: Sí | W61: 477 ACSR | Y61: 184.69361 | Z61: 85
A62: =VLOOKUP(E62,'[1]Listas Desplegables'!$H$3:$J$7,2,FALSE()) -> #N/A | B62: =VLOOKUP(E62,'[1]Listas Desplegables'!$H$3:$J$7,3,FALSE()) -> #N/A | C62: 57 | D62: LN536 | E62: Río Córdoba | F62: Zawady | G62: 34.5 | H62: 15 | I62: 334 | J62: 334 | K62: 367 | L62: Línea de transmisión | M62: 0.2264 | N62: 0.3964 | O62: 4.2505 | P62: 0.57344 | Q62: 1.79344 | R62: 1.5718 | S62: SDL | T62: Áerea | U62: Sí | W62: 4/0 Al | Y62: 154.82861 | Z62: 262 | AC62: Normalmente abierto en Zawady 34,5 kV
A63: =VLOOKUP(E63,'[1]Listas Desplegables'!$H$3:$J$7,2,FALSE()) -> #N/A | B63: =VLOOKUP(E63,'[1]Listas Desplegables'!$H$3:$J$7,3,FALSE()) -> #N/A | C63: 58 | D63: LN537 | E63: Aeropuerto | F63: Rio Cordoba | G63: 34.5 | H63: 12 | I63: 300 | J63: 300 | K63: 330 | L63: Línea de transmisión | M63: 0.3314102 | N63: 0.4619658 | O63: 3.938248 | P63: 0.6561 | Q63: 1.5842 | R63: 1.1202 | S63: SDL | T63: Áerea | U63: Sí | W63: 4/0 Al | Y63: 138.76028 | Z63: 142 | AC63: Normalmente abierta en Aeropuerto
A64: =VLOOKUP(E64,'[1]Listas Desplegables'!$H$3:$J$7,2,FALSE()) -> #N/A | B64: =VLOOKUP(E64,'[1]Listas Desplegables'!$H$3:$J$7,3,FALSE()) -> #N/A | C64: 59 | D64: LN553 | E64: Plato | F64: Real del Obispo | G64: 34.5 | H64: 29 | I64: 200 | J64: 243 | K64: 220 | L64: Transformador de corriente | M64: 0.33137 | N64: 0.46918 | O64: 1.787573 | P64: 0.31989 | Q64: 1.12663 | R64: 1.9487 | S64: SDL | T64: Áerea | U64: Sí | W64: 2/0 Al | Y64: 104.77556 | Z64: 131
A65: =VLOOKUP(E65,'[1]Listas Desplegables'!$H$3:$J$7,2,FALSE()) -> #N/A | B65: =VLOOKUP(E65,'[1]Listas Desplegables'!$H$3:$J$7,3,FALSE()) -> #N/A | C65: 60 | D65: LN560 | E65: Barrancas | F65: Fonseca | G65: 34.5 | H65: 13 | I65: 163 | J65: 243 | K65: 171 | L65: Transformador de corriente | M65: 0.23058 | N65: 0.42061 | O65: 3.9059 | P65: 0.40845 | Q65: 1.82028 | R65: 1.6716 | S65: SDL | T65: Áerea | U65: Sí | W65: 2/0 ACSR | Y65: 141.77806 | Z65: 109
A66: =VLOOKUP(E66,'[1]Listas Desplegables'!$H$3:$J$7,2,FALSE()) -> #N/A | B66: =VLOOKUP(E66,'[1]Listas Desplegables'!$H$3:$J$7,3,FALSE()) -> #N/A | C66: 61 | D66: LN563-1 | E66: Salamina | F66: Campo Alegre | G66: 34.5 | H66: 12 | I66: 270 | J66: 334 | K66: 285 | L66: Protecciones | M66: 0.63642 | N66: 0.54021 | O66: 3.5863 | P66: 0.81429 | Q66: 1.93906 | R66: 1.5927 | S66: SDL | T66: Áerea | U66: Sí | W66: 4/0 Al | Y66: 73.866667 | Z66: 49
A67: =VLOOKUP(E67,'[1]Listas Desplegables'!$H$3:$J$7,2,FALSE()) -> #N/A | B67: =VLOOKUP(E67,'[1]Listas Desplegables'!$H$3:$J$7,3,FALSE()) -> #N/A | C67: 62 | D67: LN563-2 | E67: Campo Alegre | F67: La Retirada | G67: 34.5 | H67: 6 | I67: 270 | J67: 334 | K67: 285 | L67: Protecciones | M67: 0.63642 | N67: 0.54021 | O67: 3.5863 | P67: 0.81429 | Q67: 1.93906 | R67: 1.5927 | S67: SDL | T67: Áerea | U67: Sí | W67: 4/0 Al | Y67: 73.866667 | Z67: 49
A68: =VLOOKUP(E68,'[1]Listas Desplegables'!$H$3:$J$7,2,FALSE()) -> #N/A | B68: =VLOOKUP(E68,'[1]Listas Desplegables'!$H$3:$J$7,3,FALSE()) -> #N/A | C68: 63 | D68: LN563-3 | E68: La Retirada | F68: Pivijay | G68: 34.5 | H68: 7 | I68: 270 | J68: 334 | K68: 285 | L68: Protecciones | M68: 0.63642 | N68: 0.54021 | O68: 3.5863 | P68: 0.81429 | Q68: 1.93906 | R68: 1.5927 | S68: SDL | T68: Áerea | U68: Sí | W68: 4/0 Al | Y68: 73.866667 | Z68: 49
A69: =VLOOKUP(E69,'[1]Listas Desplegables'!$H$3:$J$7,2,FALSE()) -> #N/A | B69: =VLOOKUP(E69,'[1]Listas Desplegables'!$H$3:$J$7,3,FALSE()) -> #N/A | C69: 64 | D69: LN564 | E69: Cuestecitas | F69: Hatonuevo | G69: 34.5 | H69: 25 | I69: 297 | J69: 427 | K69: 313 | L69: Transformador de corriente | M69: 0.2305 | N69: 0.4125 | O69: 3.8189 | P69: 0.4084 | Q69: 1.8363 | R69: 1.5276 | S69: SDL | T69: Áerea | U69: Sí | W69: 266,8 ACSR | Y69: 120.01111 | Z69: 40
A70: =VLOOKUP(E70,'[1]Listas Desplegables'!$H$3:$J$7,2,FALSE()) -> #N/A | B70: =VLOOKUP(E70,'[1]Listas Desplegables'!$H$3:$J$7,3,FALSE()) -> #N/A | C70: 65 | D70: LN567 | E70: Hatonuevo | F70: Barrancas | G70: 34.5 | H70: 11 | I70: 250 | J70: 320 | K70: 275 | L70: Transformador de corriente | M70: 0.33139 | N70: 0.46192 | O70: 4.1364 | P70: 0.58163 | Q70: 1.93212 | R70: 1.555 | S70: SDL | T70: Áerea | U70: Sí | W70: 4/0 ACSR | Y70: 0 | Z70: 0
A71: =VLOOKUP(E71,'[1]Listas Desplegables'!$H$3:$J$7,2,FALSE()) -> #N/A | B71: =VLOOKUP(E71,'[1]Listas Desplegables'!$H$3:$J$7,3,FALSE()) -> #N/A | C71: 66 | D71: LN578 | E71: Gaira | F71: Aeropuerto | G71: 34.5 | H71: 6.9 | I71: 300 | J71: 334 | K71: 330 | L71: Transformador de corriente | M71: 0.3835 | N71: 0.4393573 | O71: 3.758969 | P71: 1.34225 | Q71: 1.364953 | R71: 1.102645 | S71: SDL | T71: Áerea | U71: Sí | W71: 4/0 ACSR | Y71: 21.779444 | Z71: 12
A72: =VLOOKUP(E72,'[1]Listas Desplegables'!$H$3:$J$7,2,FALSE()) -> #N/A | B72: =VLOOKUP(E72,'[1]Listas Desplegables'!$H$3:$J$7,3,FALSE()) -> #N/A | C72: 67 | D72: LN592 | E72: Riohacha | F72: Camarones | G72: 34.5 | H72: 22 | I72: 100 | J72: 334 | K72: 110 | L72: Transformador de corriente | M72: 0.33137 | N72: 0.46194 | O72: 4.20079 | P72: 0.6561 | Q72: 1.5842 | R72: 1.1202 | S72: SDL | T72: Áerea | U72: Sí | W72: 4/0 ACSR | Y72: 86.529444 | Z72: 48
...

Sheet 2. Tr3
C3: Información General de Transformadores Tridevanados
C4: No. | D4: ='Manual de Uso'!C55 -> Nombre | E4: ='Manual de Uso'!C56 -> Subestación | F4: ='Manual de Uso'!C57 -> Nivel de tensión HV [kV] | G4: ='Manual de Uso'!C58 -> Nivel de tensión MV [kV] | H4: ='Manual de Uso'!C59 -> Nivel de tensión LV [kV] | I4: ='Manual de Uso'!C60 -> Capacidad HV [MVA] | J4: ='Manual de Uso'!C61 -> Capacidad MV [MVA] | K4: ='Manual de Uso'!C62 -> Capacidad LV [MVA] | L4: ='Manual de Uso'!C63 -> Grupo de conexión | M4: ='Manual de Uso'!C64 -> Impedancia HV-MV Secuencia +[%] | N4: ='Manual de Uso'!C65 -> Impedancia HV-LV Secuencia +[%] | O4: ='Manual de Uso'!C66 -> Impedancia MV-LV Secuencia +[%] | P4: ='Manual de Uso'!C67 -> Impedancia HV-MV Secuencia 0[%] | Q4: ='Manual de Uso'!C68 -> Impedancia HV-LV Secuencia 0[%] | R4: ='Manual de Uso'!C69 -> Impedancia MV-LV Secuencia 0[%] | S4: ='Manual de Uso'!C70 -> Posición Neutral Tap | T4: ='Manual de Uso'!C71 -> Posición Máxima Tap | U4: ='Manual de Uso'!C72 -> Posición Mínima Tap | V4: ='Manual de Uso'!C73 -> Delta Tap [%] | W4: ='Manual de Uso'!C74 -> Sobrecarga en emergencia | Y4: ='Manual de Uso'!C75 -> En Operación | Z4: ='Manual de Uso'!C76 -> FPO | AA4: ='Manual de Uso'!C77 -> Sistema | AB4: ='Manual de Uso'!C78 -> Pérdidas Cu HV-MV [kW] | AC4: ='Manual de Uso'!C79 -> Pérdidas Cu HV-LV [kW] | AD4: ='Manual de Uso'!C80 -> Pérdidas Cu MV-LV [kW] | AE4: ='Manual de Uso'!C81 -> Tiempo medio de reparación por evento [h] | AF4: ='Manual de Uso'!C82 -> Horas anuales de indisponibilidad [h] | AG4: ='Manual de Uso'!C83 -> Eventos anuales de indisponibilidad | AH4: ='Manual de Uso'!C84 -> Operador | AI4: ='Manual de Uso'!C85 -> Tipo activo Uso/Conexión | AJ4: ='Manual de Uso'!C86 -> Observaciones transportador
W5: Magnitud [%] | X5: Tiempo [minutos]
A6: =VLOOKUP(E6,'[1]Listas Desplegables'!$H$3:$J$7,2,FALSE()) -> #N/A | B6: =VLOOKUP(E6,'[1]Listas Desplegables'!$H$3:$J$7,3,FALSE()) -> #N/A | C6: 1 | D6: T-BAR01- | E6: BARANOA | F6: 110 | G6: 34.5 | H6: 13.8 | I6: 60 | J6: 35 | K6: 30 | L6: YN0yn0d5 | M6: 12.87 | N6: 21.82 | O6: 9.4 | P6: 12.87 | Q6: 21.82 | R6: 9.4 | S6: 0 | T6: 5 | U6: -15 | V6: 1 | W6: 130 | X6: 30 | Y6: Sí | AA6: SDL | AC6: 127.07 | AF6: 0.26028148 | AG6: 1 | AJ6: TPT a nivel de 13,8 kV de Reactancia de secuencia zero = 3,58 Ohm y Coriente nominal en el neutro = 6,87 kA
A7: =VLOOKUP(E7,'[1]Listas Desplegables'!$H$3:$J$7,2,FALSE()) -> #N/A | B7: =VLOOKUP(E7,'[1]Listas Desplegables'!$H$3:$J$7,3,FALSE()) -> #N/A | C7: 2 | D7: T-MLB01- | E7: MALAMBO | F7: 110 | G7: 34.5 | H7: 13.8 | I7: 60 | J7: 20 | K7: 40 | L7: D0yn11yn11 | M7: 6.633 | N7: 20.3 | O7: 3.05 | P7: 6.633 | Q7: 20.3 | R7: 3.05 | S7: 0 | T7: 5 | U7: -15 | V7: 1 | W7: 130 | X7: 30 | Y7: Sí | AA7: SDL | AB7: 61.9892 | AC7: 213.2222 | AD7: 51.24136
A8: =VLOOKUP(E8,'[1]Listas Desplegables'!$H$3:$J$7,2,FALSE()) -> #N/A | B8: =VLOOKUP(E8,'[1]Listas Desplegables'!$H$3:$J$7,3,FALSE()) -> #N/A | C8: 3 | D8: T-MLB03- | E8: MALAMBO | F8: 110 | G8: 34.5 | H8: 13.8 | I8: 60 | J8: 20 | K8: 40 | L8: D0yn11yn11 | M8: 6.675 | N8: 21.1 | O8: 3.15 | P8: 6.675 | Q8: 21.1 | R8: 3.15 | S8: 0 | T8: 5 | U8: -15 | V8: 1 | W8: 107 | X8: 30 | Y8: Sí | AA8: SDL | AB8: 126.76 | AC8: 1.42 | AD8: 84.19 | AF8: 0.9852 | AG8: 1
A9: =VLOOKUP(E9,'[1]Listas Desplegables'!$H$3:$J$7,2,FALSE()) -> #N/A | B9: =VLOOKUP(E9,'[1]Listas Desplegables'!$H$3:$J$7,3,FALSE()) -> #N/A | C9: 4 | D9: T-RCH01- | E9: RIOHACHA | F9: 110 | G9: 34.5 | H9: 13.8 | I9: 30 | J9: 10 | K9: 25 | L9: YN0yn0d1 | M9: 4.19 | N9: 16.56667 | O9: 2.25 | P9: 4.19 | Q9: 16.56667 | R9: 2.25 | S9: 0 | T9: 5 | U9: -15 | V9: 1 | W9: 130 | X9: 30 | Y9: Sí | AA9: SDL | AB9: 19.19 | AC9: 140.4 | AD9: 16.2 | AF9: 7.5445949 | AG9: 1 | AJ9: TPT a nivel de 13,8 kV de Reactancia de secuencia zero = 2,813 Ohm y Coriente nominal en el neutro = 8,422 kA
A10: =VLOOKUP(E10,'[1]Listas Desplegables'!$H$3:$J$7,2,FALSE()) -> #N/A | B10: =VLOOKUP(E10,'[1]Listas Desplegables'!$H$3:$J$7,3,FALSE()) -> #N/A | C10: 5 | D10: T-RCH02- | E10: RIOHACHA | F10: 110 | G10: 33 | H10: 13.8 | I10: 20 | J10: 10 | K10: 13.3 | L10: YN0yn0d11 | M10: 9.8 | N10: 6.53 | O10: 2.25 | P10: 9.8 | Q10: 6.53 | R10: 2.25 | S10: 0 | T10: 7 | U10: -21 | V10: 0.74 | W10: 130 | X10: 30 | Y10: Sí | AA10: SDL | AB10: 29.1 | AC10: 43.67 | AD10: 28.72 | AF10: 2.8077808 | AG10: 2
A11: =VLOOKUP(E11,'[1]Listas Desplegables'!$H$3:$J$7,2,FALSE()) -> #N/A | B11: =VLOOKUP(E11,'[1]Listas Desplegables'!$H$3:$J$7,3,FALSE()) -> #N/A | C11: 6 | D11: T-RCH03- | E11: RIOHACHA | F11: 110 | G11: 33 | H11: 13.8 | I11: 20 | J11: 10 | K11: 13.3 | L11: YN0yn0d11 | M11: 9.8 | N11: 6.53 | O11: 2.25 | P11: 9.8 | Q11: 6.53 | R11: 2.25 | S11: 0 | T11: 7 | U11: -21 | V11: 0.74 | W11: 130 | X11: 30 | Y11: Sí | AA11: SDL | AB11: 29.1 | AC11: 43.67 | AD11: 28.72
A12: =VLOOKUP(E12,'[1]Listas Desplegables'!$H$3:$J$7,2,FALSE()) -> #N/A | B12: =VLOOKUP(E12,'[1]Listas Desplegables'!$H$3:$J$7,3,FALSE()) -> #N/A | C12: 7 | D12: T-SJU01- | E12: SAN JUAN | F12: 110 | G12: 34.5 | H12: 13.8 | I12: 50 | J12: 35 | K12: 15 | L12: YN0d1yn0 | M12: 12.86 | N12: 5.604 | O12: 13.5086 | P12: 12.86 | Q12: 5.604 | R12: 13.5086 | S12: 0 | T12: 5 | U12: -15 | V12: 1 | W12: 105 | X12: 60 | Y12: Sí | AA12: SDL | AB12: 116 | AJ12: TPT a nivel de 34,5 kV de Reactancia de secuencia zero = 13,67 Ohm y Coriente nominal en el neutro = 4,5 kA
A13: =VLOOKUP(E13,'[1]Listas Desplegables'!$H$3:$J$7,2,FALSE()) -> #N/A | B13: =VLOOKUP(E13,'[1]Listas Desplegables'!$H$3:$J$7,3,FALSE()) -> #N/A | C13: 8 | D13: T-SJU02- | E13: SAN JUAN | F13: 110 | G13: 34.5 | H13: 13.8 | I13: 20 | J13: 14 | K13: 6 | L13: YN0d1yn0 | M13: 13.42 | N13: 5.8114 | O13: 13.73 | P13: 11.78 | Q13: 5.8114 | R13: 11.21 | S13: 0 | T13: 5 | U13: -15 | V13: 1 | W13: 130 | X13: 30 | Y13: Sí | AA13: SDL
A14: =VLOOKUP(E14,'[1]Listas Desplegables'!$H$3:$J$7,2,FALSE()) -> #N/A | B14: =VLOOKUP(E14,'[1]Listas Desplegables'!$H$3:$J$7,3,FALSE()) -> #N/A | C14: 9 | D14: T-FUN02- | E14: FUNDACION | F14: 110 | G14: 34.5 | H14: 13.8 | I14: 42 | J14: 37 | K14: 20 | L14: YN0yn0d11 | M14: 14.37 | N14: 12.32 | O14: 3.36 | P14: 14.37 | Q14: 12.32 | R14: 3.36 | S14: 0 | T14: 12 | U14: -12 | V14: 1.25 | W14: 100 | X14: 0 | Y14: Sí | AA14: SDL | AB14: 147 | AC14: 49.15 | AD14: 55.26 | AJ14: TPT a nivel de 13,8 kV de Reactancia de secuencia zero = 3,43 Ohm y Coriente nominal en el neutro = 5,4 kA
A15: =VLOOKUP(E15,'[1]Listas Desplegables'!$H$3:$J$7,2,FALSE()) -> #N/A | B15: =VLOOKUP(E15,'[1]Listas Desplegables'!$H$3:$J$7,3,FALSE()) -> #N/A | C15: 10 | D15: T-GAI01- | E15: GAIRA | F15: 110 | G15: 34.5 | H15: 13.8 | I15: 60 | J15: 30 | K15: 30 | L15: YN0d11yn0 | M15: 6.31 | N15: 11.94 | O15: 5.15 | P15: 6.31 | Q15: 11.94 | R15: 5.15 | S15: 0 | T15: 10 | U15: -11 | V15: 1 | W15: 130 | X15: 30 | Y15: Sí | AA15: SDL | AB15: 115.68 | AC15: 149.63 | AD15: 143.57 | AJ15: TPT a nivel de 34,5 kV de Reactancia de secuencia zero = 7,28 Ohm y Coriente nominal en el neutro = 4,82 kA
A16: =VLOOKUP(E16,'[1]Listas Desplegables'!$H$3:$J$7,2,FALSE()) -> #N/A | B16: =VLOOKUP(E16,'[1]Listas Desplegables'!$H$3:$J$7,3,FALSE()) -> #N/A | C16: 11 | D16: T-RCO01- | E16: RÍO CÓRDOBA | F16: 110 | G16: 34.5 | H16: 13.8 | I16: 33 | J16: 21 | K16: 15 | L16: YN0d1yn0 | M16: 8.1585 | N16: 10.177 | O16: 3.967 | P16: 8.1585 | Q16: 10.177 | R16: 3.967 | S16: 0 | T16: 5 | U16: -15 | V16: 1 | W16: 130 | X16: 30 | Y16: Sí | AA16: SDL | AB16: 85.4 | AC16: 156.43 | AF16: 3.9401052 | AG16: 7 | AJ16: TPT a nivel de 34,5 kV de Reactancia de secuencia zero = 8,44 Ohm y Coriente nominal en el neutro = 6,3 kA
A17: =VLOOKUP(E17,'[1]Listas Desplegables'!$H$3:$J$7,2,FALSE()) -> #N/A | B17: =VLOOKUP(E17,'[1]Listas Desplegables'!$H$3:$J$7,3,FALSE()) -> #N/A | C17: 12 | D17: T-SAL01- | E17: SALAMINA | F17: 110 | G17: 34.5 | H17: 13.8 | I17: 30 | J17: 20 | K17: 10 | L17: YN0yn0d1 | M17: 6.72 | N17: 6.78 | O17: 1.82667 | P17: 6.72 | Q17: 6.78 | R17: 1.82667 | S17: 0 | T17: 10 | U17: -10 | V17: 1 | W17: 130 | X17: 30 | Y17: Sí | AA17: SDL | AB17: 88.5 | AC17: 37.37 | AD17: 33.74 | AF17: 0.99003444 | AG17: 1 | AJ17: TPT a nivel de 13,8 kV de Reactancia de secuencia zero = 3,99 Ohm y Coriente nominal en el neutro = 3,64 kA
A18: =VLOOKUP(E18,'[1]Listas Desplegables'!$H$3:$J$7,2,FALSE()) -> #N/A | B18: =VLOOKUP(E18,'[1]Listas Desplegables'!$H$3:$J$7,3,FALSE()) -> #N/A | C18: 13 | D18: T-JMN01- | E18: JUAN MINA | F18: 110 | G18: 34.5 | H18: 13.8 | I18: 50 | J18: 30 | K18: 20 | L18: D0yn11yn11 | M18: 11.29 | N18: 12.5 | O18: 3.65 | P18: 11.29 | Q18: 12.5 | R18: 3.65 | S18: 0 | T18: 5 | U18: -15 | V18: 1 | W18: 100 | X18: 0 | Y18: Sí | AA18: SDL
A19: =VLOOKUP(E19,'[1]Listas Desplegables'!$H$3:$J$7,2,FALSE()) -> #N/A | B19: =VLOOKUP(E19,'[1]Listas Desplegables'!$H$3:$J$7,3,FALSE()) -> #N/A | C19: 14 | D19: T-CIE01 | E19: CIENAGA | F19: 110 | G19: 13.8 | H19: 6.9 | I19: 50 | J19: 50 | K19: 12.5 | L19: YN0yn0d1 | M19: 12.92 | N19: 6.1 | O19: 2.25 | P19: 12.59 | Q19: 5.19 | R19: 1.91 | S19: 0 | T19: 10 | U19: -10 | V19: 1 | W19: 105 | X19: 60 | Y19: Sí | AA19: SDL | AF19: 1.2341275 | AG19: 1 | AJ19: Devanado terciario de compensación / Desacoplado del T-CIE02
A20: =VLOOKUP(E20,'[1]Listas Desplegables'!$H$3:$J$7,2,FALSE()) -> #N/A | B20: =VLOOKUP(E20,'[1]Listas Desplegables'!$H$3:$J$7,3,FALSE()) -> #N/A | C20: 15 | D20: T-CIE02 | E20: CIENAGA | F20: 110 | G20: 13.8 | H20: 6.9 | I20: 50 | J20: 50 | K20: 12.5 | L20: YN0yn0d1 | M20: 12.8 | N20: 6.1 | O20: 2.25 | P20: 12.47 | Q20: 5.19 | R20: 1.91 | S20: 0 | T20: 10 | U20: -10 | V20: 1 | W20: 105 | X20: 60 | Y20: Sí | AA20: SDL | AJ20: Devanado terciario de compensación / Desacoplado del T-CIE01
A21: =VLOOKUP(E21,'[1]Listas Desplegables'!$H$3:$J$7,2,FALSE()) -> #N/A | B21: =VLOOKUP(E21,'[1]Listas Desplegables'!$H$3:$J$7,3,FALSE()) -> #N/A | C21: 16 | D21: T-ERI03 | E21: EL RÍO | F21: 34.5 | G21: 13.8 | H21: 7.967 | I21: 28 | J21: 28 | K21: 4 | L21: YN0yn0d5 | M21: 7.69 | N21: 1.603065 | O21: 0.389885 | P21: 7.69 | Q21: 1.603065 | R21: 0.389885 | S21: 0 | T21: 16 | U21: -16 | V21: 0.5 | W21: 110 | X21: 30 | Y21: Sí | AA21: SDL | AB21: 260 | AJ21: Devanado terciario de compensación / Desacoplado del T-ERI01 y T-ERI02
A22: =VLOOKUP(E22,'[1]Listas Desplegables'!$H$3:$J$7,2,FALSE()) -> #N/A | B22: =VLOOKUP(E22,'[1]Listas Desplegables'!$H$3:$J$7,3,FALSE()) -> #N/A | C22: 17 | D22: T-FLS04 | E22: LAS FLORES | F22: 34.5 | G22: 13.8 | H22: 6.9 | I22: 39.15 | J22: 39.15 | K22: 4 | L22: YN0yn0d1 | M22: 10.7 | N22: 1.510204 | O22: 0.3673469 | P22: 10.7 | Q22: 1.510204 | R22: 0.3673469 | S22: 0 | T22: 16 | U22: -16 | V22: 0.625 | W22: 110 | X22: 30 | Y22: Sí | AA22: SDL | AB22: 227.9 | AJ22: Devanado terciario de compensación
A23: =VLOOKUP(E23,'[1]Listas Desplegables'!$H$3:$J$7,2,FALSE()) -> #N/A | B23: =VLOOKUP(E23,'[1]Listas Desplegables'!$H$3:$J$7,3,FALSE()) -> #N/A | C23: 18 | D23: T-RIM02 | E23: NUEVA RIOMAR | F23: 34.5 | G23: 13.8 | H23: 6.9 | I23: 39.15 | J23: 39.15 | K23: 3 | L23: YN0yn0d1 | M23: 11.16 | N23: 1.084535 | O23: 0.2637436 | P23: 11.16 | Q23: 1.084535 | R23: 0.2637436 | S23: 0 | T23: 16 | U23: -16 | V23: 0.625 | W23: 110 | X23: 30 | Y23: Sí | AA23: SDL | AB23: 140 | AJ23: Devanado terciario de compensación
A24: =VLOOKUP(E24,'[1]Listas Desplegables'!$H$3:$J$7,2,FALSE()) -> #N/A | B24: =VLOOKUP(E24,'[1]Listas Desplegables'!$H$3:$J$7,3,FALSE()) -> #N/A | C24: 19 | D24: T-RIM03 | E24: NUEVA RIOMAR | F24: 34.5 | G24: 13.8 | H24: 6.9 | I24: 39.1 | J24: 39.1 | K24: 4 | L24: YN0yn0d1 | M24: 11.16 | N24: 1.621483 | O24: 0.3944757 | P24: 11.16 | Q24: 1.621483 | R24: 0.3944757 | S24: 0 | T24: 16 | U24: -16 | V24: 0.625 | W24: 110 | X24: 30 | Y24: Sí | AA24: SDL | AB24: 212.92 | AJ24: Devanado terciario de compensación
A25: =VLOOKUP(E25,'[1]Listas Desplegables'!$H$3:$J$7,2,FALSE()) -> #N/A | B25: =VLOOKUP(E25,'[1]Listas Desplegables'!$H$3:$J$7,3,FALSE()) -> #N/A | C25: 20 | D25: T-MGD01 | E25: RIO MAGDALENA | F25: 34.5 | G25: 13.8 | H25: 6.9 | I25: 39.15 | J25: 39.15 | K25: 4 | L25: YN0yn0d1 | M25: 10.397 | N25: 1.572107 | O25: 0.3824266 | P25: 10.397 | Q25: 1.572107 | R25: 0.3824266 | S25: 0 | T25: 16 | U25: -16 | V25: 0.625 | W25: 110 | X25: 30 | Y25: Sí | AA25: SDL | AB25: 219.4 | AF25: 1.1824976 | AG25: 1 | AJ25: Devanado terciario de compensación
A26: =VLOOKUP(E26,'[1]Listas Desplegables'!$H$3:$J$7,2,FALSE()) -> #N/A | B26: =VLOOKUP(E26,'[1]Listas Desplegables'!$H$3:$J$7,3,FALSE()) -> #N/A | C26: 21 | D26: T-SIL02 | E26: SILENCIO | F26: 34.5 | G26: 13.8 | H26: 6.9 | I26: 33 | J26: 33 | K26: 3 | L26: YN0yn0d1 | M26: 6 | N26: 1.048182 | O26: 2.8 | P26: 6 | Q26: 1.048182 | R26: 2.8 | S26: 0 | T26: 16 | U26: -16 | V26: 0.625 | W26: 110 | X26: 30 | Y26: Sí | AA26: SDL | AB26: 141.57 | AJ26: Devanado terciario de compensación / Desacoplado del T-SIL01 y T-SIL03
A27: =VLOOKUP(E27,'[1]Listas Desplegables'!$H$3:$J$7,2,FALSE()) -> #N/A | B27: =VLOOKUP(E27,'[1]Listas Desplegables'!$H$3:$J$7,3,FALSE()) -> #N/A | C27: 22 | D27: T-SIL03 | E27: SILENCIO | F27: 34.5 | G27: 13.8 | H27: 6.9 | I27: 39.15 | J27: 39.15 | K27: 4 | L27: YN0yn0d1 | M27: 10.6 | N27: 1.597547 | O27: 3.8 | P27: 10.6 | Q27: 1.597547 | R27: 3.8 | S27: 0 | T27: 16 | U27: -16 | V27: 0.625 | W27: 110 | X27: 30 | Y27: Sí | AA27: SDL | AB27: 253.7 | AF27: 0.33138333 | AG27: 1 | AJ27: Devanado terciario de compensación / Desacoplado del T-SIL02 y T-SIL01
A28: =VLOOKUP(E28,'[1]Listas Desplegables'!$H$3:$J$7,2,FALSE()) -> #N/A | B28: =VLOOKUP(E28,'[1]Listas Desplegables'!$H$3:$J$7,3,FALSE()) -> #N/A | C28: 23 | D28: UNIÓN 01 | E28: UNIÓN | F28: 110 | G28: 13.8 | H28: 6.9 | I28: 50 | J28: 50 | K28: 12.5 | L28: YN0yn0d11 | M28: 20.05 | N28: 7.93 | O28: 2.02 | P28: 19.13 | Q28: 7.33 | R28: 1.9 | S28: 0 | T28: 5 | U28: -15 | V28: 1 | W28: 100 | X28: 0 | Y28: Sí | AA28: SDL | AE28: 0 | AF28: 0 | AG28: 0 | AJ28: Devanado terciario de compensación / Desacoplado del UNIÓN 02 y UNIÓN 03
A29: =VLOOKUP(E29,'[1]Listas Desplegables'!$H$3:$J$7,2,FALSE()) -> #N/A | B29: =VLOOKUP(E29,'[1]Listas Desplegables'!$H$3:$J$7,3,FALSE()) -> #N/A | C29: 24 | D29: UNIÓN 02 | E29: UNIÓN | F29: 110 | G29: 13.8 | H29: 6.9 | I29: 50 | J29: 50 | K29: 12.5 | L29: YN0yn0d11 | M29: 19.73 | N29: 7.93 | O29: 2.02 | P29: 18.83 | Q29: 7.31 | R29: 1.9 | S29: 0 | T29: 5 | U29: -15 | V29: 1 | W29: 100 | X29: 0 | Y29: Sí | AA29: SDL | AE29: 0 | AF29: 0 | AG29: 0 | AJ29: Devanado terciario de compensación / Desacoplado del UNIÓN 01 y UNIÓN 03
A30: =VLOOKUP(E30,'[1]Listas Desplegables'!$H$3:$J$7,2,FALSE()) -> #N/A | B30: =VLOOKUP(E30,'[1]Listas Desplegables'!$H$3:$J$7,3,FALSE()) -> #N/A | C30: 25 | D30: UNIÓN 03 | E30: UNIÓN | F30: 110 | G30: 13.8 | H30: 6.9 | I30: 50 | J30: 50 | K30: 12.5 | L30: YN0yn0d11 | M30: 20.13 | N30: 7.93 | O30: 2.02 | P30: 19.24 | Q30: 7.35 | R30: 1.82 | S30: 0 | T30: 5 | U30: -15 | V30: 1 | W30: 100 | X30: 0 | Y30: Sí | AA30: SDL | AE30: 0 | AF30: 0 | AG30: 0 | AJ30: Devanado terciario de compensación / Desacoplado del UNIÓN 01 y UNIÓN 02
A31: =VLOOKUP(E31,'[1]Listas Desplegables'!$H$3:$J$7,2,FALSE()) -> #N/A | B31: =VLOOKUP(E31,'[1]Listas Desplegables'!$H$3:$J$7,3,FALSE()) -> #N/A | C31: 26 | D31: T- ESTRATEGICO CDL 01 | E31: CORDIALIDAD | F31: 110 | G31: 34.5 | H31: 13.8 | I31: 60 | J31: 60 | K31: 60 | L31: YN0d11yn0 | M31: 12.58 | N31: 24.24 | O31: 9.36 | P31: 12.58 | Q31: 24.24 | R31: 9.36 | S31: 0 | T31: 10 | U31: -10 | V31: 1 | W31: 100 | X31: 0 | Y31: Sí | AA31: SDL | AB31: 274.54 | AC31: 317.74 | AD31: 272.06
A32: =VLOOKUP(E32,'[1]Listas Desplegables'!$H$3:$J$7,2,FALSE()) -> #N/A | B32: =VLOOKUP(E32,'[1]Listas Desplegables'!$H$3:$J$7,3,FALSE()) -> #N/A | C32: 27 | D32: RÍO CORDOBA 02 | E32: RÍO CÓRDOBA | F32: 110 | G32: 34.5 | H32: 13.8 | I32: 50 | J32: 30 | K32: 20 | L32: YN0d11yn0 | M32: 11.29 | N32: 12.5 | O32: 3.65 | P32: 11.29 | Q32: 12.5 | R32: 3.65 | S32: 0 | T32: 5 | U32: -15 | V32: 1 | W32: 100 | X32: 0 | Y32: No | Z32: 2029 | AA32: SDL | AJ32: Segundo transformador NA a nivel de 13,8 kV y el T-RCO01- NA a nivel de 34,5 kV y se cierran los interruptores de la línea 537 TPT a nivel de 34,5 kV de I= 0,48 kA, X = 3,64 Ohm
A33: =VLOOKUP(E33,'[1]Listas Desplegables'!$H$3:$J$7,2,FALSE()) -> #N/A | B33: =VLOOKUP(E33,'[1]Listas Desplegables'!$H$3:$J$7,3,FALSE()) -> #N/A | C33: 28 | D33: GAIRA 02 | E33: GAIRA | F33: 110 | G33: 34.5 | H33: 13.8 | I33: 60 | J33: 30 | K33: 30 | L33: YN0d11yn0 | M33: 6.31 | N33: 11.94 | O33: 5.15 | P33: 6.31 | Q33: 11.94 | R33: 5.15 | S33: 0 | T33: 10 | U33: -11 | V33: 1.01 | W33: 100 | X33: 0 | Y33: No | Z33: 2029 | AA33: SDL | AB33: 115.68 | AC33: 149.63 | AD33: 143.57 | AE33: 0 | AF33: 0 | AG33: 0 | AJ33: Segundo transformador TPT a nivel de 34,5 kV de Reactancia de secuencia zero = 7,28 Ohm y Coriente nominal en el neutro = 4,82 kA
A34: =VLOOKUP(E34,'[1]Listas Desplegables'!$H$3:$J$7,2,FALSE()) -> #N/A | B34: =VLOOKUP(E34,'[1]Listas Desplegables'!$H$3:$J$7,3,FALSE()) -> #N/A | C34: 29 | D34: TEBSA 2 100 MVA | E34: TEBSA | F34: 220 | G34: 110 | H34: 13.8 | I34: 100 | J34: 100 | K34: 20 | L34: YNa0d1 | M34: 11 | N34: 4.95 | O34: 2.57 | P34: 11 | Q34: 4.95 | R34: 2.57 | S34: 9 | T34: 29 | U34: 1 | V34: 1.01 | W34: 110 | X34: 30 | Y34: Sí | AA34: STN | AB34: 100 | AC34: 100 | AD34: 100
A35: =VLOOKUP(E35,'[1]Listas Desplegables'!$H$3:$J$7,2,FALSE()) -> #N/A | B35: =VLOOKUP(E35,'[1]Listas Desplegables'!$H$3:$J$7,3,FALSE()) -> #N/A | C35: 30 | D35: TEBSA 5 100 MVA | E35: TEBSA | F35: 220 | G35: 110 | H35: 13.8 | I35: 100 | J35: 100 | K35: 20 | L35: YNa0d1 | M35: 10.45 | N35: 4.95 | O35: 2.57 | P35: 10.45 | Q35: 4.95 | R35: 2.57 | S35: 9 | T35: 29 | U35: 1 | V35: 1.01 | W35: 110 | X35: 30 | Y35: Sí | AA35: STN | AB35: 100 | AC35: 100 | AD35: 100
A36: =VLOOKUP(E36,'[1]Listas Desplegables'!$H$3:$J$7,2,FALSE()) -> #N/A | B36: =VLOOKUP(E36,'[1]Listas Desplegables'!$H$3:$J$7,3,FALSE()) -> #N/A | C36: 31 | D36: T01- NUEVA SAN JUAN | E36: NUEVA SAN JUAN | F36: 220 | G36: 110 | H36: 13.8 | I36: 150 | J36: 150 | K36: 51 | L36: YNYND1 | M36: 12.74 | N36: 14.13 | O36: 8.92 | P36: 12.74 | Q36: 14.13 | R36: 8.92 | S36: 0 | T36: 12 | U36: -8 | V36: 1 | W36: 100 | X36: 0 | Y36: No | Z36: 2029 | AA36: STN
A37: =VLOOKUP(E37,'[1]Listas Desplegables'!$H$3:$J$7,2,FALSE()) -> #N/A | B37: =VLOOKUP(E37,'[1]Listas Desplegables'!$H$3:$J$7,3,FALSE()) -> #N/A | C37: 32 | D37: T1 Nueva El Río | E37: EL RÍO | F37: 220 | G37: 110 | H37: 13.8 | I37: 150 | J37: 150 | K37: 51 | L37: YNYND1 | M37: 12.74 | N37: 14.13 | O37: 8.92 | P37: 12.74 | Q37: 14.13 | R37: 8.92 | S37: 0 | T37: 12 | U37: -8 | V37: 1 | W37: 100 | X37: 0 | Y37: No | Z37: 2029 | AA37: STN
A38: =VLOOKUP(E38,'[1]Listas Desplegables'!$H$3:$J$7,2,FALSE()) -> #N/A | B38: =VLOOKUP(E38,'[1]Listas Desplegables'!$H$3:$J$7,3,FALSE()) -> #N/A | C38: 33 | D38: T2 Nueva El Río | E38: EL RÍO | F38: 220 | G38: 110 | H38: 13.8 | I38: 150 | J38: 150 | K38: 51 | L38: YNYND1 | M38: 12.74 | N38: 14.13 | O38: 8.92 | P38: 12.74 | Q38: 14.13 | R38: 8.92 | S38: 0 | T38: 12 | U38: -8 | V38: 1 | W38: 100 | X38: 0 | Y38: No | Z38: 2029 | AA38: STN
A39: =VLOOKUP(E39,'[1]Listas Desplegables'!$H$3:$J$7,2,FALSE()) -> #N/A | B39: =VLOOKUP(E39,'[1]Listas Desplegables'!$H$3:$J$7,3,FALSE()) -> #N/A | C39: 34 | D39: TEBSA 1 100 MVA | E39: TEBSA | F39: 220 | G39: 110 | H39: 13.8 | I39: 100 | J39: 100 | K39: 20 | L39: YNa0d1 | M39: 12.66 | N39: 4.03 | O39: 1.03 | P39: 12.66 | Q39: 4.03 | R39: 1.03 | S39: 9 | T39: 29 | U39: 1 | V39: 1.09 | W39: 110 | X39: 30 | Y39: Sí | AA39: STN | AB39: 100 | AC39: 100 | AD39: 100
A40: =VLOOKUP(E40,'[1]Listas Desplegables'!$H$3:$J$7,2,FALSE()) -> #N/A | B40: =VLOOKUP(E40,'[1]Listas Desplegables'!$H$3:$J$7,3,FALSE()) -> #N/A | C40: 35 | D40: T03 Cuestecitas | E40: CUESTECITAS | F40: 110 | G40: 34.5 | H40: 13.8 | I40: 50 | J40: 50 | K40: 1 | L40: YN0yn0d1 | M40: 37 | N40: 10.6 | O40: 23.7 | P40: 33.4 | Q40: 10.3 | R40: 22 | S40: 0 | T40: 10 | U40: -10 | V40: 1 | W40: 110 | X40: 30 | Y40: Sí | AA40: STR | AB40: 37 | AC40: 10.6 | AD40: 23.7 | AJ40: Se límita límita la capacidad del transformador a 25MVA
A41: =VLOOKUP(E41,'[1]Listas Desplegables'!$H$3:$J$7,2,FALSE()) -> #N/A | B41: =VLOOKUP(E41,'[1]Listas Desplegables'!$H$3:$J$7,3,FALSE()) -> #N/A | C41: 36
A42: =VLOOKUP(E42,'[1]Listas Desplegables'!$H$3:$J$7,2,FALSE()) -> #N/A | B42: =VLOOKUP(E42,'[1]Listas Desplegables'!$H$3:$J$7,3,FALSE()) -> #N/A | C42: 37
...

Sheet 3. Tr2
C3: Información General de Transformadores Bidevanados
C4: No. | D4: ='Manual de Uso'!C87 -> Nombre | E4: ='Manual de Uso'!C88 -> Subestación | F4: ='Manual de Uso'!C89 -> Nivel de tensión HV [kV] | G4: ='Manual de Uso'!C90 -> Nivel de tensión LV [kV] | H4: ='Manual de Uso'!C91 -> Capacidad [MVA] | I4: ='Manual de Uso'!C92 -> Grupo de conexión | J4: ='Manual de Uso'!C93 -> Impedancia Secuencia +[%] | K4: ='Manual de Uso'!C94 -> Impedancia Secuencia 0[%] | L4: ='Manual de Uso'!C95 -> Posición Neutral Tap | M4: ='Manual de Uso'!C96 -> Posición Máxima Tap | N4: ='Manual de Uso'!C97 -> Posición Mínima Tap | O4: ='Manual de Uso'!C98 -> Delta Tap [%] | P4: ='Manual de Uso'!C99 -> Sobrecarga en emergencia | R4: ='Manual de Uso'!C100 -> En Operación | S4: ='Manual de Uso'!C101 -> FPO | T4: ='Manual de Uso'!C102 -> Sistema | U4: ='Manual de Uso'!C103 -> Pérdidas Cu [kW] | V4: ='Manual de Uso'!C104 -> Tiempo medio de reparación por evento [h] | W4: ='Manual de Uso'!C105 -> Horas anuales de indisponibilidad [h] | X4: ='Manual de Uso'!C106 -> Eventos anuales de indisponibilidad | Y4: ='Manual de Uso'!C107 -> Operador | Z4: ='Manual de Uso'!C108 -> Tipo activo Uso/Conexión | AA4: ='Manual de Uso'!C109 -> Observaciones transportador
P5: Magnitud [%] | Q5: Tiempo [minutos]
A6: =VLOOKUP(E6,'[1]Listas Desplegables'!$H$3:$J$7,2,FALSE()) -> #N/A | B6: =VLOOKUP(E6,'[1]Listas Desplegables'!$H$3:$J$7,3,FALSE()) -> #N/A | C6: 1 | D6: T-AOR01 | E6: AEROPUERTO | F6: 34.5 | G6: 13.8 | H6: 15 | I6: Dyn1 | J6: 9.12 | K6: 9.12 | L6: 0 | M6: 10 | N6: -10 | O6: 1 | P6: 115 | Q6: 30 | R6: Sí | T6: SDL | U6: 66.431 | W6: 0 | X6: 0
A7: =VLOOKUP(E7,'[1]Listas Desplegables'!$H$3:$J$7,2,FALSE()) -> #N/A | B7: =VLOOKUP(E7,'[1]Listas Desplegables'!$H$3:$J$7,3,FALSE()) -> #N/A | C7: 2 | D7: T-PROV AOR | E7: AEROPUERTO | F7: 34.5 | G7: 13.8 | H7: 12.5 | I7: Dyn1 | J7: 8.8125 | K7: 8.8125 | L7: 0 | M7: 16 | N7: -16 | O7: 0.625 | P7: 100 | Q7: 0 | R7: Sí | T7: SDL | U7: 71.192
A8: =VLOOKUP(E8,'[1]Listas Desplegables'!$H$3:$J$7,2,FALSE()) -> #N/A | B8: =VLOOKUP(E8,'[1]Listas Desplegables'!$H$3:$J$7,3,FALSE()) -> #N/A | C8: 3 | D8: T-ARA01 | E8: ARACATACA | F8: 34.5 | G8: 13.8 | H8: 12.5 | I8: Dyn5 | J8: 9.1 | K8: 9.1 | L8: 0 | M8: 2 | N8: -2 | O8: 2.5 | P8: 110 | Q8: 30 | R8: Sí | T8: SDL | U8: 80 | W8: 0.0038833333 | X8: 2
A9: =VLOOKUP(E9,'[1]Listas Desplegables'!$H$3:$J$7,2,FALSE()) -> #N/A | B9: =VLOOKUP(E9,'[1]Listas Desplegables'!$H$3:$J$7,3,FALSE()) -> #N/A | C9: 4 | D9: T-APA01 | E9: ARROYO DE PIEDRA | F9: 34.5 | G9: 13.8 | H9: 12.5 | I9: Dyn5 | J9: 5.264 | K9: 5.264 | L9: 0 | M9: 8 | N9: -8 | O9: 1.25 | P9: 110 | Q9: 30 | R9: Sí | T9: SDL | U9: 24 | W9: 0.28092778 | X9: 3
A10: =VLOOKUP(E10,'[1]Listas Desplegables'!$H$3:$J$7,2,FALSE()) -> #N/A | B10: =VLOOKUP(E10,'[1]Listas Desplegables'!$H$3:$J$7,3,FALSE()) -> #N/A | C10: 5 | D10: T-BNA01 | E10: BALLENAS | F10: 34.5 | G10: 13.8 | H10: 1 | I10: Dyn11 | J10: 4.89 | K10: 4.89 | L10: 0 | M10: 2 | N10: -2 | O10: 2.5 | P10: 105 | Q10: 30 | R10: Sí | T10: SDL | U10: 12 | W10: 2.5108333 | X10: 2
A11: =VLOOKUP(E11,'[1]Listas Desplegables'!$H$3:$J$7,2,FALSE()) -> #N/A | B11: =VLOOKUP(E11,'[1]Listas Desplegables'!$H$3:$J$7,3,FALSE()) -> #N/A | C11: 6 | D11: T-BRC01 | E11: BARRANCAS | F11: 34.5 | G11: 13.8 | H11: 8 | I11: Dyn11 | J11: 6.56 | K11: 6.56 | L11: 0 | M11: 4 | N11: -4 | O11: 2.5 | P11: 110 | Q11: 30 | R11: Sí | T11: SDL | U11: 28 | W11: 0 | X11: 0 | AA11: Desacoplado del T02
A12: =VLOOKUP(E12,'[1]Listas Desplegables'!$H$3:$J$7,2,FALSE()) -> #N/A | B12: =VLOOKUP(E12,'[1]Listas Desplegables'!$H$3:$J$7,3,FALSE()) -> #N/A | C12: 7 | D12: T-BRC02 | E12: BARRANCAS | F12: 34.5 | G12: 13.8 | H12: 4 | I12: Dyn5 | J12: 5.62 | K12: 5.62 | L12: 0 | M12: 2 | N12: -2 | O12: 2.5 | P12: 110 | Q12: 30 | R12: Sí | T12: SDL | W12: 0 | X12: 0 | AA12: Desacoplado del T01
A13: =VLOOKUP(E13,'[1]Listas Desplegables'!$H$3:$J$7,2,FALSE()) -> #N/A | B13: =VLOOKUP(E13,'[1]Listas Desplegables'!$H$3:$J$7,3,FALSE()) -> #N/A | C13: 8 | D13: T-BON01 | E13: BONDA | F13: 34.5 | G13: 13.8 | H13: 12.5 | I13: Dyn1 | J13: 8.8125 | K13: 8.8125 | L13: 0 | M13: 16 | N13: -16 | O13: 0.625 | P13: 115 | Q13: 30 | R13: Sí | T13: SDL | U13: 71.192 | W13: 22.541942 | X13: 2
A14: =VLOOKUP(E14,'[1]Listas Desplegables'!$H$3:$J$7,2,FALSE()) -> #N/A | B14: =VLOOKUP(E14,'[1]Listas Desplegables'!$H$3:$J$7,3,FALSE()) -> #N/A | C14: 9 | D14: T-BON02 | E14: BONDA | F14: 34.5 | G14: 13.8 | H14: 12.5 | I14: Dyn1 | J14: 7.07 | K14: 7.07 | L14: 0 | M14: 16 | N14: -16 | O14: 0.625 | P14: 115 | Q14: 30 | R14: Sí | T14: SDL | U14: 81
A15: =VLOOKUP(E15,'[1]Listas Desplegables'!$H$3:$J$7,2,FALSE()) -> #N/A | B15: =VLOOKUP(E15,'[1]Listas Desplegables'!$H$3:$J$7,3,FALSE()) -> #N/A | C15: 10 | D15: T-CES01 | E15: CAMARONES | F15: 34.5 | G15: 13.8 | H15: 4 | I15: Dyn5 | J15: 7.91 | K15: 7.91 | L15: 0 | M15: 2 | N15: -2 | O15: 2.5 | P15: 115 | Q15: 30 | R15: Sí | T15: SDL | W15: 0.14680833 | X15: 2
A16: =VLOOKUP(E16,'[1]Listas Desplegables'!$H$3:$J$7,2,FALSE()) -> #N/A | B16: =VLOOKUP(E16,'[1]Listas Desplegables'!$H$3:$J$7,3,FALSE()) -> #N/A | C16: 11 | D16: T-CAE01 | E16: CAMPO ALEGRE | F16: 34.5 | G16: 13.8 | H16: 10 | I16: Dyn1 | J16: 7.55 | K16: 7.55 | L16: 0 | M16: 2 | N16: -2 | O16: 2.5 | P16: 105 | Q16: 30 | R16: Sí | T16: SDL | U16: 44.8 | W16: 0 | X16: 1
A17: =VLOOKUP(E17,'[1]Listas Desplegables'!$H$3:$J$7,2,FALSE()) -> #N/A | B17: =VLOOKUP(E17,'[1]Listas Desplegables'!$H$3:$J$7,3,FALSE()) -> #N/A | C17: 12 | D17: T-CAR01 | E17: CARACOLÍ | F17: 110 | G17: 13.8 | H17: 30 | I17: Dyn11 | J17: 12.96 | K17: 12.89 | L17: 0 | M17: 5 | N17: -15 | O17: 1 | P17: 110 | Q17: 30 | R17: Sí | T17: SDL | W17: 0 | X17: 0
A18: =VLOOKUP(E18,'[1]Listas Desplegables'!$H$3:$J$7,2,FALSE()) -> #N/A | B18: =VLOOKUP(E18,'[1]Listas Desplegables'!$H$3:$J$7,3,FALSE()) -> #N/A | C18: 13 | D18: T-CAR02 | E18: CARACOLÍ | F18: 110 | G18: 13.8 | H18: 30 | I18: Dyn11 | J18: 12.99 | K18: 12.89 | L18: 0 | M18: 5 | N18: -15 | O18: 1 | P18: 110 | Q18: 30 | R18: Sí | T18: SDL | W18: 0 | X18: 0
A19: =VLOOKUP(E19,'[1]Listas Desplegables'!$H$3:$J$7,2,FALSE()) -> #N/A | B19: =VLOOKUP(E19,'[1]Listas Desplegables'!$H$3:$J$7,3,FALSE()) -> #N/A | C19: 14 | D19: T-CTR01 | E19: CENTRO | F19: 110 | G19: 13.8 | H19: 50 | I19: Dyn11 | J19: 19.1 | K19: 19.1 | L19: 0 | M19: 5 | N19: -15 | O19: 1 | P19: 130 | Q19: 30 | R19: Sí | T19: SDL | U19: 188.7 | W19: 0 | X19: 0 | AA19: Acoplado al T-CTR02
A20: =VLOOKUP(E20,'[1]Listas Desplegables'!$H$3:$J$7,2,FALSE()) -> #N/A | B20: =VLOOKUP(E20,'[1]Listas Desplegables'!$H$3:$J$7,3,FALSE()) -> #N/A | C20: 15 | D20: T-CTR02 | E20: CENTRO | F20: 110 | G20: 13.8 | H20: 50 | I20: Dyn11 | J20: 19.1 | K20: 19.1 | L20: 0 | M20: 5 | N20: -15 | O20: 1 | P20: 130 | Q20: 30 | R20: Sí | T20: SDL | U20: 188.7 | W20: 0 | X20: 0 | AA20: Acoplado al T-CTR01
A21: =VLOOKUP(E21,'[1]Listas Desplegables'!$H$3:$J$7,2,FALSE()) -> #N/A | B21: =VLOOKUP(E21,'[1]Listas Desplegables'!$H$3:$J$7,3,FALSE()) -> #N/A | C21: 16 | D21: T-CDL01 | E21: CORDIALIDAD | F21: 110 | G21: 13.8 | H21: 60 | I21: Dyn5 | J21: 12.33 | K21: 12.33 | L21: 0 | M21: 10 | N21: -15 | O21: 1 | P21: 130 | Q21: 30 | R21: Sí | T21: SDL | U21: 108.211 | W21: 0 | X21: 0
A22: =VLOOKUP(E22,'[1]Listas Desplegables'!$H$3:$J$7,2,FALSE()) -> #N/A | B22: =VLOOKUP(E22,'[1]Listas Desplegables'!$H$3:$J$7,3,FALSE()) -> #N/A | C22: 17 | D22: T-CDL02 | E22: CORDIALIDAD | F22: 110 | G22: 13.8 | H22: 50 | I22: Dyn5 | J22: 12.51 | K22: 13.68 | L22: 0 | M22: 10 | N22: -15 | O22: 1 | P22: 100 | Q22: 0 | R22: Sí | T22: SDL | U22: 223.21 | W22: 0 | X22: 0
A23: =VLOOKUP(E23,'[1]Listas Desplegables'!$H$3:$J$7,2,FALSE()) -> #N/A | B23: =VLOOKUP(E23,'[1]Listas Desplegables'!$H$3:$J$7,3,FALSE()) -> #N/A | C23: 18 | D23: T-CUC05 | E23: CUESTECITAS | F23: 34.5 | G23: 13.8 | H23: 12.5 | I23: Dyn1 | J23: 8.75 | K23: 8.75 | L23: 0 | M23: 16 | N23: -16 | O23: 0.625 | P23: 110 | Q23: 30 | R23: Sí | T23: SDL | W23: 0 | X23: 0
A24: =VLOOKUP(E24,'[1]Listas Desplegables'!$H$3:$J$7,2,FALSE()) -> #N/A | B24: =VLOOKUP(E24,'[1]Listas Desplegables'!$H$3:$J$7,3,FALSE()) -> #N/A | C24: 19 | D24: T-RTN01 | E24: EL RETEN | F24: 34.5 | G24: 13.8 | H24: 6.5 | I24: Dyn5 | J24: 8.65 | K24: 8.65 | L24: 0 | M24: 1 | N24: -3 | O24: 2.5 | P24: 110 | Q24: 30 | R24: Sí | T24: SDL | U24: 48.5 | W24: 0 | X24: 0
A25: =VLOOKUP(E25,'[1]Listas Desplegables'!$H$3:$J$7,2,FALSE()) -> #N/A | B25: =VLOOKUP(E25,'[1]Listas Desplegables'!$H$3:$J$7,3,FALSE()) -> #N/A | C25: 20 | D25: T-ERI05 | E25: EL RIO | F25: 110 | G25: 34.5 | H25: 125 | I25: YNd11 | J25: 11.33 | K25: 11.33 | L25: 0 | M25: 2 | N25: -2 | O25: 2.5 | P25: 130 | Q25: 30 | R25: Sí | T25: SDL | U25: 467.75 | W25: 0 | X25: 0
A26: =VLOOKUP(E26,'[1]Listas Desplegables'!$H$3:$J$7,2,FALSE()) -> #N/A | B26: =VLOOKUP(E26,'[1]Listas Desplegables'!$H$3:$J$7,3,FALSE()) -> #N/A | C26: 21 | D26: T-ERI02 | E26: EL RIO | F26: 34.5 | G26: 13.8 | H26: 33 | I26: YnYn0 | J26: 7.8936 | K26: 7.8936 | L26: 0 | M26: 16 | N26: -16 | O26: 0.625 | P26: 110 | Q26: 30 | R26: Sí | T26: SDL
A27: =VLOOKUP(E27,'[1]Listas Desplegables'!$H$3:$J$7,2,FALSE()) -> #N/A | B27: =VLOOKUP(E27,'[1]Listas Desplegables'!$H$3:$J$7,3,FALSE()) -> #N/A | C27: 22 | D27: T-ERI01 | E27: EL RIO | F27: 34.5 | G27: 13.8 | H27: 33 | I27: YnYn0 | J27: 7.8276 | K27: 7.8276 | L27: 0 | M27: 16 | N27: -16 | O27: 0.625 | P27: 110 | Q27: 30 | R27: Sí | T27: SDL
A28: =VLOOKUP(E28,'[1]Listas Desplegables'!$H$3:$J$7,2,FALSE()) -> #N/A | B28: =VLOOKUP(E28,'[1]Listas Desplegables'!$H$3:$J$7,3,FALSE()) -> #N/A | C28: 23 | D28: T-FON01 | E28: FONSECA | F28: 34.5 | G28: 13.8 | H28: 13.3 | I28: YNyn0 | J28: 5.11 | K28: 5.11 | L28: 0 | M28: 2 | N28: -2 | O28: 2.5 | P28: 105 | Q28: 30 | R28: Sí | T28: SDL | W28: 1.6884894 | X28: 3 | AA28: Desacoplado del T02
A29: =VLOOKUP(E29,'[1]Listas Desplegables'!$H$3:$J$7,2,FALSE()) -> #N/A | B29: =VLOOKUP(E29,'[1]Listas Desplegables'!$H$3:$J$7,3,FALSE()) -> #N/A | C29: 24 | D29: T-FON02 | E29: FONSECA | F29: 34.5 | G29: 13.8 | H29: 13.3 | I29: YNyn0 | J29: 5.1 | K29: 5.1 | L29: 0 | M29: 2 | N29: -2 | O29: 2.5 | P29: 100 | Q29: 0 | R29: Sí | T29: SDL | U29: 58.2 | V29: 0 | W29: 0 | X29: 0 | AA29: Desacoplado del T01
A30: =VLOOKUP(E30,'[1]Listas Desplegables'!$H$3:$J$7,2,FALSE()) -> #N/A | B30: =VLOOKUP(E30,'[1]Listas Desplegables'!$H$3:$J$7,3,FALSE()) -> #N/A | C30: 25 | D30: T-HAN01 | E30: HATO NUEVO | F30: 34.5 | G30: 13.8 | H30: 6.5 | I30: Dyn1 | J30: 7.74 | K30: 7.74 | L30: 0 | M30: 2 | N30: -2 | O30: 2.5 | P30: 115 | Q30: 30 | R30: Sí | T30: SDL | W30: 0 | X30: 0
A31: =VLOOKUP(E31,'[1]Listas Desplegables'!$H$3:$J$7,2,FALSE()) -> #N/A | B31: =VLOOKUP(E31,'[1]Listas Desplegables'!$H$3:$J$7,3,FALSE()) -> #N/A | C31: 26 | D31: T-HAN02 | E31: HATO NUEVO | F31: 34.5 | G31: 13.8 | H31: 6.5 | I31: Dyn1 | J31: 7.8 | K31: 7.8 | L31: 0 | M31: 2 | N31: -2 | O31: 2.5 | P31: 115 | Q31: 30 | R31: Sí | T31: SDL | W31: 0 | X31: 0
A32: =VLOOKUP(E32,'[1]Listas Desplegables'!$H$3:$J$7,2,FALSE()) -> #N/A | B32: =VLOOKUP(E32,'[1]Listas Desplegables'!$H$3:$J$7,3,FALSE()) -> #N/A | C32: 27 | D32: T-JDA01 | E32: JUAN DE ACOSTA | F32: 34.5 | G32: 13.8 | H32: 9.3 | I32: Dyn1 | J32: 8.078 | K32: 8.078 | L32: 0 | M32: 2 | N32: -2 | O32: 2.5 | P32: 110 | Q32: 30 | R32: Sí | T32: SDL | U32: 66.431
A33: =VLOOKUP(E33,'[1]Listas Desplegables'!$H$3:$J$7,2,FALSE()) -> #N/A | B33: =VLOOKUP(E33,'[1]Listas Desplegables'!$H$3:$J$7,3,FALSE()) -> #N/A | C33: 28 | D33: T-LRT01 | E33: LA RETIRADA | F33: 34.5 | G33: 13.8 | H33: 1 | I33: Dyn5 | J33: 5.4 | K33: 5.4 | L33: 0 | M33: 2 | N33: -2 | O33: 2.5 | P33: 115 | Q33: 30 | R33: Sí | T33: SDL | U33: 12.73 | W33: 0 | X33: 0
A34: =VLOOKUP(E34,'[1]Listas Desplegables'!$H$3:$J$7,2,FALSE()) -> #N/A | B34: =VLOOKUP(E34,'[1]Listas Desplegables'!$H$3:$J$7,3,FALSE()) -> #N/A | C34: 29 | D34: T-UNI06 | E34: LA UNION (ATLANTICO) | F34: 110 | G34: 34.5 | H34: 125 | I34: YNd11 | J34: 11.33 | K34: 11.33 | L34: 0 | M34: 2 | N34: -2 | O34: 2.5 | P34: 130 | Q34: 30 | R34: Sí | T34: SDL | U34: 459.6 | W34: 0 | X34: 0
A35: =VLOOKUP(E35,'[1]Listas Desplegables'!$H$3:$J$7,2,FALSE()) -> #N/A | B35: =VLOOKUP(E35,'[1]Listas Desplegables'!$H$3:$J$7,3,FALSE()) -> #N/A | C35: 30 | D35: T-FLS01 | E35: LAS FLORES | F35: 110 | G35: 34.5 | H35: 50 | I35: YNd11 | J35: 13.9 | K35: 13.9 | L35: 0 | M35: 10 | N35: -10 | O35: 1 | P35: 110 | Q35: 30 | R35: Sí | T35: SDL | U35: 171.5 | W35: 0 | X35: 0
A36: =VLOOKUP(E36,'[1]Listas Desplegables'!$H$3:$J$7,2,FALSE()) -> #N/A | B36: =VLOOKUP(E36,'[1]Listas Desplegables'!$H$3:$J$7,3,FALSE()) -> #N/A | C36: 31 | D36: T-FLS02 | E36: LAS FLORES | F36: 110 | G36: 34.5 | H36: 50 | I36: YNd11 | J36: 13.9 | K36: 13.9 | L36: 0 | M36: 10 | N36: -10 | O36: 1 | P36: 110 | Q36: 30 | R36: Sí | T36: SDL | U36: 171.5 | W36: 0.2359775 | X36: 2
